File: Y261_oscil_creep_recovery_100Pa_trimmed.txt
Time	Strain	Shear Stress
[s]	[1]	[Pa]
70280	0.0009996839	1.05943
70580	0.001000045	0.5429842
70731.51	0.1403141	100
70734.51	0.1567628	100
70737.51	0.1650163	100
70740.51	0.1707638	100
70743.51	0.1752144	100
70746.51	0.1788478	100
70749.51	0.1819372	100
70752.51	0.1846311	100
70755.51	0.1870719	100
70758.51	0.189278	100
70761.51	0.1912737	100
70764.51	0.1931011	100
70767.51	0.1948639	100
70770.51	0.1965033	100
70773.51	0.1979944	100
70776.51	0.1994368	100
70779.51	0.2008011	100
70782.51	0.2020923	100
70785.51	0.2033354	100
70788.51	0.2044926	100
70791.51	0.2056204	100
70794.51	0.2066862	100
70797.51	0.2077341	100
70800.51	0.2087388	100
70803.51	0.2097035	100
70806.51	0.2106279	100
70809.51	0.2115037	100
70812.51	0.212368	100
70815.51	0.2132196	100
70818.51	0.2140302	100
70821.51	0.2148229	100
70824.51	0.215617	100
70827.51	0.2163604	100
70830.51	0.2170782	100
70833.51	0.2178134	100
70836.51	0.2185258	100
70839.51	0.2191889	100
70842.51	0.2198614	100
70845.51	0.2205398	100
70848.51	0.2211783	100
70851.51	0.2217819	100
70854.51	0.2224062	100
70857.51	0.2230461	100
70860.51	0.2236351	100
70863.51	0.2242162	100
70866.51	0.2248215	100
70869.51	0.2253742	100
70872.51	0.2259618	100
70875.51	0.2264871	100
70878.51	0.2270494	100
70881.51	0.2275963	100
70884.51	0.2281025	100
70887.51	0.2286368	100
70890.51	0.2291669	100
70893.51	0.2296669	100
70896.51	0.230163	100
70899.51	0.230665	100
70902.51	0.2311617	100
70905.51	0.2316692	100
70908.51	0.2321379	100
70911.51	0.2326005	100
70914.51	0.2330466	100
70917.51	0.2334906	100
70920.51	0.2339508	100
70923.51	0.2343892	100
70926.51	0.2348155	100
70929.51	0.2352466	100
70932.51	0.2356726	100
70935.51	0.2360725	100
70938.51	0.2364629	100
70941.51	0.2368797	100
70944.51	0.2372819	100
70947.51	0.2376814	100
70950.51	0.2380923	100
70953.51	0.238503	100
70956.51	0.238899	100
70959.51	0.2392809	100
70962.51	0.2396686	100
70965.51	0.2400523	100
70968.51	0.2404331	100
70971.51	0.2408046	100
70974.51	0.2411626	100
70977.51	0.2415263	100
70980.51	0.2418844	100
70983.51	0.2422522	100
70986.51	0.2426153	100
70989.51	0.2429741	100
70992.51	0.2433279	100
70995.51	0.243675	100
70998.51	0.244031	100
71001.51	0.2443859	100
71004.51	0.2447249	100
71007.51	0.2450561	100
71010.51	0.2453777	100
71013.51	0.2457081	100
71016.51	0.246043	100
71019.51	0.2463821	100
71022.51	0.2467033	100
71025.51	0.2470356	100
71028.51	0.2473475	100
71031.51	0.2476697	100
71034.51	0.248002	100
71037.51	0.2483243	100
71040.51	0.248629	100
71043.51	0.2489248	100
71046.51	0.2492339	100
71049.51	0.2495479	100
71052.51	0.2498676	100
71055.51	0.2501928	100
71058.51	0.2505081	100
71061.51	0.2508276	100
71064.51	0.2511251	100
71067.51	0.25142	100
71070.51	0.2517203	100
71073.51	0.2520366	100
71076.51	0.25235	100
71079.52	0.2526635	100
71082.52	0.2529557	100
71085.52	0.2532665	100
71088.52	0.2535828	100
71091.52	0.2538871	100
71094.52	0.2541657	100
71097.52	0.2544348	100
71100.52	0.2547365	100
71103.52	0.2550428	100
71106.52	0.2553254	100
71109.52	0.2556014	100
71112.52	0.2558698	100
71115.52	0.2561333	100
71118.52	0.2564062	100
71121.52	0.2566744	100
71124.52	0.2569541	100
71127.52	0.2572257	100
71130.52	0.257486	100
71133.52	0.2577595	100
71136.52	0.2580197	100
71139.52	0.2582829	100
71142.52	0.2585413	100
71145.52	0.2588033	100
71148.52	0.2590573	100
71151.52	0.2593056	100
71154.52	0.2595704	100
71157.52	0.2598379	100
71160.52	0.2600728	100
71163.52	0.2603317	100
71166.52	0.2605775	100
71169.52	0.2608122	100
71172.52	0.2610856	100
71175.52	0.2613198	100
71178.52	0.2615806	100
71181.52	0.2618316	100
71184.52	0.2620652	100
71187.52	0.2623347	100
71190.52	0.2625709	100
71193.52	0.2628182	100
71196.52	0.263048	100
71199.52	0.2632725	100
71202.52	0.2635306	100
71205.52	0.2637588	100
71208.52	0.2639977	100
71211.53	0.2642278	100
71214.53	0.2644556	100
71217.53	0.2646895	100
71220.53	0.2649163	100
71223.53	0.2651407	100
71226.53	0.2653671	100
71229.53	0.2656034	100
71232.53	0.2658296	100
71235.53	0.2660487	100
71238.53	0.2662632	100
71241.53	0.2664967	100
71244.53	0.2667211	100
71247.53	0.2669467	100
71250.52	0.2671787	100
71253.52	0.2674054	100
71256.52	0.2676183	100
71259.52	0.2678375	100
71262.52	0.2680586	100
71265.52	0.2682717	100
71268.52	0.2684863	100
71271.52	0.2687006	100
71274.52	0.2689133	100
71277.52	0.2691306	100
71280.52	0.2693542	100
71283.51	0.2695657	100
71286.51	0.2697627	100
71289.51	0.2699788	100
71292.51	0.270183	100
71295.51	0.2703963	100
71298.51	0.2705906	100
71301.51	0.2708051	100
71304.51	0.2709918	100
71307.51	0.2711993	100
71310.51	0.2713899	100
71313.51	0.2716087	100
71316.51	0.2718101	100
71319.51	0.2719954	100
71322.51	0.2722023	100
71325.51	0.2724045	100
71328.51	0.2725862	100
71331.51	0.1818843	0
71334.51	0.1655316	0
71337.51	0.1569654	0
71340.51	0.1509009	0
71343.51	0.1460967	0
71346.51	0.1420701	0
71349.51	0.1386094	0
71352.51	0.1355119	0
71355.51	0.132758	0
71358.51	0.1302906	0
71361.51	0.1280062	0
71364.51	0.1258908	0
71367.51	0.1239367	0
71370.51	0.122129	0
71373.51	0.1204109	0
71376.51	0.1187762	0
71379.51	0.117226	0
71382.51	0.1157525	0
71385.51	0.114361	0
71388.51	0.1130242	0
71391.51	0.1117252	0
71394.51	0.1104984	0
71397.51	0.1093197	0
71400.51	0.1081933	0
71403.51	0.1071224	0
71406.51	0.106087	0
71409.51	0.1050898	0
71412.51	0.1041023	0
71415.51	0.1031557	0
71418.51	0.1022681	0
71421.51	0.1013544	0
71424.51	0.1005381	0
71427.51	0.09968136	0
71435.01	0.09774879	0
71465.01	0.09101155	0
71495.01	0.08551588	0
71525.01	0.08093488	0
71555.01	0.07701694	0
71585.01	0.07357666	0
71615.01	0.07063823	0
71645.01	0.06801168	0
71675.01	0.06567129	0
71705.01	0.06353457	0
71735.01	0.06162032	0
71765.01	0.05981036	0
71795.01	0.05815531	0
71825.01	0.05665934	0
71855.01	0.05526571	0
71885.01	0.05395122	0
71915.01	0.05269897	0
71945.01	0.05153612	0
71975.01	0.05047458	0
72005.01	0.04941944	0
72035.01	0.04846285	0
72065.01	0.04753487	0
72095.01	0.04666128	0
72125.01	0.04583933	0
72155.01	0.04509027	0
72185.01	0.04436534	0
72215.01	0.04368375	0
72245.01	0.04300274	0
72275.01	0.0423892	0
72305.01	0.04176357	0
72335.01	0.04116184	0
72365.01	0.04058184	0
72395.01	0.04005525	0
72425.01	0.03953524	0
72455.01	0.03906646	0
72485.01	0.03860369	0
72515.01	0.0381319	0
72545.01	0.03769054	0
72575.01	0.03726372	0
72605.01	0.03680495	0
72635.01	0.03639485	0
72665.01	0.03597418	0
72695.01	0.03561224	0
72725.01	0.03521867	0
72755.01	0.0348537	0
72785.01	0.03453471	0
72815.01	0.03424667	0
72845.01	0.03390568	0
72875.01	0.03360582	0
72905.01	0.03330354	0
72935.01	0.03298938	0
72965.01	0.03272311	0
72995.01	0.03245527	0
73025.01	0.03218489	0
73055.01	0.0319534	0
73085.01	0.03167139	0
73115.01	0.03138397	0
73145.01	0.03115191	0
73175.01	0.03093076	0
73205.01	0.03069753	0
73235.01	0.03044212	0
73265.01	0.03021102	0
73295.01	0.02994368	0
73325.01	0.02971495	0
73355.01	0.02954361	0
73385.01	0.02929659	0
73415.01	0.02910836	0
73445.01	0.02891917	0
73475.01	0.02872927	0
73505.01	0.0285729	0
73535.01	0.02841948	0
73565.01	0.02824658	0
73595.01	0.0280443	0
73625.01	0.02787891	0
73655.01	0.02770431	0
73685.01	0.02750836	0
73715.01	0.02736489	0
73745.01	0.0272141	0
73775.01	0.02706986	0
73805.01	0.02693939	0
73835.01	0.02675398	0
73865.01	0.0265887	0
73895.01	0.02645174	0
73925.01	0.0263297	0
73955.01	0.0262103	0
73985.01	0.02599083	0
74015.01	0.02587794	0
74045.01	0.02575102	0
74075.01	0.0256339	0
74105.01	0.02547921	0
74135.01	0.02532984	0
74165.01	0.02519887	0
74195.01	0.02511319	0
74225.01	0.02499208	0
74255.01	0.02488211	0
74285.01	0.02476782	0
74315.01	0.02468786	0
74345.01	0.02457019	0
74375.01	0.0244518	0
74405.01	0.02432344	0
74435.01	0.02420586	0
74465.01	0.02408816	0
74495.01	0.02398014	0
74525.01	0.0238706	0
74555.01	0.02373122	0
74585.01	0.02364472	0
74615.01	0.02354184	0
74645.01	0.02342831	0
74675.01	0.02329489	0
74705.01	0.02320441	0
74735.01	0.02312516	0
74765.01	0.02306293	0
74795.01	0.02297099	0
74825.01	0.0228825	0
74855.01	0.02278671	0
74885.01	0.02268877	0
74915.01	0.02259914	0
74945.01	0.02250066	0
74975.01	0.02241496	0
75005.01	0.02234504	0
75035.01	0.02224471	0
75065.01	0.02219882	0
75095.01	0.02211625	0
75125.01	0.02200769	0
75155.01	0.02190862	0
75185.01	0.02183527	0
75215.01	0.02179202	0
75245.01	0.02172008	0
75275.01	0.02163862	0
75305.01	0.02153548	0
75335.01	0.02146021	0
75365.01	0.02138654	0
75395.01	0.02131762	0
75425.01	0.02126209	0
75455.01	0.02122587	0
75485.01	0.02110499	0
75515.01	0.02101675	0
75545.01	0.0209613	0
75575.01	0.02087972	0
75605.01	0.02079461	0
75635.01	0.02074784	0
75665.01	0.02071577	0
75695.01	0.02066097	0
75725.01	0.02061708	0
75755.01	0.02053407	0
75785.01	0.02044235	0
75815.01	0.02040781	0
75845.01	0.02036679	0
75875.01	0.02031929	0
75905.01	0.0202258	0
75935.01	0.02011607	0
75965.01	0.02003812	0
75995.01	0.01998808	0
76025.01	0.01993392	0
76055.01	0.01989306	0
76085.01	0.01986806	0
76115.01	0.01984565	0
76145.01	0.01978163	0
76175.01	0.01969868	0
76205.01	0.01967158	0
76235.01	0.0196461	0
76265.01	0.01956454	0
76295.01	0.01944536	0
76325.01	0.01941346	0
76355.01	0.01937872	0
76385.01	0.01931306	0
76415.01	0.01924089	0
76445.01	0.01916394	0
76475.01	0.01917123	0
76505.01	0.01916828	0
76535.01	0.01905805	0
76565.01	0.01905122	0
76595.01	0.01894743	0
76625.01	0.01892489	0
76655.01	0.01890157	0
76685.01	0.01886748	0
76715.01	0.01883701	0
76745.01	0.0188038	0
76775.01	0.01873479	0
76805.01	0.01870589	0
76835.01	0.0186628	0
76865.01	0.01863604	0
76895.01	0.0185739	0
76925.01	0.01849834	0
76955.01	0.01844013	0
76985.01	0.01838698	0
77015.01	0.01833624	0
77045.01	0.01830407	0
77075.01	0.01826068	0
77105.01	0.0182579	0
77135.01	0.01822554	0
77165.01	0.01818683	0
77195.01	0.01812745	0
77225.01	0.0180796	0
77255.01	0.01804223	0
77285.01	0.01801152	0
77315.01	0.01797953	0
77345.01	0.01793551	0
77375.01	0.01786549	0
77405.01	0.01786493	0
77435.01	0.0178297	0
77465.01	0.01781748	0
77495.01	0.01775261	0
77525.01	0.01774314	0
77555.01	0.0177069	0
77585.01	0.01766969	0
77615.01	0.0175876	0
77645.01	0.01756601	0
77675.01	0.0175793	0
77705.01	0.01753246	0
77735.01	0.01751797	0
77765.01	0.01745659	0
77795.01	0.01743039	0
77825.01	0.01736601	0
77855.01	0.01736473	0
77885.01	0.01735253	0
77915.01	0.01726374	0
77945.01	0.01721748	0
77975.01	0.01717684	0
78005.01	0.01718617	0
78035.01	0.01719862	0
78065.01	0.01716517	0
78095.01	0.01709319	0
78125.01	0.01708968	0
78155.01	0.017031	0
78185.01	0.01700519	0
78215.01	0.01697611	0
78245.01	0.01692586	0
78275.01	0.01687687	0
78305.01	0.01683985	0
78335.01	0.01683153	0
78365.01	0.01682027	0
78395.01	0.01677247	0
78425.01	0.01673431	0
78455.01	0.01669124	0
78485.01	0.0166809	0
78515.01	0.01664757	0
78545.01	0.0166392	0
78575.01	0.01661588	0
78605.01	0.01658364	0
78635.01	0.01655593	0
78665.01	0.01651463	0
78695.01	0.01647905	0
78725.01	0.01645596	0
78755.01	0.0164859	0
78785.01	0.01646611	0
78815.01	0.01638253	0
78845.01	0.01638103	0
78875.01	0.01633673	0
78905.01	0.01632883	0
78935.01	0.0162699	0
78965.01	0.01623421	0
78995.01	0.0162101	0
79025.01	0.01618118	0
79055.01	0.01615191	0
79085.01	0.01611126	0
79115.01	0.01610842	0
79145.01	0.01610048	0
79175.01	0.01606613	0
79205.01	0.01606743	0
79235.01	0.01606358	0
79265.01	0.01605954	0
79295.01	0.01600478	0
79325.01	0.01595538	0
79580.01	0.00100001	0.6040832
79790.91	0.1317309	100
79793.91	0.1530436	100
79796.91	0.1622301	100
79799.91	0.1682514	100
79802.91	0.1728356	100
79805.91	0.1765771	100
79808.91	0.1797849	100
79811.91	0.1825693	100
79814.91	0.1850528	100
79817.91	0.18728	100
79820.91	0.189283	100
79823.91	0.1911437	100
79826.91	0.1928779	100
79829.91	0.1944763	100
79832.91	0.1959664	100
79835.91	0.1973833	100
79838.91	0.1987372	100
79841.91	0.2000219	100
79844.91	0.2012407	100
79847.91	0.2023924	100
79850.91	0.2034998	100
79853.91	0.2045893	100
79856.91	0.2056556	100
79859.91	0.2066271	100
79862.91	0.2076007	100
79865.91	0.2085737	100
79868.91	0.2094868	100
79871.91	0.2103695	100
79874.91	0.2112312	100
79877.91	0.2120768	100
79880.91	0.2128969	100
79883.91	0.2137002	100
79886.91	0.2145114	100
79889.91	0.2152673	100
79892.91	0.2159846	100
79895.91	0.2167199	100
79898.91	0.2174299	100
79901.91	0.2181084	100
79904.91	0.2187759	100
79907.91	0.2194219	100
79910.91	0.2201016	100
79913.91	0.2207362	100
79916.91	0.221365	100
79919.91	0.2219727	100
79922.91	0.2225719	100
79925.91	0.2231591	100
79928.91	0.2237397	100
79931.91	0.2243153	100
79934.91	0.2248668	100
79937.91	0.2254144	100
79940.91	0.2259551	100
79943.91	0.2264779	100
79946.91	0.2270132	100
79949.91	0.2275412	100
79952.91	0.2280472	100
79955.91	0.2285378	100
79958.91	0.2290558	100
79961.91	0.2295412	100
79964.91	0.2300411	100
79967.91	0.2304976	100
79970.91	0.2309662	100
79973.91	0.2314307	100
79976.91	0.2319084	100
79979.91	0.2323577	100
79982.91	0.2328012	100
79985.91	0.2332434	100
79988.91	0.2336969	100
79991.91	0.234156	100
79994.91	0.2345585	100
79997.91	0.2350314	100
80000.91	0.2354342	100
80003.91	0.2359039	100
80006.91	0.2363086	100
80009.91	0.2367296	100
80012.91	0.2371686	100
80015.91	0.2375881	100
80018.91	0.2379914	100
80021.91	0.2383869	100
80024.91	0.2387699	100
80027.91	0.2391652	100
80030.91	0.2395643	100
80033.91	0.2399688	100
80036.91	0.2403394	100
80039.91	0.2406925	100
80042.91	0.2410943	100
80045.91	0.2414405	100
80048.91	0.2418327	100
80051.91	0.2421888	100
80054.91	0.2425377	100
80057.92	0.2429263	100
80060.92	0.2432597	100
80063.92	0.2436254	100
80066.92	0.2439787	100
80069.92	0.2443406	100
80072.92	0.2447061	100
80075.92	0.2450631	100
80078.92	0.2453947	100
80081.92	0.2457355	100
80084.92	0.2460789	100
80087.92	0.2464042	100
80090.92	0.2467198	100
80093.92	0.247058	100
80096.92	0.2473699	100
80099.92	0.2476929	100
80102.92	0.2480107	100
80105.92	0.2483191	100
80108.92	0.2486462	100
80111.92	0.2489495	100
80114.92	0.2492524	100
80117.92	0.2495815	100
80120.92	0.2498894	100
80123.92	0.2502135	100
80126.92	0.2505198	100
80129.92	0.2508282	100
80132.92	0.2511373	100
80135.92	0.2514366	100
80138.92	0.2517288	100
80141.92	0.2520234	100
80144.92	0.2523165	100
80147.92	0.252604	100
80150.92	0.2528969	100
80153.92	0.2531883	100
80156.92	0.2534837	100
80159.92	0.2537764	100
80162.92	0.2540725	100
80165.92	0.2543645	100
80168.92	0.2546304	100
80171.92	0.2549202	100
80174.92	0.2551824	100
80177.92	0.2554851	100
80180.92	0.2557645	100
80183.92	0.2560701	100
80186.92	0.2563451	100
80189.93	0.2566098	100
80192.93	0.2569013	100
80195.93	0.2571719	100
80198.93	0.2574322	100
80201.93	0.2577165	100
80204.93	0.2579975	100
80207.93	0.2582528	100
80210.93	0.2585129	100
80213.93	0.2587929	100
80216.93	0.2590673	100
80219.93	0.2593466	100
80222.93	0.2596064	100
80225.93	0.259865	100
80228.93	0.2601237	100
80231.93	0.2603814	100
80234.93	0.260643	100
80237.93	0.2608993	100
80240.93	0.2611649	100
80243.93	0.2614232	100
80246.93	0.2616823	100
80249.93	0.2619171	100
80252.93	0.2621547	100
80255.93	0.2624165	100
80258.93	0.2626691	100
80261.93	0.2628874	100
80264.93	0.2631438	100
80267.93	0.2634143	100
80270.93	0.263638	100
80273.93	0.2638947	100
80276.93	0.2641263	100
80279.93	0.2643437	100
80282.93	0.2646115	100
80285.93	0.2648196	100
80288.93	0.2650861	100
80291.93	0.2652842	100
80294.93	0.2655477	100
80297.93	0.2657642	100
80300.93	0.2659948	100
80303.93	0.2662388	100
80306.93	0.2664443	100
80309.93	0.2666951	100
80312.93	0.2669058	100
80315.93	0.2671514	100
80318.93	0.2673832	100
80321.93	0.2676215	100
80324.93	0.267835	100
80327.93	0.2680773	100
80330.92	0.2682848	100
80333.92	0.2685358	100
80336.92	0.2687209	100
80339.92	0.2689522	100
80342.92	0.269173	100
80345.92	0.2693624	100
80348.92	0.2695902	100
80351.92	0.2698346	100
80354.92	0.2700272	100
80357.92	0.270247	100
80360.92	0.270478	100
80363.91	0.2706773	100
80366.91	0.2708865	100
80369.91	0.2711225	100
80372.91	0.2713072	100
80375.91	0.2715138	100
80378.91	0.2717423	100
80381.91	0.271969	100
80384.91	0.2721844	100
80387.91	0.2723972	100
80390.91	0.1865635	0
80393.91	0.1659008	0
80396.91	0.1565573	0
80399.91	0.1500955	0
80402.91	0.1451607	0
80405.91	0.1411651	0
80408.91	0.1377309	0
80411.91	0.134751	0
80414.91	0.1320325	0
80417.91	0.1295924	0
80420.91	0.1273432	0
80423.91	0.1252464	0
80426.91	0.1232878	0
80429.91	0.1214738	0
80432.91	0.1197765	0
80435.91	0.1181821	0
80438.91	0.1166627	0
80441.91	0.1152057	0
80444.91	0.1138346	0
80447.91	0.1125547	0
80450.91	0.1112839	0
80453.91	0.1101019	0
80456.91	0.1089599	0
80459.91	0.1078648	0
80462.91	0.1068154	0
80465.91	0.1058055	0
80468.91	0.104821	0
80471.91	0.1038652	0
80474.91	0.1029427	0
80477.91	0.1020388	0
80480.91	0.1011804	0
80483.91	0.1003303	0
80486.91	0.09951756	0
80489.91	0.09872922	0
80519.01	0.09198709	0
80549.01	0.08648472	0
80579.01	0.08192837	0
80609.01	0.07811398	0
80639.01	0.07483758	0
80669.01	0.07193527	0
80699.01	0.06936297	0
80729.01	0.06702664	0
80759.01	0.0648761	0
80789.01	0.06297442	0
80819.01	0.06118393	0
80849.01	0.05956505	0
80879.01	0.05809986	0
80909.01	0.05671632	0
80939.01	0.05542519	0
80969.01	0.05416745	0
80999.01	0.05306016	0
81029.01	0.05199234	0
81059.01	0.05097068	0
81089.01	0.050053	0
81119.01	0.04917717	0
81149.01	0.04836524	0
81179.01	0.04762217	0
81209.01	0.04685373	0
81239.01	0.04615584	0
81269.01	0.04548898	0
81299.01	0.04483119	0
81329.01	0.04418843	0
81359.01	0.04356847	0
81389.01	0.04297534	0
81419.01	0.04242254	0
81449.01	0.04192127	0
81479.01	0.04140438	0
81509.01	0.04098559	0
81539.01	0.04048851	0
81569.01	0.04007769	0
81599.01	0.03959596	0
81629.01	0.03914497	0
81659.01	0.03877711	0
81689.01	0.03837493	0
81719.01	0.03800631	0
81749.01	0.0376443	0
81779.01	0.03727493	0
81809.01	0.03690074	0
81839.01	0.03655816	0
81869.01	0.03621959	0
81899.01	0.03595432	0
81929.01	0.03565315	0
81959.01	0.03535904	0
81989.01	0.03502857	0
82019.01	0.03473731	0
82049.01	0.03447684	0
82079.01	0.03422751	0
82109.01	0.03396708	0
82139.01	0.03372373	0
82169.01	0.03344049	0
82199.01	0.03319121	0
82229.01	0.03300409	0
82259.01	0.03277162	0
82289.01	0.03250364	0
82319.01	0.03229552	0
82349.01	0.03208266	0
82379.01	0.0318664	0
82409.01	0.03166227	0
82439.01	0.03146715	0
82469.01	0.03130964	0
82499.01	0.0311381	0
82529.01	0.03091739	0
82559.01	0.03073703	0
82589.01	0.03054278	0
82619.01	0.03041467	0
82649.01	0.03025027	0
82679.01	0.03006328	0
82709.01	0.02993787	0
82739.01	0.02975123	0
82769.01	0.02960655	0
82799.01	0.02946043	0
82829.01	0.02930667	0
82859.01	0.02911908	0
82889.01	0.02899805	0
82919.01	0.02886967	0
82949.01	0.02872223	0
82979.01	0.02857477	0
83009.01	0.02839549	0
83039.01	0.02825984	0
83069.01	0.02813558	0
83099.01	0.02803005	0
83129.01	0.02789977	0
83159.01	0.02774848	0
83189.01	0.02760715	0
83219.01	0.02751472	0
83249.01	0.02738551	0
83279.01	0.02726098	0
83309.01	0.02715164	0
83339.01	0.02701832	0
83369.01	0.02690243	0
83399.01	0.02681936	0
83429.01	0.02669173	0
83459.01	0.0265331	0
83489.01	0.02647684	0
83519.01	0.02637489	0
83549.01	0.02628771	0
83579.01	0.02618205	0
83609.01	0.02610138	0
83639.01	0.02601574	0
83669.01	0.02589347	0
83699.01	0.02584356	0
83729.01	0.02576043	0
83759.01	0.0256684	0
83789.01	0.02555452	0
83819.01	0.02544018	0
83849.01	0.02538886	0
83879.01	0.02531308	0
83909.01	0.02522886	0
83939.01	0.02513874	0
83969.01	0.02502058	0
83999.01	0.02494151	0
84029.01	0.02485905	0
84059.01	0.02481382	0
84089.01	0.02474065	0
84119.01	0.02466954	0
84149.01	0.02459633	0
84179.01	0.02450655	0
84209.01	0.02441181	0
84239.01	0.02432438	0
84269.01	0.02426777	0
84299.01	0.02418433	0
84329.01	0.02411681	0
84359.01	0.02408007	0
84389.01	0.0240058	0
84419.01	0.02391225	0
84449.01	0.02384552	0
84479.01	0.02380902	0
84509.01	0.02375761	0
84539.01	0.02369036	0
84569.01	0.02365525	0
84599.01	0.0235721	0
84629.01	0.02351223	0
84659.01	0.02347365	0
84689.01	0.02342154	0
84719.01	0.02334228	0
84749.01	0.02327433	0
84779.01	0.02321296	0
84809.01	0.02317739	0
84839.01	0.02311528	0
84869.01	0.02307627	0
84899.01	0.02299463	0
84929.01	0.02290385	0
84959.01	0.02289223	0
84989.01	0.02284882	0
85019.01	0.02282777	0
85049.01	0.02277903	0
85079.01	0.02271699	0
85109.01	0.02263859	0
85139.01	0.02255341	0
85169.01	0.02248974	0
85199.01	0.02244155	0
85229.01	0.02237639	0
85259.01	0.02235006	0
85289.01	0.02232975	0
85319.01	0.02225145	0
85349.01	0.0222061	0
85379.01	0.02213041	0
85409.01	0.02206013	0
85439.01	0.02201605	0
85469.01	0.02198921	0
85499.01	0.02193751	0
85529.01	0.02195493	0
85559.01	0.02186755	0
85589.01	0.02182427	0
85619.01	0.02177265	0
85649.01	0.02175505	0
85679.01	0.0217055	0
85709.01	0.02169883	0
85739.01	0.02167009	0
85769.01	0.02162921	0
85799.01	0.02158059	0
85829.01	0.02153163	0
85859.01	0.02145584	0
85889.01	0.02139798	0
85919.01	0.02134791	0
85949.01	0.02128633	0
85979.01	0.0212677	0
86009.01	0.02122795	0
86039.01	0.02121271	0
86069.01	0.02119216	0
86099.01	0.021182	0
86129.01	0.02115055	0
86159.01	0.02107807	0
86189.01	0.02102489	0
86219.01	0.02101233	0
86249.01	0.02098675	0
86279.01	0.02093642	0
86309.01	0.02091489	0
86339.01	0.02083704	0
86369.01	0.02079766	0
86399.01	0.02075724	0
86429.01	0.02067971	0
86459.01	0.02067732	0
86489.01	0.02066218	0
86519.01	0.02063055	0
86549.01	0.02061304	0
86579.01	0.02055757	0
86609.01	0.02053001	0
86639.01	0.02049156	0
86669.01	0.02045022	0
86699.01	0.02040604	0
86729.01	0.02037544	0
86759.01	0.02035517	0
86789.01	0.02028512	0
86819.01	0.02029645	0
86849.01	0.0202495	0
86879.01	0.02024942	0
86909.01	0.0202431	0
86939.01	0.02022727	0
86969.01	0.02021048	0
86999.01	0.02017983	0
87029.01	0.02012169	0
87059.01	0.02009159	0
87089.01	0.0200427	0
87119.01	0.02001598	0
87149.01	0.01998713	0
87179.01	0.01994414	0
87209.01	0.01993875	0
87239.01	0.01989602	0
87269.01	0.01987591	0
87299.01	0.01986874	0
87329.01	0.01982849	0
87359.01	0.0198041	0
87389.01	0.01974404	0
87419.01	0.019684	0
87449.01	0.0196912	0
87479.01	0.01969409	0
87509.01	0.01968877	0
87539.01	0.01965513	0
87569.01	0.01964475	0
87599.01	0.01961877	0
87629.01	0.01958043	0
87659.01	0.01951585	0
87689.01	0.01949727	0
87719.01	0.01947223	0
87749.01	0.01944269	0
87779.01	0.01945456	0
87809.01	0.01938451	0
87839.01	0.01933806	0
87869.01	0.01936514	0
87899.01	0.01935703	0
87929.01	0.01931748	0
87959.01	0.01930639	0
87989.01	0.01927491	0
88019.01	0.01923424	0
88049.01	0.01923011	0
88079.01	0.01922943	0
88109.01	0.01919442	0
88139.01	0.01918029	0
88169.01	0.01913565	0
88199.01	0.01913205	0
88229.01	0.01911608	0
88259.01	0.01913184	0
88289.01	0.01910679	0
88319.01	0.01904805	0
88349.01	0.01904044	0
88379.01	0.01897697	0
88580.02	0.0009999695	0.7320418
88850.31	0.1143129	100
88853.31	0.1479156	100
88856.31	0.1581692	100
88859.31	0.1647314	100
88862.31	0.169556	100
88865.31	0.1734202	100
88868.31	0.1766215	100
88871.31	0.1794276	100
88874.31	0.1819108	100
88877.31	0.1841313	100
88880.31	0.1861753	100
88883.31	0.1880856	100
88886.31	0.1898463	100
88889.31	0.1914959	100
88892.31	0.1930399	100
88895.31	0.1945071	100
88898.31	0.1958984	100
88901.31	0.1972031	100
88904.31	0.1984401	100
88907.31	0.199622	100
88910.31	0.200759	100
88913.31	0.2018482	100
88916.31	0.202905	100
88919.31	0.2039149	100
88922.31	0.2048791	100
88925.31	0.2058039	100
88928.31	0.2067061	100
88931.31	0.2075868	100
88934.31	0.2084382	100
88937.31	0.2092827	100
88940.31	0.2101056	100
88943.31	0.2108955	100
88946.31	0.2116621	100
88949.31	0.2124058	100
88952.31	0.2131494	100
88955.31	0.213859	100
88958.31	0.2145585	100
88961.31	0.2152564	100
88964.31	0.2159293	100
88967.31	0.2166038	100
88970.31	0.2172723	100
88973.31	0.2179012	100
88976.31	0.2185244	100
88979.31	0.2191392	100
88982.31	0.2197432	100
88985.31	0.2203208	100
88988.31	0.2208897	100
88991.31	0.2214582	100
88994.31	0.2220241	100
88997.31	0.2225808	100
89000.31	0.2231294	100
89003.31	0.2236712	100
89006.31	0.22421	100
89009.31	0.2247368	100
89012.31	0.2252447	100
89015.31	0.2257403	100
89018.31	0.2262201	100
89021.31	0.2266848	100
89024.31	0.227158	100
89027.31	0.2276357	100
89030.31	0.2280992	100
89033.31	0.2285611	100
89036.33	0.2290106	100
89039.33	0.2294514	100
89042.33	0.2298912	100
89045.33	0.2303196	100
89048.33	0.2307414	100
89051.33	0.2311604	100
89054.33	0.2315859	100
89057.33	0.2320107	100
89060.33	0.2324336	100
89063.33	0.2328402	100
89066.33	0.2332481	100
89069.33	0.2336464	100
89072.33	0.234042	100
89075.33	0.2344373	100
89078.33	0.2348252	100
89081.33	0.2352055	100
89084.33	0.2355901	100
89087.33	0.235977	100
89090.33	0.2363441	100
89093.33	0.2367028	100
89096.33	0.2370696	100
89099.33	0.2374431	100
89102.33	0.2378129	100
89105.33	0.2381717	100
89108.33	0.2385347	100
89111.33	0.2388868	100
89114.33	0.2392319	100
89117.33	0.2395751	100
89120.33	0.2399223	100
89123.33	0.2402674	100
89126.33	0.2406077	100
89129.33	0.2409429	100
89132.33	0.2412779	100
89135.33	0.2416201	100
89138.33	0.241951	100
89141.33	0.2422765	100
89144.33	0.2425937	100
89147.33	0.2429175	100
89150.33	0.2432422	100
89153.33	0.2435597	100
89156.33	0.2438667	100
89159.33	0.2441782	100
89162.33	0.2445019	100
89165.34	0.2448226	100
89168.34	0.24513	100
89171.34	0.245436	100
89174.34	0.2457437	100
89177.34	0.2460371	100
89180.34	0.2463367	100
89183.34	0.246648	100
89186.34	0.2469547	100
89189.34	0.2472558	100
89192.34	0.2475482	100
89195.34	0.2478417	100
89198.34	0.2481318	100
89201.34	0.2484274	100
89204.34	0.2487119	100
89207.34	0.2490014	100
89210.34	0.2492963	100
89213.34	0.2495728	100
89216.34	0.2498566	100
89219.34	0.2501309	100
89222.34	0.2504091	100
89225.34	0.2506867	100
89228.34	0.2509432	100
89231.34	0.251204	100
89234.34	0.2514807	100
89237.34	0.2517464	100
89240.34	0.252014	100
89243.34	0.2522885	100
89246.34	0.2525585	100
89249.34	0.2528238	100
89252.34	0.2530855	100
89255.34	0.2533456	100
89258.34	0.2536012	100
89261.34	0.2538537	100
89264.34	0.2541184	100
89267.34	0.2543792	100
89270.34	0.254644	100
89273.34	0.2549038	100
89276.34	0.2551596	100
89279.34	0.2554116	100
89282.34	0.2556655	100
89285.34	0.2559221	100
89288.34	0.2561657	100
89291.34	0.256416	100
89294.34	0.2566658	100
89297.34	0.2569159	100
89300.34	0.2571628	100
89303.34	0.2574142	100
89306.34	0.2576629	100
89309.34	0.2579013	100
89312.34	0.2581392	100
89315.34	0.2583758	100
89318.34	0.2586146	100
89321.34	0.2588476	100
89324.34	0.2590908	100
89327.34	0.2593392	100
89330.34	0.2595768	100
89333.34	0.2598076	100
89336.34	0.2600473	100
89339.34	0.2602782	100
89342.34	0.260515	100
89345.34	0.260751	100
89348.34	0.2609679	100
89351.34	0.2611723	100
89354.34	0.2613918	100
89357.34	0.2616412	100
89360.34	0.261871	100
89363.34	0.2621016	100
89366.34	0.2623245	100
89369.34	0.2625464	100
89372.34	0.2627765	100
89375.34	0.2629816	100
89378.34	0.2631963	100
89381.34	0.2634043	100
89384.34	0.2636239	100
89387.34	0.263842	100
89390.34	0.2640636	100
89393.34	0.2642846	100
89396.34	0.2645031	100
89399.34	0.2647157	100
89402.34	0.264922	100
89405.34	0.2651361	100
89408.34	0.2653437	100
89411.33	0.2655498	100
89414.33	0.2657615	100
89417.33	0.2659621	100
89420.33	0.266167	100
89423.33	0.2663733	100
89426.33	0.2665736	100
89429.33	0.2667734	100
89432.33	0.2669787	100
89435.33	0.2671737	100
89438.33	0.2673707	100
89441.33	0.2675626	100
89444.31	0.2677631	100
89447.31	0.2679692	100
89450.31	0.1941696	0
89453.31	0.1633556	0
89456.31	0.1531566	0
89459.31	0.1465458	0
89462.33	0.1415283	0
89465.33	0.1374274	0
89468.33	0.133897	0
89471.33	0.1308418	0
89474.33	0.1281195	0
89477.33	0.1256764	0
89480.33	0.1234852	0
89483.33	0.12146	0
89486.33	0.1195779	0
89489.31	0.1178331	0
89492.31	0.1162138	0
89495.31	0.1146919	0
89498.31	0.1132261	0
89501.31	0.111825	0
89504.31	0.110488	0
89507.31	0.109226	0
89510.31	0.1080136	0
89513.31	0.1068517	0
89516.31	0.1057198	0
89519.31	0.104638	0
89522.31	0.1035992	0
89525.31	0.1025986	0
89528.31	0.1016394	0
89531.31	0.1007119	0
89534.31	0.09980916	0
89537.31	0.09893184	0
89540.31	0.09807744	0
89543.31	0.09724642	0
89546.31	0.0964507	0
89549.31	0.09567558	0
89573.02	0.09036847	0
89603.02	0.084825	0
89633.02	0.08025124	0
89663.02	0.07634041	0
89693.02	0.0730144	0
89723.02	0.07009614	0
89753.02	0.06754333	0
89783.02	0.06529106	0
89813.02	0.06322003	0
89843.02	0.06135786	0
89873.02	0.05966062	0
89903.02	0.05803556	0
89933.02	0.05662699	0
89963.02	0.05526873	0
89993.02	0.05399412	0
90023.02	0.05279512	0
90053.02	0.05171804	0
90083.02	0.05076107	0
90113.02	0.04984164	0
90143.02	0.04889573	0
90173.02	0.04796928	0
90203.02	0.04717064	0
90233.02	0.04642124	0
90263.02	0.04568877	0
90293.02	0.04501249	0
90323.02	0.04432719	0
90353.02	0.04364286	0
90383.02	0.04301882	0
90413.02	0.04241575	0
90443.02	0.0418631	0
90473.02	0.04132551	0
90503.02	0.04082379	0
90533.02	0.04029857	0
90563.02	0.03983491	0
90593.02	0.03938304	0
90623.02	0.0389538	0
90653.02	0.03850546	0
90683.02	0.03812043	0
90713.02	0.03767328	0
90743.02	0.03728578	0
90773.02	0.03692189	0
90803.02	0.03656974	0
90833.02	0.03622819	0
90863.02	0.03593226	0
90893.02	0.03564061	0
90923.02	0.03523764	0
90953.02	0.03490342	0
90983.02	0.03458844	0
91013.02	0.0343205	0
91043.02	0.03402104	0
91073.02	0.03371511	0
91103.02	0.03343954	0
91133.02	0.03318385	0
91163.02	0.03290942	0
91193.02	0.0327101	0
91223.02	0.03246307	0
91253.02	0.03220819	0
91283.02	0.03200669	0
91313.02	0.03178597	0
91343.02	0.03155942	0
91373.02	0.03132267	0
91403.02	0.03109851	0
91433.02	0.03092487	0
91463.02	0.03070424	0
91493.02	0.03051672	0
91523.02	0.03032092	0
91553.02	0.03014858	0
91583.02	0.02999765	0
91613.02	0.02984308	0
91643.02	0.02963624	0
91673.02	0.02943884	0
91703.02	0.02925345	0
91733.02	0.0290872	0
91763.02	0.02891131	0
91793.02	0.02871929	0
91823.02	0.02859525	0
91853.02	0.02838225	0
91883.02	0.02823155	0
91913.02	0.02805654	0
91943.02	0.02796811	0
91973.02	0.02780761	0
92003.02	0.02773821	0
92033.02	0.02763164	0
92063.02	0.02752109	0
92093.02	0.02737874	0
92123.02	0.02724369	0
92153.02	0.02711863	0
92183.02	0.02700526	0
92213.02	0.02684285	0
92243.02	0.0267365	0
92273.02	0.02663736	0
92303.02	0.02650838	0
92333.02	0.02636909	0
92363.02	0.0262458	0
92393.02	0.02612808	0
92423.02	0.02602301	0
92453.02	0.02592626	0
92483.02	0.02582996	0
92513.02	0.02570458	0
92543.02	0.02554716	0
92573.02	0.02543592	0
92603.02	0.02531453	0
92633.02	0.02521812	0
92663.02	0.0251084	0
92693.02	0.02503381	0
92723.02	0.02493252	0
92753.02	0.02486491	0
92783.02	0.02477639	0
92813.02	0.02467245	0
92843.02	0.02458749	0
92873.02	0.02448863	0
92903.02	0.02442905	0
92933.02	0.02437781	0
92963.02	0.02427087	0
92993.02	0.0241833	0
93023.02	0.02407996	0
93053.02	0.02398661	0
93083.02	0.02389745	0
93113.02	0.02380721	0
93143.02	0.02377744	0
93173.02	0.02370747	0
93203.02	0.02362158	0
93233.02	0.02355793	0
93263.02	0.02348517	0
93293.02	0.023453	0
93323.02	0.02336229	0
93353.02	0.02335149	0
93383.02	0.02327123	0
93413.02	0.02319339	0
93443.02	0.02313984	0
93473.02	0.02310801	0
93503.02	0.02301872	0
93533.02	0.02293157	0
93563.02	0.02285713	0
93593.02	0.02284161	0
93623.02	0.02279014	0
93653.02	0.02267913	0
93683.02	0.02259123	0
93713.02	0.02250898	0
93743.02	0.02244311	0
93773.02	0.02235687	0
93803.02	0.02228882	0
93833.02	0.02223643	0
93863.02	0.02219196	0
93893.02	0.02211906	0
93923.02	0.02205516	0
93953.02	0.02199659	0
93983.02	0.02194311	0
94013.02	0.02192109	0
94043.02	0.02188806	0
94073.02	0.02183111	0
94103.02	0.02177368	0
94133.02	0.02175024	0
94163.02	0.02168511	0
94193.02	0.02164169	0
94223.02	0.02161108	0
94253.02	0.02153481	0
94283.02	0.02153943	0
94313.02	0.02153551	0
94343.02	0.02147601	0
94373.02	0.02139795	0
94403.02	0.0213143	0
94433.02	0.02125249	0
94463.02	0.02119382	0
94493.02	0.02112993	0
94523.02	0.02111119	0
94553.02	0.0210597	0
94583.02	0.02101782	0
94613.02	0.02096999	0
94643.02	0.02095959	0
94673.02	0.02094399	0
94703.02	0.02089562	0
94733.02	0.02086973	0
94763.02	0.02080514	0
94793.02	0.02077183	0
94823.02	0.02073809	0
94853.02	0.02072396	0
94883.02	0.02064804	0
94913.02	0.02058854	0
94943.02	0.02057468	0
94973.02	0.02053894	0
95003.02	0.02050791	0
95033.02	0.02046075	0
95063.02	0.02041946	0
95093.02	0.02039693	0
95123.02	0.02036848	0
95153.02	0.02033559	0
95183.02	0.0202973	0
95213.02	0.02029515	0
95243.02	0.02025201	0
95273.02	0.02019239	0
95303.02	0.02015821	0
95333.02	0.0201462	0
95363.02	0.02008413	0
95393.02	0.02005671	0
95423.02	0.02004436	0
95453.02	0.01999643	0
95483.02	0.01995224	0
95513.02	0.01995991	0
95543.02	0.01991485	0
95573.02	0.0198676	0
95603.02	0.01983684	0
95633.02	0.01982054	0
95663.02	0.01980366	0
95693.02	0.01978274	0
95723.02	0.01972252	0
95753.02	0.01970547	0
95783.02	0.01965694	0
95813.02	0.01965888	0
95843.02	0.01963873	0
95873.02	0.01962538	0
95903.02	0.01960456	0
95933.02	0.01958748	0
95963.02	0.01954679	0
95993.02	0.01952134	0
96023.02	0.01948124	0
96053.02	0.01943788	0
96083.02	0.01942812	0
96113.02	0.01939035	0
96143.02	0.01937166	0
96173.02	0.01932819	0
96203.02	0.01930835	0
96233.02	0.01929709	0
96263.02	0.01928236	0
96293.02	0.01927979	0
96323.02	0.01923831	0
96353.02	0.01919615	0
96383.02	0.01917666	0
96413.02	0.01912703	0
96443.02	0.01911596	0
96473.02	0.01907684	0
96503.02	0.01904548	0
96533.02	0.0190339	0
96563.02	0.01903255	0
96593.02	0.0189994	0
96623.02	0.01898336	0
96653.02	0.01895016	0
96683.02	0.01891012	0
96713.02	0.01888956	0
96743.02	0.01886343	0
96773.02	0.01882483	0
96803.02	0.01885606	0
96833.02	0.01885539	0
96863.02	0.01880062	0
96893.02	0.01877976	0
96923.02	0.01874764	0
96953.02	0.01872197	0
96983.02	0.01870874	0
97013.02	0.01868109	0
97043.02	0.01871658	0
97073.02	0.0187156	0
97103.02	0.01867505	0
97133.02	0.0186385	0
97163.02	0.01858875	0
97193.02	0.0185914	0
97223.02	0.01855955	0
97253.02	0.01851366	0
97283.02	0.01849109	0
97313.02	0.01847996	0
97343.02	0.01846525	0
97373.02	0.01847841	0
97403.02	0.01847039	0
97433.02	0.01848569	0
97450.02	0.01848113	0