File: Y261_creep2.txt
Time	Strain	Shear Stress
[s]	[1]	[Pa]
70730.11	0.1011128	100
70730.51	0.1247803	100
70730.91	0.1330088	100
70731.3	0.1382588	100
70731.71	0.1421396	100
70732.11	0.1452451	100
70732.51	0.1478138	100
70732.91	0.1500486	100
70733.3	0.151991	100
70733.71	0.1537222	100
70734.11	0.1553046	100
70734.51	0.1567628	100
70734.91	0.1580922	100
70735.3	0.1593313	100
70735.71	0.1604989	100
70736.11	0.1616048	100
70736.51	0.16264	100
70736.91	0.1636156	100
70737.3	0.1645407	100
70737.71	0.1654412	100
70738.11	0.1663079	100
70738.51	0.1671247	100
70738.91	0.1678909	100
70739.3	0.1686299	100
70739.71	0.1693667	100
70740.11	0.1700798	100
70740.51	0.1707638	100
70740.91	0.1714055	100
70741.3	0.1720336	100
70741.71	0.1726552	100
70742.11	0.1732614	100
70742.51	0.1738419	100
70742.91	0.1743942	100
70743.3	0.1749312	100
70743.71	0.1754667	100
70744.11	0.1759885	100
70744.51	0.1764993	100
70744.91	0.176986	100
70745.3	0.1774628	100
70745.71	0.1779317	100
70746.11	0.1783927	100
70746.51	0.1788478	100
70746.91	0.1792833	100
70747.3	0.1797173	100
70747.71	0.1801397	100
70748.11	0.1805478	100
70748.51	0.1809549	100
70748.91	0.1813561	100
70749.3	0.1817517	100
70749.71	0.1821329	100
70750.11	0.1825018	100
70750.51	0.1828672	100
70750.91	0.1832395	100
70751.3	0.1836017	100
70751.71	0.1839491	100
70752.11	0.1842889	100
70752.51	0.1846311	100
70752.91	0.1849782	100
70753.3	0.1853155	100
70753.71	0.1856366	100
70754.11	0.1859519	100
70754.51	0.1862772	100
70754.91	0.1866072	100
70755.3	0.1869213	100
70755.71	0.1872103	100
70756.11	0.187518	100
70756.51	0.1878345	100
70756.91	0.1881421	100
70757.3	0.1884166	100
70757.71	0.1886887	100
70758.11	0.1889842	100
70758.51	0.189278	100
70758.91	0.1895485	100
70759.3	0.1897995	100
70759.71	0.1900701	100
70760.11	0.1903534	100
70760.51	0.1906224	100
70760.91	0.1908685	100
70761.3	0.1911217	100
70761.71	0.1913981	100
70762.11	0.1916656	100
70762.51	0.1918979	100
70762.91	0.1921301	100
70763.3	0.1923922	100
70763.71	0.1926522	100
70764.11	0.1928835	100
70764.51	0.1931011	100
70764.91	0.1933513	100
70765.3	0.1936062	100
70765.71	0.1938361	100
70766.11	0.1940495	100
70766.51	0.1942918	100
70766.91	0.1945362	100
70767.3	0.1947589	100
70767.71	0.1949642	100
70768.11	0.1951843	100
70768.51	0.195422	100
70768.91	0.1956422	100
70769.3	0.1958406	100
70769.71	0.196053	100
70770.11	0.1962882	100
70770.51	0.1965033	100
70770.91	0.1966908	100
70771.3	0.1968938	100
70771.71	0.1971177	100
70772.11	0.1973194	100
70772.51	0.197503	100
70772.91	0.1977017	100
70773.3	0.1979202	100
70773.71	0.198116	100
70774.11	0.1982903	100
70774.51	0.1984833	100
70774.91	0.1986928	100
70775.3	0.1988842	100
70775.71	0.1990569	100
70776.11	0.1992376	100
70776.51	0.1994368	100
70776.91	0.1996283	100
70777.3	0.1997943	100
70777.71	0.199975	100
70778.11	0.2001749	100
70778.51	0.2003633	100
70778.91	0.2005238	100
70779.3	0.2007011	100
70779.71	0.2008949	100
70780.11	0.2010719	100
70780.51	0.2012299	100
70780.91	0.2014041	100
70781.3	0.2015896	100
70781.71	0.2017603	100
70782.11	0.2019187	100
70782.51	0.2020923	100
70782.91	0.2022723	100
70783.3	0.2024326	100
70783.71	0.2025832	100
70784.11	0.2027559	100
70784.51	0.2029337	100
70784.91	0.2030899	100
70785.3	0.2032415	100
70785.71	0.2034066	100
70786.11	0.2035726	100
70786.51	0.2037184	100
70786.91	0.2038727	100
70787.3	0.2040381	100
70787.71	0.2041967	100
70788.11	0.2043404	100
70788.51	0.2044926	100
70788.91	0.2046556	100
70789.3	0.2048038	100
70789.71	0.2049441	100
70790.11	0.2050984	100
70790.51	0.2052568	100
70790.91	0.2053982	100
70791.3	0.2055392	100
70791.71	0.2056887	100
70792.11	0.2058398	100
70792.51	0.2059797	100
70792.91	0.2061223	100
70793.3	0.2062729	100
70793.71	0.2064195	100
70794.11	0.2065566	100
70794.51	0.2066862	100
70794.91	0.2068348	100
70795.3	0.2069753	100
70795.71	0.2071142	100
70796.11	0.20725	100
70796.51	0.2073917	100
70796.91	0.2075271	100
70797.3	0.2076652	100
70797.71	0.2077996	100
70798.11	0.2079355	100
70798.51	0.2080705	100
70798.91	0.2082071	100
70799.3	0.2083428	100
70799.71	0.208478	100
70800.11	0.2086062	100
70800.51	0.2087388	100
70800.91	0.2088713	100
70801.3	0.2089996	100
70801.71	0.2091327	100
70802.11	0.2092594	100
70802.51	0.2093906	100
70802.91	0.2095147	100
70803.3	0.2096408	100
70803.71	0.2097664	100
70804.11	0.2098866	100
70804.51	0.2100091	100
70804.91	0.2101366	100
70805.3	0.2102622	100
70805.71	0.2103802	100
70806.11	0.2105041	100
70806.51	0.2106279	100
70806.91	0.2107451	100
70807.3	0.2108585	100
70807.71	0.2109778	100
70808.11	0.211098	100
70808.51	0.2112138	100
70808.91	0.2113246	100
70809.3	0.2114435	100
70809.71	0.2115663	100
70810.11	0.2116823	100
70810.51	0.2117955	100
70810.91	0.211913	100
70811.3	0.2120343	100
70811.71	0.2121487	100
70812.11	0.212257	100
70812.51	0.212368	100
70812.91	0.2124909	100
70813.3	0.2125989	100
70813.71	0.2127023	100
70814.11	0.2128173	100
70814.51	0.2129397	100
70814.91	0.2130496	100
70815.3	0.2131538	100
70815.71	0.2132615	100
70816.11	0.2133799	100
70816.51	0.2134931	100
70816.91	0.2135924	100
70817.3	0.2136919	100
70817.71	0.2138066	100
70818.11	0.2139241	100
70818.51	0.2140302	100
70818.91	0.2141301	100
70819.3	0.2142408	100
70819.71	0.2143587	100
70820.11	0.2144601	100
70820.51	0.2145556	100
70820.91	0.2146708	100
70821.3	0.2147872	100
70821.71	0.2148854	100
70822.11	0.2149778	100
70822.51	0.2150895	100
70822.91	0.2152038	100
70823.3	0.2153033	100
70823.71	0.2153955	100
70824.11	0.2155012	100
70824.51	0.215617	100
70824.91	0.2157175	100
70825.3	0.2158036	100
70825.71	0.2159041	100
70826.11	0.216019	100
70826.51	0.2161189	100
70826.91	0.2162049	100
70827.3	0.2163006	100
70827.71	0.2164141	100
70828.11	0.2165124	100
70828.51	0.2165937	100
70828.91	0.2166859	100
70829.3	0.2167961	100
70829.71	0.2169053	100
70830.11	0.2169923	100
70830.51	0.2170782	100
70830.91	0.2171848	100
70831.3	0.217295	100
70831.71	0.217382	100
70832.11	0.2174642	100
70832.51	0.2175632	100
70832.91	0.2176791	100
70833.3	0.2177723	100
70833.71	0.2178501	100
70834.11	0.2179442	100
70834.51	0.2180526	100
70834.91	0.2181503	100
70835.3	0.2182262	100
70835.71	0.218318	100
70836.11	0.2184318	100
70836.51	0.2185258	100
70836.91	0.2185968	100
70837.3	0.2186828	100
70837.71	0.2187947	100
70838.11	0.2188932	100
70838.51	0.2189696	100
70838.91	0.2190492	100
70839.3	0.2191563	100
70839.71	0.2192564	100
70840.11	0.2193345	100
70840.51	0.2194088	100
70840.91	0.2195083	100
70841.3	0.2196134	100
70841.71	0.2196985	100
70842.11	0.2197689	100
70842.51	0.2198614	100
70842.91	0.2199701	100
70843.3	0.2200535	100
70843.71	0.2201248	100
70844.11	0.220206	100
70844.51	0.2203154	100
70844.91	0.2204098	100
70845.3	0.2204785	100
70845.71	0.2205535	100
70846.11	0.2206566	100
70846.51	0.2207543	100
70846.91	0.2208343	100
70847.3	0.2208996	100
70847.71	0.2209835	100
70848.11	0.2210889	100
70848.51	0.2211783	100
70848.91	0.2212461	100
70849.3	0.2213217	100
70849.71	0.2214262	100
70850.11	0.221521	100
70850.51	0.2215889	100
70850.91	0.2216549	100
70851.3	0.2217521	100
70851.71	0.2218503	100
70852.11	0.2219197	100
70852.51	0.2219858	100
70852.91	0.2220789	100
70853.3	0.2221811	100
70853.71	0.2222598	100
70854.11	0.2223234	100
70854.51	0.2224062	100
70854.91	0.2225125	100
70855.3	0.2225963	100
70855.71	0.2226583	100
70856.11	0.2227343	100
70856.51	0.2228349	100
70856.91	0.2229282	100
70857.3	0.2229881	100
70857.71	0.2230564	100
70858.11	0.223153	100
70858.51	0.223248	100
70858.91	0.2233116	100
70859.3	0.223378	100
70859.71	0.2234738	100
70860.11	0.2235695	100
70860.51	0.2236351	100
70860.91	0.223698	100
70861.3	0.2237922	100
70861.71	0.2238891	100
70862.11	0.2239587	100
70862.51	0.2240175	100
70862.91	0.2241066	100
70863.3	0.2242013	100
70863.71	0.2242672	100
70864.11	0.2243281	100
70864.51	0.2244217	100
70864.91	0.2245118	100
70865.3	0.2245671	100
70865.71	0.2246388	100
70866.11	0.2247401	100
70866.51	0.2248215	100
70866.91	0.2248753	100
70867.3	0.2249559	100
70867.71	0.2250566	100
70868.11	0.2251318	100
70868.51	0.225186	100
70868.91	0.2252659	100
70869.3	0.2253628	100
70869.71	0.2254216	100
70870.11	0.2254819	100
70870.51	0.2255748	100
70870.91	0.2256624	100
70871.3	0.2257167	100
70871.71	0.2257843	100
70872.11	0.2258826	100
70872.51	0.2259618	100
70872.91	0.2260122	100
70873.3	0.2260858	100
70873.71	0.2261828	100
70874.11	0.2262562	100
70874.51	0.2263095	100
70874.91	0.2263851	100
70875.3	0.2264812	100
70875.71	0.2265398	100
70876.11	0.2265951	100
70876.51	0.2266863	100
70876.91	0.2267689	100
70877.3	0.226822	100
70877.71	0.2268901	100
70878.11	0.2269841	100
70878.51	0.2270494	100
70878.91	0.2270993	100
70879.3	0.2271894	100
70879.71	0.227278	100
70880.11	0.2273311	100
70880.51	0.227399	100
70880.91	0.2274933	100
70881.3	0.2275548	100
70881.71	0.2276076	100
70882.11	0.2276935	100
70882.51	0.2277718	100
70882.91	0.2278197	100
70883.3	0.2279001	100
70883.71	0.227989	100
70884.11	0.228048	100
70884.51	0.2281025	100
70884.91	0.2281949	100
70885.3	0.2282613	100
70885.71	0.2283103	100
70886.11	0.2283973	100
70886.51	0.2284778	100
70886.91	0.2285282	100
70887.3	0.2285918	100
70887.71	0.2286833	100
70888.11	0.2287424	100
70888.51	0.2287973	100
70888.91	0.2288818	100
70889.3	0.2289518	100
70889.71	0.228998	100
70890.11	0.2290765	100
70890.51	0.2291669	100
70890.91	0.2292189	100
70891.3	0.2292822	100
70891.71	0.2293696	100
70892.11	0.2294292	100
70892.51	0.2294835	100
70892.91	0.229573	100
70893.3	0.229636	100
70893.71	0.2296846	100
70894.11	0.2297643	100
70894.51	0.2298437	100
70894.91	0.2298905	100
70895.3	0.2299655	100
70895.71	0.2300483	100
70896.11	0.2300954	100
70896.51	0.230163	100
70896.91	0.2302489	100
70897.3	0.2303093	100
70897.71	0.2303671	100
70898.11	0.2304539	100
70898.51	0.230514	100
70898.91	0.2305652	100
70899.3	0.2306486	100
70899.71	0.2307199	100
70900.11	0.2307661	100
70900.51	0.2308325	100
70900.91	0.2309149	100
70901.3	0.2309682	100
70901.71	0.2310223	100
70902.11	0.2311033	100
70902.51	0.2311617	100
70902.91	0.2312189	100
70903.3	0.2313014	100
70903.71	0.2313697	100
70904.11	0.2314185	100
70904.51	0.2314995	100
70904.91	0.2315639	100
70905.3	0.2316219	100
70905.71	0.2316977	100
70906.11	0.2317672	100
70906.51	0.2318094	100
70906.91	0.2318847	100
70907.3	0.2319501	100
70907.71	0.2319995	100
70908.11	0.2320614	100
70908.51	0.2321379	100
70908.91	0.2321847	100
70909.3	0.2322453	100
70909.71	0.2323235	100
70910.11	0.2323744	100
70910.51	0.2324307	100
70910.91	0.2325094	100
70911.3	0.2325688	100
70911.71	0.2326191	100
70912.11	0.2326926	100
70912.51	0.2327553	100
70912.91	0.2328023	100
70913.3	0.2328634	100
70913.71	0.2329391	100
70914.11	0.2329881	100
70914.51	0.2330466	100
70914.91	0.2331168	100
70915.3	0.2331724	100
70915.71	0.2332181	100
70916.11	0.2332863	100
70916.51	0.233355	100
70916.91	0.2334008	100
70917.3	0.2334568	100
70917.71	0.233528	100
70918.11	0.2335804	100
70918.51	0.2336295	100
70918.91	0.2336975	100
70919.3	0.2337601	100
70919.71	0.2338109	100
70920.11	0.2338779	100
70920.51	0.2339508	100
70920.91	0.2340035	100
70921.3	0.2340633	100
70921.71	0.2341346	100
70922.11	0.2341831	100
70922.51	0.2342386	100
70922.91	0.2343077	100
70923.3	0.2343647	100
70923.71	0.2344122	100
70924.11	0.2344721	100
70924.51	0.2345378	100
70924.91	0.2345872	100
70925.3	0.2346513	100
70925.71	0.2347149	100
70926.11	0.2347631	100
70926.51	0.2348155	100
70926.91	0.2348853	100
70927.3	0.2349412	100
70927.71	0.2349923	100
70928.11	0.2350498	100
70928.51	0.2351123	100
70928.91	0.2351612	100
70929.3	0.2352241	100
70929.71	0.2352864	100
70930.11	0.2353348	100
70930.51	0.235392	100
70930.91	0.2354557	100
70931.3	0.2355061	100
70931.71	0.2355575	100
70932.11	0.2356226	100
70932.51	0.2356726	100
70932.91	0.2357205	100
70933.3	0.23578	100
70933.71	0.2358404	100
70934.11	0.2358861	100
70934.51	0.235939	100
70934.91	0.2359962	100
70935.3	0.2360405	100
70935.71	0.2360915	100
70936.11	0.236149	100
70936.51	0.2361986	100
70936.91	0.2362453	100
70937.3	0.2363034	100
70937.71	0.2363584	100
70938.11	0.236408	100
70938.51	0.2364629	100
70938.91	0.2365206	100
70939.3	0.236571	100
70939.71	0.2366241	100
70940.11	0.2366862	100
70940.51	0.2367416	100
70940.91	0.2367962	100
70941.3	0.2368519	100
70941.71	0.2369095	100
70942.11	0.2369591	100
70942.51	0.237012	100
70942.91	0.2370681	100
70943.3	0.2371201	100
70943.71	0.2371728	100
70944.11	0.2372268	100
70944.51	0.2372819	100
70944.91	0.2373317	100
70945.3	0.2373872	100
70945.71	0.2374453	100
70946.11	0.2374972	100
70946.51	0.2375475	100
70946.91	0.2376039	100
70947.31	0.237656	100
70947.72	0.2377084	100
70948.12	0.2377641	100
70948.51	0.2378217	100
70948.91	0.2378774	100
70949.31	0.2379333	100
70949.72	0.2379886	100
70950.12	0.2380393	100
70950.51	0.2380923	100
70950.91	0.2381442	100
70951.31	0.2382022	100
70951.72	0.2382553	100
70952.12	0.2383125	100
70952.51	0.2383676	100
70952.91	0.2384215	100
70953.31	0.2384779	100
70953.72	0.2385308	100
70954.12	0.2385843	100
70954.51	0.2386352	100
70954.91	0.238691	100
70955.31	0.2387427	100
70955.72	0.238796	100
70956.12	0.2388494	100
70956.51	0.238899	100
70956.91	0.2389517	100
70957.31	0.2390042	100
70957.72	0.2390536	100
70958.12	0.239104	100
70958.51	0.2391552	100
70958.91	0.2392053	100
70959.31	0.2392533	100
70959.72	0.2393036	100
70960.12	0.2393595	100
70960.51	0.2394061	100
70960.91	0.2394549	100
70961.31	0.2395109	100
70961.72	0.2395649	100
70962.12	0.2396146	100
70962.51	0.2396686	100
70962.91	0.2397225	100
70963.31	0.239771	100
70963.72	0.2398239	100
70964.12	0.2398753	100
70964.51	0.2399242	100
70964.91	0.2399715	100
70965.31	0.2400288	100
70965.72	0.2400763	100
70966.12	0.2401262	100
70966.51	0.2401811	100
70966.91	0.2402311	100
70967.31	0.2402781	100
70967.72	0.2403371	100
70968.12	0.240389	100
70968.51	0.2404331	100
70968.91	0.2404887	100
70969.31	0.2405369	100
70969.72	0.2405805	100
70970.12	0.2406369	100
70970.51	0.2406889	100
70970.91	0.2407304	100
70971.31	0.2407839	100
70971.72	0.2408329	100
70972.12	0.240876	100
70972.51	0.2409279	100
70972.91	0.2409773	100
70973.31	0.2410192	100
70973.72	0.2410712	100
70974.12	0.241125	100
70974.51	0.2411626	100
70974.91	0.2412157	100
70975.31	0.2412707	100
70975.72	0.2413118	100
70976.12	0.2413634	100
70976.51	0.2414169	100
70976.91	0.2414594	100
70977.31	0.2415098	100
70977.72	0.2415589	100
70978.12	0.241596	100
70978.51	0.241649	100
70978.91	0.2416996	100
70979.31	0.2417386	100
70979.72	0.241796	100
70980.12	0.2418401	100
70980.51	0.2418844	100
70980.91	0.2419403	100
70981.31	0.2419883	100
70981.72	0.2420294	100
70982.12	0.24209	100
70982.51	0.242137	100
70982.91	0.2421754	100
70983.31	0.242236	100
70983.72	0.2422844	100
70984.12	0.2423248	100
70984.51	0.2423853	100
70984.91	0.2424265	100
70985.31	0.2424667	100
70985.72	0.2425292	100
70986.12	0.2425736	100
70986.51	0.2426153	100
70986.91	0.2426731	100
70987.31	0.2427143	100
70987.72	0.2427537	100
70988.12	0.2428161	100
70988.51	0.2428565	100
70988.91	0.2429005	100
70989.31	0.2429592	100
70989.72	0.2430013	100
70990.12	0.2430433	100
70990.51	0.243107	100
70990.91	0.2431409	100
70991.31	0.2431879	100
70991.72	0.2432468	100
70992.12	0.2432801	100
70992.51	0.2433279	100
70992.91	0.2433852	100
70993.31	0.2434142	100
70993.72	0.2434621	100
70994.12	0.2435159	100
70994.51	0.2435479	100
70994.91	0.243606	100
70995.31	0.2436556	100
70995.72	0.2436906	100
70996.12	0.243747	100
70996.51	0.2437966	100
70996.91	0.243834	100
70997.31	0.2438929	100
70997.72	0.2439372	100
70998.12	0.24397	100
70998.51	0.244031	100
70998.91	0.2440696	100
70999.31	0.2441132	100
70999.72	0.244175	100
71000.12	0.2442127	100
71000.51	0.2442528	100
71000.91	0.2443153	100
71001.31	0.2443474	100
71001.72	0.2443936	100
71002.12	0.2444542	100
71002.51	0.2444818	100
71002.91	0.2445282	100
71003.31	0.2445862	100
71003.72	0.2446121	100
71004.12	0.2446729	100
71004.51	0.2447249	100
71004.91	0.2447529	100
71005.31	0.2448112	100
71005.72	0.2448616	100
71006.12	0.2448918	100
71006.51	0.2449491	100
71006.91	0.2449919	100
71007.31	0.2450231	100
71007.72	0.245084	100
71008.12	0.2451189	100
71008.51	0.245162	100
71008.91	0.2452251	100
71009.31	0.24525	100
71009.72	0.2452998	100
71010.12	0.2453509	100
71010.51	0.2453777	100
71010.91	0.2454331	100
71011.31	0.2454804	100
71011.72	0.2455075	100
71012.12	0.2455666	100
71012.51	0.2456083	100
71012.91	0.2456423	100
71013.31	0.2457058	100
71013.72	0.2457433	100
71014.12	0.2457768	100
71014.51	0.2458392	100
71014.91	0.2458719	100
71015.31	0.2459057	100
71015.72	0.2459718	100
71016.12	0.2459948	100
71016.51	0.246043	100
71016.91	0.2460943	100
71017.31	0.2461229	100
71017.72	0.2461812	100
71018.12	0.2462206	100
71018.51	0.2462508	100
71018.91	0.2463147	100
71019.31	0.246348	100
71019.72	0.2463817	100
71020.12	0.2464467	100
71020.51	0.2464787	100
71020.91	0.2465139	100
71021.31	0.2465787	100
71021.72	0.2466014	100
71022.12	0.2466473	100
71022.51	0.2467033	100
71022.91	0.2467278	100
71023.31	0.2467904	100
71023.72	0.2468367	100
71024.12	0.2468651	100
71024.51	0.2469302	100
71024.91	0.2469682	100
71025.31	0.2470037	100
71025.72	0.2470699	100
71026.12	0.247097	100
71026.51	0.2471413	100
71026.91	0.2472005	100
71027.31	0.2472201	100
71027.72	0.2472702	100
71028.12	0.2473287	100
71028.51	0.2473475	100
71028.91	0.2474068	100
71029.31	0.2474529	100
71029.72	0.2474755	100
71030.12	0.2475395	100
71030.51	0.2475729	100
71030.91	0.2476046	100
71031.31	0.2476678	100
71031.72	0.2476897	100
71032.12	0.2477351	100
71032.51	0.2477932	100
71032.91	0.2478111	100
71033.31	0.2478689	100
71033.72	0.2479148	100
71034.12	0.2479377	100
71034.51	0.248002	100
71034.91	0.2480348	100
71035.31	0.2480689	100
71035.72	0.248134	100
71036.12	0.2481571	100
71036.51	0.2482033	100
71036.91	0.2482612	100
71037.31	0.2482801	100
71037.72	0.2483357	100
71038.12	0.2483839	100
71038.51	0.2484042	100
71038.91	0.2484644	100
71039.31	0.2485084	100
71039.72	0.2485279	100
71040.12	0.2485936	100
71040.51	0.248629	100
71040.91	0.2486547	100
71041.31	0.2487195	100
71041.72	0.2487467	100
71042.12	0.248781	100
71042.51	0.2488437	100
71042.91	0.2488655	100
71043.31	0.2489098	100
71043.72	0.2489696	100
71044.12	0.2489849	100
71044.51	0.2490383	100
71044.91	0.249092	100
71045.31	0.249109	100
71045.72	0.2491712	100
71046.12	0.2492159	100
71046.51	0.2492339	100
71046.91	0.2492978	100
71047.31	0.2493378	100
71047.72	0.2493616	100
71048.12	0.2494275	100
71048.51	0.2494548	100
71048.91	0.2494864	100
71049.31	0.2495519	100
71049.72	0.2495747	100
71050.12	0.2496124	100
71050.51	0.2496744	100
71050.91	0.2496934	100
71051.31	0.2497402	100
71051.72	0.2497993	100
71052.12	0.249816	100
71052.51	0.2498676	100
71052.91	0.2499244	100
71053.31	0.2499394	100
71053.72	0.2499996	100
71054.12	0.2500439	100
71054.51	0.2500657	100
71054.91	0.2501278	100
71055.31	0.2501641	100
71055.72	0.2501894	100
71056.12	0.2502583	100
71056.51	0.2502809	100
71056.91	0.2503188	100
71057.31	0.2503828	100
71057.72	0.2503979	100
71058.12	0.2504432	100
71058.51	0.2505081	100
71058.91	0.2505249	100
71059.31	0.2505764	100
71059.72	0.2506347	100
71060.12	0.2506534	100
71060.51	0.2507061	100
71060.91	0.2507652	100
71061.31	0.2507811	100
71061.72	0.2508392	100
71062.12	0.2508871	100
71062.51	0.2509015	100
71062.91	0.2509651	100
71063.31	0.2510032	100
71063.72	0.2510258	100
71064.12	0.251091	100
71064.51	0.2511251	100
71064.91	0.2511507	100
71065.31	0.2512168	100
71065.72	0.2512485	100
71066.12	0.251275	100
71066.51	0.2513442	100
71066.91	0.2513626	100
71067.31	0.2514016	100
71067.72	0.2514616	100
71068.12	0.2514778	100
71068.51	0.2515266	100
71068.91	0.2515877	100
71069.31	0.2516009	100
71069.72	0.2516545	100
71070.12	0.2517028	100
71070.51	0.2517203	100
71070.91	0.2517867	100
71071.31	0.2518253	100
71071.72	0.251846	100
71072.12	0.2519162	100
71072.51	0.251948	100
71072.91	0.2519755	100
71073.31	0.2520428	100
71073.72	0.2520674	100
71074.12	0.2520968	100
71074.51	0.2521635	100
71074.91	0.252184	100
71075.31	0.2522214	100
71075.72	0.2522865	100
71076.12	0.2523043	100
71076.51	0.25235	100
71076.91	0.2524129	100
71077.31	0.2524324	100
71077.72	0.2524745	100
71078.13	0.2525396	100
71078.52	0.2525562	100
71078.92	0.2526017	100
71079.32	0.2526635	100
71079.73	0.2526811	100
71080.13	0.2527203	100
71080.52	0.252783	100
71080.92	0.2528027	100
71081.32	0.2528344	100
71081.73	0.2529014	100
71082.13	0.2529292	100
71082.52	0.2529557	100
71082.92	0.25302	100
71083.32	0.2530634	100
71083.73	0.2530785	100
71084.13	0.2531312	100
71084.52	0.2531904	100
71084.92	0.2532051	100
71085.32	0.2532484	100
71085.73	0.2533109	100
71086.13	0.2533323	100
71086.52	0.2533727	100
71086.92	0.2534369	100
71087.32	0.2534565	100
71087.73	0.2534891	100
71088.13	0.2535521	100
71088.52	0.2535828	100
71088.92	0.253605	100
71089.32	0.2536713	100
71089.73	0.2537068	100
71090.13	0.2537236	100
71090.52	0.2537812	100
71090.92	0.2538291	100
71091.32	0.2538408	100
71091.73	0.2538831	100
71092.13	0.2539443	100
71092.52	0.2539634	100
71092.92	0.2539932	100
71093.32	0.2540528	100
71093.73	0.2540881	100
71094.13	0.2541058	100
71094.52	0.2541657	100
71094.92	0.254212	100
71095.32	0.2542283	100
71095.73	0.2542718	100
71096.13	0.2543308	100
71096.52	0.2543488	100
71096.92	0.2543795	100
71097.32	0.2544431	100
71097.73	0.2544742	100
71098.13	0.2544942	100
71098.52	0.2545528	100
71098.92	0.2545958	100
71099.32	0.2546102	100
71099.73	0.2546628	100
71100.13	0.254716	100
71100.52	0.2547365	100
71100.92	0.254776	100
71101.32	0.2548405	100
71101.73	0.2548603	100
71102.13	0.2548861	100
71102.52	0.2549482	100
71102.92	0.2549817	100
71103.32	0.2550032	100
71103.73	0.2550593	100
71104.13	0.2551004	100
71104.52	0.2551079	100
71104.92	0.2551635	100
71105.32	0.2552096	100
71105.73	0.2552219	100
71106.13	0.2552711	100
71106.52	0.2553254	100
71106.92	0.2553368	100
71107.32	0.2553776	100
71107.73	0.2554377	100
71108.13	0.2554563	100
71108.52	0.2554868	100
71108.92	0.2555464	100
71109.32	0.255572	100
71109.73	0.2555921	100
71110.13	0.2556601	100
71110.52	0.2556843	100
71110.92	0.2557078	100
71111.32	0.2557663	100
71111.73	0.2558032	100
71112.13	0.2558186	100
71112.52	0.2558698	100
71112.92	0.2559145	100
71113.32	0.2559273	100
71113.73	0.2559766	100
71114.13	0.2560245	100
71114.52	0.2560348	100
71114.92	0.2560817	100
71115.32	0.2561361	100
71115.73	0.25615	100
71116.13	0.2561876	100
71116.52	0.2562477	100
71116.92	0.2562578	100
71117.32	0.2562951	100
71117.73	0.2563548	100
71118.13	0.2563716	100
71118.52	0.2564062	100
71118.92	0.256467	100
71119.32	0.2564912	100
71119.73	0.256513	100
71120.13	0.2565708	100
71120.52	0.2566078	100
71120.92	0.2566209	100
71121.32	0.2566731	100
71121.73	0.256717	100
71122.13	0.2567274	100
71122.52	0.2567806	100
71122.92	0.2568296	100
71123.32	0.256841	100
71123.73	0.2568884	100
71124.13	0.256941	100
71124.52	0.2569541	100
71124.92	0.2570007	100
71125.32	0.2570506	100
71125.73	0.2570658	100
71126.13	0.2571	100
71126.52	0.2571545	100
71126.92	0.2571695	100
71127.32	0.2571992	100
71127.73	0.2572579	100
71128.13	0.257275	100
71128.52	0.2573012	100
71128.92	0.2573598	100
71129.32	0.2573769	100
71129.73	0.2574017	100
71130.13	0.257461	100
71130.52	0.257486	100
71130.92	0.2575063	100
71131.32	0.2575636	100
71131.73	0.257593	100
71132.13	0.2576112	100
71132.52	0.2576671	100
71132.92	0.2577035	100
71133.32	0.2577185	100
71133.73	0.2577706	100
71134.13	0.2578106	100
71134.52	0.257824	100
71134.92	0.2578726	100
71135.32	0.2579181	100
71135.73	0.2579284	100
71136.13	0.2579734	100
71136.52	0.2580197	100
71136.92	0.2580383	100
71137.32	0.2580736	100
71137.73	0.258129	100
71138.13	0.2581459	100
71138.52	0.2581767	100
71138.92	0.2582331	100
71139.32	0.2582497	100
71139.73	0.2582774	100
71140.13	0.2583345	100
71140.52	0.258359	100
71140.92	0.2583815	100
71141.32	0.2584396	100
71141.73	0.2584712	100
71142.13	0.2584862	100
71142.52	0.2585413	100
71142.92	0.2585785	100
71143.32	0.2585915	100
71143.73	0.2586436	100
71144.13	0.2586844	100
71144.52	0.2586986	100
71144.92	0.2587487	100
71145.32	0.2587906	100
71145.73	0.2588063	100
71146.13	0.2588571	100
71146.52	0.2588943	100
71146.92	0.2589079	100
71147.32	0.2589605	100
71147.73	0.2590041	100
71148.13	0.259016	100
71148.52	0.2590573	100
71148.92	0.2591068	100
71149.32	0.2591243	100
71149.73	0.2591532	100
71150.13	0.2592081	100
71150.52	0.2592352	100
71150.92	0.2592545	100
71151.32	0.2593079	100
71151.73	0.259341	100
71152.13	0.259356	100
71152.52	0.2594047	100
71152.92	0.2594475	100
71153.32	0.2594601	100
71153.73	0.2594973	100
71154.13	0.2595491	100
71154.52	0.2595704	100
71154.92	0.2595942	100
71155.32	0.2596468	100
71155.73	0.2596794	100
71156.13	0.2596962	100
71156.52	0.2597409	100
71156.92	0.2597857	100
71157.32	0.2598045	100
71157.73	0.2598331	100
71158.13	0.2598867	100
71158.52	0.2599211	100
71158.92	0.259936	100
71159.32	0.2599791	100
71159.73	0.2600278	100
71160.13	0.2600495	100
71160.52	0.2600728	100
71160.92	0.2601229	100
71161.32	0.2601588	100
71161.73	0.2601705	100
71162.13	0.2602067	100
71162.52	0.2602552	100
71162.92	0.260273	100
71163.32	0.2603017	100
71163.73	0.26035	100
71164.13	0.2603864	100
71164.52	0.2604033	100
71164.92	0.2604372	100
71165.32	0.2604869	100
71165.73	0.2605108	100
71166.13	0.2605324	100
71166.52	0.2605775	100
71166.92	0.2606177	100
71167.32	0.2606312	100
71167.73	0.2606675	100
71168.13	0.2607158	100
71168.52	0.2607372	100
71168.92	0.2607599	100
71169.32	0.2608107	100
71169.73	0.2608474	100
71170.13	0.2608636	100
71170.52	0.2609014	100
71170.92	0.260949	100
71171.32	0.260977	100
71171.73	0.2609976	100
71172.13	0.2610428	100
71172.52	0.2610856	100
71172.92	0.2611074	100
71173.32	0.2611311	100
71173.73	0.2611817	100
71174.13	0.2612213	100
71174.52	0.2612371	100
71174.92	0.2612705	100
71175.32	0.2613206	100
71175.73	0.2613496	100
71176.13	0.2613677	100
71176.52	0.2614118	100
71176.92	0.2614536	100
71177.32	0.2614706	100
71177.73	0.2615017	100
71178.13	0.2615505	100
71178.52	0.2615806	100
71178.92	0.2616024	100
71179.32	0.2616488	100
71179.73	0.2616845	100
71180.13	0.2617052	100
71180.52	0.2617421	100
71180.92	0.2617869	100
71181.32	0.26181	100
71181.73	0.2618327	100
71182.13	0.2618791	100
71182.52	0.261919	100
71182.92	0.2619395	100
71183.32	0.2619732	100
71183.73	0.2620177	100
71184.13	0.262047	100
71184.52	0.2620652	100
71184.92	0.2621112	100
71185.32	0.2621527	100
71185.73	0.2621749	100
71186.13	0.2622001	100
71186.52	0.2622494	100
71186.92	0.2622834	100
71187.32	0.2623064	100
71187.73	0.2623432	100
71188.13	0.2623857	100
71188.52	0.2624074	100
71188.92	0.2624343	100
71189.32	0.2624849	100
71189.73	0.2625164	100
71190.13	0.2625364	100
71190.52	0.2625709	100
71190.92	0.2626152	100
71191.32	0.2626381	100
71191.73	0.2626703	100
71192.13	0.2627115	100
71192.52	0.2627456	100
71192.92	0.2627653	100
71193.32	0.2628024	100
71193.73	0.2628427	100
71194.13	0.262873	100
71194.52	0.2628906	100
71194.92	0.2629311	100
71195.32	0.2629629	100
71195.73	0.2629802	100
71196.13	0.2630093	100
71196.52	0.263048	100
71196.92	0.2630746	100
71197.32	0.263096	100
71197.73	0.2631319	100
71198.13	0.263174	100
71198.52	0.2631997	100
71198.92	0.2632228	100
71199.32	0.2632665	100
71199.73	0.263302	100
71200.13	0.2633261	100
71200.52	0.2633542	100
71200.92	0.2633974	100
71201.32	0.263434	100
71201.73	0.2634544	100
71202.13	0.2634855	100
71202.52	0.2635306	100
71202.92	0.2635629	100
71203.32	0.2635841	100
71203.73	0.2636166	100
71204.13	0.2636586	100
71204.52	0.2636849	100
71204.92	0.263708	100
71205.32	0.2637462	100
71205.73	0.2637846	100
71206.13	0.2638083	100
71206.52	0.2638311	100
71206.92	0.2638683	100
71207.32	0.2639057	100
71207.73	0.2639303	100
71208.13	0.2639567	100
71208.52	0.2639977	100
71208.92	0.2640367	100
71209.33	0.2640611	100
71209.73	0.2640887	100
71210.13	0.2641265	100
71210.53	0.264158	100
71210.93	0.2641806	100
71211.33	0.2642112	100
71211.73	0.264249	100
71212.13	0.2642788	100
71212.53	0.2643035	100
71212.93	0.2643349	100
71213.33	0.2643741	100
71213.73	0.2644059	100
71214.13	0.26443	100
71214.53	0.2644556	100
71214.93	0.2644949	100
71215.33	0.2645256	100
71215.73	0.2645537	100
71216.13	0.2645771	100
71216.53	0.2646145	100
71216.93	0.2646491	100
71217.33	0.2646744	100
71217.73	0.2646986	100
71218.13	0.2647303	100
71218.53	0.2647691	100
71218.93	0.2647965	100
71219.33	0.2648181	100
71219.73	0.2648476	100
71220.13	0.2648863	100
71220.53	0.2649163	100
71220.93	0.2649392	100
71221.33	0.2649636	100
71221.73	0.2650022	100
71222.13	0.2650367	100
71222.53	0.2650652	100
71222.93	0.2650891	100
71223.33	0.265121	100
71223.73	0.2651596	100
71224.13	0.2651867	100
71224.53	0.2652129	100
71224.93	0.2652408	100
71225.33	0.2652807	100
71225.73	0.2653098	100
71226.13	0.2653361	100
71226.53	0.2653671	100
71226.93	0.2654035	100
71227.33	0.2654318	100
71227.73	0.2654559	100
71228.13	0.2654871	100
71228.53	0.2655209	100
71228.93	0.265557	100
71229.33	0.2655824	100
71229.73	0.2656142	100
71230.13	0.2656485	100
71230.53	0.2656823	100
71230.93	0.2657075	100
71231.33	0.265736	100
71231.73	0.2657716	100
71232.13	0.2658031	100
71232.53	0.2658296	100
71232.93	0.2658532	100
71233.33	0.2658913	100
71233.73	0.2659246	100
71234.13	0.2659529	100
71234.53	0.2659748	100
71234.93	0.266009	100
71235.33	0.2660398	100
71235.73	0.2660686	100
71236.13	0.266095	100
71236.53	0.266122	100
71236.93	0.2661522	100
71237.33	0.2661781	100
71237.73	0.2662041	100
71238.13	0.2662311	100
71238.53	0.2662632	100
71238.93	0.266292	100
71239.33	0.2663224	100
71239.73	0.2663514	100
71240.13	0.2663859	100
71240.53	0.2664191	100
71240.93	0.266449	100
71241.33	0.2664738	100
71241.73	0.2665098	100
71242.13	0.266544	100
71242.53	0.2665739	100
71242.93	0.2666005	100
71243.33	0.2666308	100
71243.73	0.2666631	100
71244.13	0.2666931	100
71244.53	0.2667211	100
71244.93	0.2667481	100
71245.33	0.2667806	100
71245.73	0.2668096	100
71246.13	0.2668383	100
71246.53	0.2668672	100
71246.93	0.2668998	100
71247.33	0.2669314	100
71247.73	0.2669604	100
71248.13	0.2669917	100
71248.53	0.2670267	100
71248.93	0.2670583	100
71249.33	0.2670835	100
71249.73	0.2671127	100
71250.13	0.2671513	100
71250.52	0.2671787	100
71250.92	0.2672091	100
71251.32	0.2672398	100
71251.73	0.2672742	100
71252.13	0.2673042	100
71252.52	0.2673315	100
71252.92	0.2673613	100
71253.32	0.2673901	100
71253.73	0.2674228	100
71254.13	0.267451	100
71254.52	0.2674771	100
71254.92	0.2675051	100
71255.32	0.2675362	100
71255.73	0.2675648	100
71256.13	0.267591	100
71256.52	0.2676183	100
71256.92	0.2676472	100
71257.32	0.2676738	100
71257.73	0.2677008	100
71258.13	0.2677285	100
71258.52	0.2677609	100
71258.92	0.2677895	100
71259.32	0.267821	100
71259.73	0.2678518	100
71260.13	0.26788	100
71260.52	0.2679108	100
71260.92	0.2679404	100
71261.32	0.2679712	100
71261.73	0.2679984	100
71262.13	0.2680297	100
71262.52	0.2680586	100
71262.92	0.2680867	100
71263.32	0.2681144	100
71263.73	0.2681415	100
71264.13	0.2681682	100
71264.52	0.2681969	100
71264.92	0.2682252	100
71265.32	0.2682562	100
71265.73	0.2682854	100
71266.13	0.2683145	100
71266.52	0.2683416	100
71266.92	0.26837	100
71267.32	0.2683998	100
71267.73	0.2684295	100
71268.13	0.2684586	100
71268.52	0.2684863	100
71268.92	0.2685155	100
71269.32	0.2685449	100
71269.73	0.2685744	100
71270.13	0.2686013	100
71270.52	0.2686328	100
71270.92	0.2686605	100
71271.32	0.2686878	100
71271.73	0.2687139	100
71272.13	0.2687428	100
71272.52	0.2687711	100
71272.92	0.2687989	100
71273.32	0.2688268	100
71273.73	0.268854	100
71274.13	0.2688849	100
71274.52	0.2689133	100
71274.92	0.2689361	100
71275.32	0.2689625	100
71275.73	0.2689934	100
71276.13	0.2690289	100
71276.52	0.2690607	100
71276.92	0.2690863	100
71277.32	0.2691161	100
71277.73	0.2691456	100
71278.13	0.2691772	100
71278.52	0.2692053	100
71278.92	0.2692374	100
71279.32	0.2692673	100
71279.73	0.2693006	100
71280.13	0.2693291	100
71280.52	0.2693542	100
71280.92	0.2693837	100
71281.32	0.2694139	100
71281.73	0.269443	100
71282.13	0.2694687	100
71282.52	0.2694944	100
71282.92	0.2695275	100
71283.31	0.2695558	100
71283.72	0.2695802	100
71284.12	0.2696047	100
71284.51	0.2696336	100
71284.91	0.2696608	100
71285.31	0.2696889	100
71285.72	0.2697083	100
71286.12	0.2697326	100
71286.51	0.2697627	100
71286.91	0.2697955	100
71287.31	0.2698207	100
71287.72	0.2698442	100
71288.12	0.2698693	100
71288.51	0.2699048	100
71288.91	0.2699353	100
71289.31	0.2699664	100
71289.72	0.2699909	100
71290.12	0.2700149	100
71290.51	0.2700451	100
71290.91	0.2700739	100
71291.31	0.2700996	100
71291.72	0.270121	100
71292.12	0.2701535	100
71292.51	0.270183	100
71292.91	0.2702132	100
71293.31	0.2702366	100
71293.72	0.2702662	100
71294.12	0.2702927	100
71294.51	0.2703266	100
71294.91	0.2703512	100
71295.31	0.2703774	100
71295.72	0.2704039	100
71296.12	0.270436	100
71296.51	0.2704633	100
71296.91	0.2704847	100
71297.31	0.270506	100
71297.72	0.2705309	100
71298.12	0.2705625	100
71298.51	0.2705906	100
71298.91	0.2706183	100
71299.31	0.2706412	100
71299.72	0.2706762	100
71300.12	0.2707065	100
71300.51	0.2707335	100
71300.91	0.2707569	100
71301.31	0.2707821	100
71301.72	0.270818	100
71302.12	0.2708391	100
71302.51	0.2708633	100
71302.91	0.2708823	100
71303.31	0.2709164	100
71303.72	0.2709425	100
71304.12	0.270974	100
71304.51	0.2709918	100
71304.91	0.2710231	100
71305.31	0.2710528	100
71305.72	0.2710863	100
71306.12	0.2711082	100
71306.51	0.2711298	100
71306.91	0.2711632	100
71307.31	0.2711937	100
71307.72	0.2712206	100
71308.12	0.2712392	100
71308.51	0.2712621	100
71308.91	0.2712924	100
71309.31	0.271322	100
71309.72	0.2713396	100
71310.12	0.2713627	100
71310.51	0.2713899	100
71310.91	0.2714279	100
71311.31	0.2714512	100
71311.72	0.2714748	100
71312.12	0.2715007	100
71312.51	0.2715343	100
71312.91	0.2715662	100
71313.31	0.2715862	100
71313.72	0.2716116	100
71314.12	0.2716422	100
71314.51	0.2716781	100
71314.91	0.2717029	100
71315.31	0.2717221	100
71315.72	0.2717472	100
71316.11	0.2717825	100
71316.51	0.2718101	100
71316.91	0.2718289	100
71317.3	0.2718494	100
71317.71	0.2718859	100
71318.11	0.2719128	100
71318.51	0.2719316	100
71318.91	0.2719533	100
71319.3	0.2719884	100
71319.71	0.2720216	100
71320.11	0.2720416	100
71320.51	0.272066	100
71320.91	0.2720988	100
71321.3	0.2721331	100
71321.71	0.2721494	100
71322.11	0.2721709	100
71322.51	0.2722023	100
71322.91	0.2722374	100
71323.3	0.2722573	100
71323.71	0.2722757	100
71324.11	0.2723084	100
71324.51	0.2723414	100
71324.91	0.2723601	100
71325.3	0.2723785	100
71325.71	0.272412	100
71326.11	0.2724414	100
71326.51	0.2724638	100
71326.91	0.2724804	100
71327.3	0.272517	100
71327.71	0.2725483	100
71328.11	0.272569	100
71328.51	0.2725862	100
71328.91	0.2726235	100
71329.3	0.2726569	100
71329.71	0.2726788	100
71330.01	0.2727007	100