File: Y261_recov2.txt
Time	Strain	Shear Stress
[s]	[1]	[Pa]
71330.11	0.214779	0.0000000000000000000000007965861
71330.51	0.1957991	0
71330.91	0.1885603	0
71331.3	0.1837974	0
71331.71	0.1801785	0
71332.11	0.1771985	0
71332.51	0.1746737	0
71332.91	0.1724407	0
71333.3	0.1704516	0
71333.71	0.1686826	0
71334.11	0.167049	0
71334.51	0.1655316	0
71334.91	0.1641593	0
71335.3	0.1628729	0
71335.71	0.1616414	0
71336.11	0.1604951	0
71336.51	0.1594442	0
71336.91	0.1584193	0
71337.3	0.1574191	0
71337.71	0.156486	0
71338.11	0.1555971	0
71338.51	0.15473	0
71338.91	0.1538985	0
71339.3	0.1531176	0
71339.71	0.1523568	0
71340.11	0.1516191	0
71340.51	0.1509009	0
71340.91	0.150202	0
71341.3	0.149521	0
71341.71	0.1488603	0
71342.11	0.1482131	0
71342.51	0.147582	0
71342.91	0.1469811	0
71343.3	0.1463911	0
71343.71	0.1458085	0
71344.11	0.1452445	0
71344.51	0.1447012	0
71344.91	0.1441557	0
71345.3	0.1436116	0
71345.71	0.1430991	0
71346.11	0.1425925	0
71346.51	0.1420701	0
71346.91	0.1415752	0
71347.3	0.1411108	0
71347.71	0.1406354	0
71348.11	0.1401469	0
71348.51	0.1397035	0
71348.91	0.1392646	0
71349.3	0.1388091	0
71349.71	0.1383686	0
71350.11	0.1379693	0
71350.51	0.1375512	0
71350.91	0.1371183	0
71351.3	0.1367187	0
71351.71	0.1363319	0
71352.11	0.1359163	0
71352.51	0.1355119	0
71352.91	0.1351532	0
71353.3	0.1347689	0
71353.71	0.1343667	0
71354.11	0.1340101	0
71354.51	0.1336629	0
71354.91	0.1332818	0
71355.3	0.132918	0
71355.71	0.1325926	0
71356.11	0.1322481	0
71356.51	0.1318872	0
71356.91	0.1315673	0
71357.3	0.131257	0
71357.71	0.1309068	0
71358.11	0.1305874	0
71358.51	0.1302906	0
71358.91	0.1299617	0
71359.3	0.1296446	0
71359.71	0.1293611	0
71360.11	0.1290397	0
71360.51	0.1287299	0
71360.91	0.1284538	0
71361.3	0.1281514	0
71361.71	0.1278443	0
71362.11	0.1275705	0
71362.51	0.1272907	0
71362.91	0.1269911	0
71363.3	0.1267188	0
71363.71	0.1264526	0
71364.11	0.1261613	0
71364.51	0.1258908	0
71364.91	0.1256394	0
71365.3	0.1253633	0
71365.71	0.1250894	0
71366.11	0.1248421	0
71366.51	0.1245863	0
71366.91	0.1243203	0
71367.3	0.1240699	0
71367.71	0.123824	0
71368.11	0.1235685	0
71368.51	0.1233249	0
71368.91	0.1230881	0
71369.3	0.1228392	0
71369.71	0.1225976	0
71370.11	0.1223654	0
71370.51	0.122129	0
71370.91	0.1218894	0
71371.3	0.1216595	0
71371.71	0.1214325	0
71372.11	0.1212008	0
71372.51	0.1209721	0
71372.91	0.1207497	0
71373.3	0.1205179	0
71373.71	0.1202949	0
71374.11	0.120069	0
71374.51	0.1198543	0
71374.91	0.1196364	0
71375.3	0.1194177	0
71375.71	0.1192016	0
71376.11	0.1189852	0
71376.51	0.1187762	0
71376.91	0.1185656	0
71377.3	0.1183602	0
71377.71	0.118143	0
71378.11	0.1179423	0
71378.51	0.1177335	0
71378.91	0.1175301	0
71379.3	0.1173266	0
71379.71	0.1171335	0
71380.11	0.1169238	0
71380.51	0.1167297	0
71380.91	0.1165429	0
71381.3	0.1163349	0
71381.71	0.1161413	0
71382.11	0.1159551	0
71382.51	0.1157525	0
71382.91	0.1155655	0
71383.3	0.1153844	0
71383.71	0.1151843	0
71384.11	0.1150048	0
71384.51	0.1148258	0
71384.91	0.1146324	0
71385.3	0.1144526	0
71385.71	0.1142848	0
71386.11	0.1140867	0
71386.51	0.1139106	0
71386.91	0.1137435	0
71387.3	0.11355	0
71387.71	0.1133723	0
71388.11	0.1132149	0
71388.51	0.1130242	0
71388.91	0.1128473	0
71389.3	0.1126927	0
71389.71	0.1125031	0
71390.11	0.1123244	0
71390.51	0.1121713	0
71390.91	0.1119858	0
71391.3	0.1118041	0
71391.71	0.11166	0
71392.11	0.1114755	0
71392.51	0.1113031	0
71392.91	0.1111638	0
71393.3	0.1109804	0
71393.71	0.1108161	0
71394.11	0.1106757	0
71394.51	0.1104984	0
71394.91	0.1103341	0
71395.3	0.110198	0
71395.71	0.1100203	0
71396.11	0.1098656	0
71396.51	0.1097272	0
71396.91	0.109553	0
71397.3	0.1093975	0
71397.71	0.1092639	0
71398.11	0.1090933	0
71398.51	0.108948	0
71398.91	0.1088144	0
71399.3	0.1086361	0
71399.71	0.1084964	0
71400.11	0.1083604	0
71400.51	0.1081933	0
71400.91	0.1080606	0
71401.3	0.1079342	0
71401.71	0.1077617	0
71402.11	0.1076393	0
71402.51	0.107497	0
71402.91	0.1073358	0
71403.3	0.107222	0
71403.71	0.1070671	0
71404.11	0.1069159	0
71404.51	0.106799	0
71404.91	0.106639	0
71405.3	0.1064914	0
71405.71	0.1063776	0
71406.11	0.1062152	0
71406.51	0.106087	0
71406.91	0.1059619	0
71407.3	0.105798	0
71407.71	0.1056909	0
71408.11	0.1055451	0
71408.51	0.1053987	0
71408.91	0.1052884	0
71409.3	0.1051301	0
71409.71	0.1050088	0
71410.11	0.1048936	0
71410.51	0.1047359	0
71410.91	0.1046341	0
71411.3	0.1044997	0
71411.71	0.1043563	0
71412.11	0.1042528	0
71412.51	0.1041023	0
71412.91	0.1039765	0
71413.3	0.1038666	0
71413.71	0.1037144	0
71414.11	0.1036124	0
71414.51	0.1034894	0
71414.91	0.1033413	0
71415.3	0.1032434	0
71415.71	0.103101	0
71416.11	0.1029758	0
71416.51	0.1028743	0
71416.91	0.1027215	0
71417.3	0.1026232	0
71417.71	0.1024991	0
71418.11	0.1023635	0
71418.51	0.1022681	0
71418.91	0.1021303	0
71419.3	0.1020193	0
71419.71	0.1019131	0
71420.11	0.101769	0
71420.51	0.1016708	0
71420.91	0.1015347	0
71421.3	0.1014154	0
71421.71	0.1013181	0
71422.11	0.1011816	0
71422.51	0.101094	0
71422.91	0.1009674	0
71423.3	0.1008625	0
71423.71	0.100759	0
71424.11	0.100626	0
71424.51	0.1005381	0
71424.91	0.1004166	0
71425.3	0.1002979	0
71425.71	0.1002027	0
71426.11	0.1000633	0
71426.51	0.09997636	0
71426.91	0.09984762	0
71427.3	0.09974246	0
71427.71	0.09964428	0
71428.11	0.09951323	0
71428.51	0.0994324	0
71428.91	0.09929943	0
71429.3	0.09919649	0
71429.71	0.09909823	0
71431.01	0.09879892	0
71435.01	0.09774879	0
71439.01	0.09675297	0
71443.01	0.09579072	0
71447.01	0.09486792	0
71451.01	0.09396929	0
71455.01	0.0930966	0
71459.01	0.09224856	0
71463.01	0.0914161	0
71467.01	0.09060945	0
71471.01	0.08981156	0
71475.01	0.08903645	0
71479.01	0.08828925	0
71483.01	0.08756448	0
71487.01	0.08686711	0
71491.01	0.08618772	0
71495.01	0.08551588	0
71499.01	0.08487931	0
71503.01	0.08423172	0
71507.01	0.08360757	0
71511.01	0.08298283	0
71515.01	0.08237556	0
71519.01	0.08178803	0
71523.01	0.08121228	0
71527.01	0.08064966	0
71531.01	0.08009847	0
71535.01	0.07956227	0
71539.01	0.07903125	0
71543.01	0.0785037	0
71547.01	0.07799117	0
71551.01	0.07748778	0
71555.01	0.07701694	0
71559.01	0.07653629	0
71563.01	0.0760609	0
71567.01	0.07559557	0
71571.01	0.07513367	0
71575.01	0.07465435	0
71579.01	0.07420791	0
71583.01	0.07378293	0
71587.01	0.07337101	0
71591.01	0.07295802	0
71595.01	0.07256091	0
71599.01	0.07216028	0
71603.01	0.07176631	0
71607.01	0.0713749	0
71611.01	0.07099778	0
71615.01	0.07063823	0
71619.01	0.07027988	0
71623.01	0.06992608	0
71627.01	0.06957734	0
71631.01	0.06921747	0
71635.01	0.06886016	0
71639.01	0.06850598	0
71643.01	0.06817273	0
71647.01	0.06785113	0
71651.01	0.06753223	0
71655.01	0.06722337	0
71659.01	0.06689863	0
71663.01	0.06658477	0
71667.01	0.06628598	0
71671.01	0.06597995	0
71675.01	0.06567129	0
71679.01	0.06538716	0
71683.01	0.06509531	0
71687.01	0.06480097	0
71691.01	0.06452032	0
71695.01	0.06424128	0
71699.01	0.06395493	0
71703.01	0.06366772	0
71707.01	0.06340078	0
71711.01	0.06312383	0
71715.01	0.06286462	0
71719.01	0.06260676	0
71723.01	0.0623562	0
71727.01	0.06211168	0
71731.01	0.06187474	0
71735.01	0.06162032	0
71739.01	0.06137198	0
71743.01	0.06112425	0
71747.01	0.06088094	0
71751.01	0.06063788	0
71755.01	0.06039716	0
71759.01	0.06015351	0
71763.01	0.05992325	0
71767.01	0.05969294	0
71771.01	0.05947542	0
71775.01	0.05925076	0
71779.01	0.05902955	0
71783.01	0.05880545	0
71787.01	0.05857891	0
71791.01	0.05836428	0
71795.01	0.05815531	0
71799.01	0.05795035	0
71803.01	0.05774867	0
71807.01	0.05754928	0
71811.01	0.05735074	0
71815.01	0.05715472	0
71819.01	0.05695404	0
71823.01	0.05675845	0
71827.01	0.05656178	0
71831.01	0.05637595	0
71835.01	0.05617728	0
71839.01	0.0559959	0
71843.01	0.05581771	0
71847.01	0.05562889	0
71851.01	0.05543942	0
71855.01	0.05526571	0
71859.01	0.05508812	0
71863.01	0.05491712	0
71867.01	0.05472683	0
71871.01	0.05456191	0
71875.01	0.05437827	0
71879.01	0.05421125	0
71883.01	0.05403342	0
71887.01	0.05387388	0
71891.01	0.05370574	0
71895.01	0.05353668	0
71899.01	0.05337787	0
71903.01	0.05320925	0
71907.01	0.05303113	0
71911.01	0.05287134	0
71915.01	0.05269897	0
71919.01	0.05251875	0
71923.01	0.05236076	0
71927.01	0.05222381	0
71931.01	0.05207193	0
71935.01	0.051906	0
71939.01	0.05175516	0
71943.01	0.05160537	0
71947.01	0.05146597	0
71951.01	0.05133093	0
71955.01	0.05117955	0
71959.01	0.05103253	0
71963.01	0.05089738	0
71967.01	0.05075645	0
71971.01	0.05061492	0
71975.01	0.05047458	0
71979.01	0.05031811	0
71983.01	0.05017344	0
71987.01	0.0500326	0
71991.01	0.0498829	0
71995.01	0.04975314	0
71999.01	0.0496228	0
72003.01	0.04948842	0
72007.01	0.04934735	0
72011.01	0.0492187	0
72015.01	0.04909476	0
72019.01	0.04897134	0
72023.01	0.04885516	0
72027.01	0.04872416	0
72031.01	0.04858618	0
72035.01	0.04846285	0
72039.01	0.04834271	0
72043.01	0.04822015	0
72047.01	0.04809356	0
72051.01	0.04797075	0
72055.01	0.04784928	0
72059.01	0.04772164	0
72063.01	0.0475963	0
72067.01	0.04746758	0
72071.01	0.04734673	0
72075.01	0.0472267	0
72079.01	0.04710782	0
72083.01	0.04699652	0
72087.01	0.04688465	0
72091.01	0.04677186	0
72095.01	0.04666128	0
72099.01	0.04655267	0
72103.01	0.04643577	0
72107.01	0.04631709	0
72111.01	0.04620541	0
72115.01	0.04609736	0
72119.01	0.04599603	0
72123.01	0.04589477	0
72127.01	0.04578745	0
72131.01	0.04568879	0
72135.01	0.04559305	0
72139.01	0.04549259	0
72143.01	0.04539168	0
72147.01	0.04529218	0
72151.01	0.04519344	0
72155.01	0.04509027	0
72159.01	0.04499181	0
72163.01	0.04489522	0
72167.01	0.04480993	0
72171.01	0.04469793	0
72175.01	0.04459635	0
72179.01	0.04450121	0
72183.01	0.04440546	0
72187.01	0.04431791	0
72191.01	0.04423234	0
72195.01	0.04414496	0
72199.01	0.04405714	0
72203.01	0.04395855	0
72207.01	0.0438676	0
72211.01	0.0437803	0
72215.01	0.04368375	0
72219.01	0.04359784	0
72223.01	0.04350958	0
72227.01	0.04341412	0
72231.01	0.04332737	0
72235.01	0.04322529	0
72239.01	0.04314731	0
72243.01	0.04305241	0
72247.01	0.04295641	0
72251.01	0.04287161	0
72255.01	0.04278181	0
72259.01	0.04270125	0
72263.01	0.04262687	0
72267.01	0.04254406	0
72271.01	0.04246672	0
72275.01	0.0423892	0
72279.01	0.04229976	0
72283.01	0.04221316	0
72287.01	0.04212372	0
72291.01	0.04204202	0
72295.01	0.04195939	0
72299.01	0.04187872	0
72303.01	0.04180221	0
72307.01	0.04172562	0
72311.01	0.04164528	0
72315.01	0.04156666	0
72319.01	0.04149217	0
72323.01	0.04141465	0
72327.01	0.04133256	0
72331.01	0.04124695	0
72335.01	0.04116184	0
72339.01	0.04107817	0
72343.01	0.04100143	0
72347.01	0.04092561	0
72351.01	0.04084855	0
72355.01	0.04077211	0
72359.01	0.04069943	0
72363.01	0.04061838	0
72367.01	0.04054583	0
72371.01	0.04047803	0
72375.01	0.04040225	0
72379.01	0.04033465	0
72383.01	0.04027339	0
72387.01	0.0402029	0
72391.01	0.04012837	0
72395.01	0.04005525	0
72399.01	0.0399852	0
72403.01	0.03992012	0
72407.01	0.03985417	0
72411.01	0.03978291	0
72415.01	0.03971176	0
72419.01	0.03964483	0
72423.01	0.03956774	0
72427.01	0.03950668	0
72431.01	0.0394442	0
72435.01	0.03939354	0
72439.01	0.03932272	0
72443.01	0.03925703	0
72447.01	0.03919479	0
72451.01	0.03913219	0
72455.01	0.03906646	0
72459.01	0.03900068	0
72463.01	0.03893962	0
72467.01	0.03887616	0
72471.01	0.0388133	0
72475.01	0.03875642	0
72479.01	0.0386899	0
72483.01	0.03863359	0
72487.01	0.03857125	0
72491.01	0.03851166	0
72495.01	0.03845319	0
72499.01	0.03838839	0
72503.01	0.03833505	0
72507.01	0.03827323	0
72511.01	0.03819318	0
72515.01	0.0381319	0
72519.01	0.03807298	0
72523.01	0.03801058	0
72527.01	0.03794973	0
72531.01	0.03789329	0
72535.01	0.03784013	0
72539.01	0.03777871	0
72543.01	0.03772365	0
72547.01	0.03766639	0
72551.01	0.03760579	0
72555.01	0.03755264	0
72559.01	0.03750155	0
72563.01	0.03744355	0
72567.01	0.0373828	0
72571.01	0.03733006	0
72575.01	0.03726372	0
72579.01	0.03721238	0
72583.01	0.03715716	0
72587.01	0.03709583	0
72591.01	0.03703392	0
72595.01	0.03697531	0
72599.01	0.03691353	0
72603.01	0.0368384	0
72607.01	0.03676937	0
72611.01	0.03671278	0
72615.01	0.03667579	0
72619.01	0.03662735	0
72623.01	0.03657265	0
72627.01	0.03651308	0
72631.01	0.03645968	0
72635.01	0.03639485	0
72639.01	0.03633458	0
72643.01	0.0362743	0
72647.01	0.03622213	0
72651.01	0.03616996	0
72655.01	0.03611769	0
72659.01	0.03605788	0
72663.01	0.0359993	0
72667.01	0.03594911	0
72671.01	0.03590147	0
72675.01	0.03584624	0
72679.01	0.03578574	0
72683.01	0.03574202	0
72687.01	0.03569663	0
72691.01	0.03565055	0
72695.01	0.03561224	0
72699.01	0.03556857	0
72703.01	0.03551674	0
72707.01	0.03546466	0
72711.01	0.03541218	0
72715.01	0.03534462	0
72719.01	0.03528196	0
72723.01	0.03523505	0
72727.01	0.03519644	0
72731.01	0.03514169	0
72735.01	0.03511435	0
72739.01	0.0350618	0
72743.01	0.03500384	0
72747.01	0.03495451	0
72751.01	0.03489539	0
72755.01	0.0348537	0
72759.01	0.03481514	0
72763.01	0.0347678	0
72767.01	0.03471592	0
72771.01	0.0346648	0
72775.01	0.03462185	0
72779.01	0.03458346	0
72783.01	0.03454913	0
72787.01	0.03451521	0
72791.01	0.03447217	0
72795.01	0.0344324	0
72799.01	0.0343838	0
72803.01	0.03434003	0
72807.01	0.03431004	0
72811.01	0.03428127	0
72815.01	0.03424667	0
72819.01	0.03419168	0
72823.01	0.03412693	0
72827.01	0.03409474	0
72831.01	0.0340504	0
72835.01	0.03400521	0
72839.01	0.03396643	0
72843.01	0.03392602	0
72847.01	0.03388277	0
72851.01	0.03384248	0
72855.01	0.03380295	0
72859.01	0.03376157	0
72863.01	0.03371142	0
72867.01	0.03367447	0
72871.01	0.03364911	0
72875.01	0.03360582	0
72879.01	0.03357203	0
72883.01	0.03353361	0
72887.01	0.03349889	0
72891.01	0.03345919	0
72895.01	0.03340832	0
72899.01	0.03336797	0
72903.01	0.03332823	0
72907.01	0.03327869	0
72911.01	0.03324651	0
72915.01	0.03321088	0
72919.01	0.03318525	0
72923.01	0.0331443	0
72927.01	0.03308187	0
72931.01	0.03303702	0
72935.01	0.03298938	0
72939.01	0.032934	0
72943.01	0.03290916	0
72947.01	0.0328601	0
72951.01	0.03281619	0
72955.01	0.0327968	0
72959.01	0.03277161	0
72963.01	0.03274418	0
72967.01	0.03269648	0
72971.01	0.03265489	0
72975.01	0.03262752	0
72979.01	0.03259104	0
72983.01	0.03256162	0
72987.01	0.03252271	0
72991.01	0.03249572	0
72995.01	0.03245527	0
72999.01	0.03240479	0
73003.01	0.0323788	0
73007.01	0.03233844	0
73011.01	0.03231654	0
73015.01	0.03227598	0
73019.01	0.03224238	0
73023.01	0.03220784	0
73027.01	0.03216616	0
73031.01	0.03212843	0
73035.01	0.03210193	0
73039.01	0.03207498	0
73043.01	0.03205115	0
73047.01	0.03201757	0
73051.01	0.03199328	0
73055.01	0.0319534	0
73059.01	0.03191053	0
73063.01	0.03185469	0
73067.01	0.03182753	0
73071.01	0.03178914	0
73075.01	0.03176527	0
73079.01	0.0317227	0
73083.01	0.03168904	0
73087.01	0.03165251	0
73091.01	0.0316154	0
73095.01	0.03158185	0
73099.01	0.03154457	0
73103.01	0.03150774	0
73107.01	0.03146822	0
73111.01	0.03142705	0
73115.01	0.03138397	0
73119.01	0.03135728	0
73123.01	0.03132606	0
73127.01	0.0313023	0
73131.01	0.03127271	0
73135.01	0.03123425	0
73139.01	0.03119743	0
73143.01	0.03116532	0
73147.01	0.03113069	0
73151.01	0.03109134	0
73155.01	0.03106462	0
73159.01	0.03103342	0
73163.01	0.03100869	0
73167.01	0.03099031	0
73171.01	0.03096439	0
73175.01	0.03093076	0
73179.01	0.0308983	0
73183.01	0.03087065	0
73187.01	0.03084369	0
73191.01	0.03081161	0
73195.01	0.03077784	0
73199.01	0.0307363	0
73203.01	0.03071301	0
73207.01	0.03067802	0
73211.01	0.03064355	0
73215.01	0.03061049	0
73219.01	0.03058685	0
73223.01	0.03054008	0
73227.01	0.03050863	0
73231.01	0.03047139	0
73235.01	0.03044212	0
73239.01	0.0304077	0
73243.01	0.03038196	0
73247.01	0.03035359	0
73251.01	0.03032594	0
73255.01	0.03029419	0
73259.01	0.03025768	0
73263.01	0.03023253	0
73267.01	0.0301929	0
73271.01	0.03015911	0
73275.01	0.03012895	0
73279.01	0.03008798	0
73283.01	0.03004355	0
73287.01	0.03001197	0
73291.01	0.02997702	0
73295.01	0.02994368	0
73299.01	0.02990858	0
73303.01	0.0298631	0
73307.01	0.0298128	0
73311.01	0.0297812	0
73315.01	0.02977023	0
73319.01	0.02974471	0
73323.01	0.02972399	0
73327.01	0.02970407	0
73331.01	0.02968843	0
73335.01	0.0296606	0
73339.01	0.02964574	0
73343.01	0.02962846	0
73347.01	0.02960068	0
73351.01	0.02956935	0
73355.01	0.02954361	0
73359.01	0.02952126	0
73363.01	0.02947149	0
73367.01	0.02943066	0
73371.01	0.02939604	0
73375.01	0.02935853	0
73379.01	0.02932203	0
73383.01	0.02932081	0
73387.01	0.02928192	0
73391.01	0.02925893	0
73395.01	0.02922599	0
73399.01	0.02920095	0
73403.01	0.02917794	0
73407.01	0.02915476	0
73411.01	0.02913167	0
73415.01	0.02910836	0
73419.01	0.02908097	0
73423.01	0.02905834	0
73427.01	0.02902771	0
73431.01	0.0290035	0
73435.01	0.02897275	0
73439.01	0.02894762	0
73443.01	0.02893033	0
73447.01	0.02890644	0
73451.01	0.02887889	0
73455.01	0.02885259	0
73459.01	0.02882875	0
73463.01	0.02880706	0
73467.01	0.02878368	0
73471.01	0.02875781	0
73475.01	0.02872927	0
73479.01	0.02869942	0
73483.01	0.02869734	0
73487.01	0.02867522	0
73491.01	0.02864825	0
73495.01	0.02862872	0
73499.01	0.0285984	0
73503.01	0.02858728	0
73507.01	0.02856889	0
73511.01	0.02854678	0
73515.01	0.02852166	0
73519.01	0.02849662	0
73523.01	0.02847551	0
73527.01	0.02845203	0
73531.01	0.02843395	0
73535.01	0.02841948	0
73539.01	0.02839572	0
73543.01	0.02837641	0
73547.01	0.02835712	0
73551.01	0.0283244	0
73555.01	0.02829574	0
73559.01	0.02828158	0
73563.01	0.02825805	0
73567.01	0.02823536	0
73571.01	0.02820486	0
73575.01	0.02817707	0
73579.01	0.02815062	0
73583.01	0.02811786	0
73587.01	0.02809352	0
73591.01	0.02807961	0
73595.01	0.0280443	0
73599.01	0.02801922	0
73603.01	0.02800345	0
73607.01	0.0279812	0
73611.01	0.02796479	0
73615.01	0.02794276	0
73619.01	0.02791539	0
73623.01	0.02789459	0
73627.01	0.02785654	0
73631.01	0.02783918	0
73635.01	0.02782226	0
73639.01	0.02780093	0
73643.01	0.02775709	0
73647.01	0.02773919	0
73651.01	0.02772091	0
73655.01	0.02770431	0
73659.01	0.02767382	0
73663.01	0.02764817	0
73667.01	0.0276252	0
73671.01	0.02759742	0
73675.01	0.02756159	0
73679.01	0.02753831	0
73683.01	0.027517	0
73687.01	0.02749801	0
73691.01	0.02747983	0
73695.01	0.02745777	0
73699.01	0.02744003	0
73703.01	0.02742619	0
73707.01	0.02740525	0
73711.01	0.02738726	0
73715.01	0.02736489	0
73719.01	0.02734051	0
73723.01	0.02731436	0
73727.01	0.02729077	0
73731.01	0.02727459	0
73735.01	0.02726219	0
73739.01	0.02724729	0
73743.01	0.02723197	0
73747.01	0.02720642	0
73751.01	0.02718518	0
73755.01	0.02716548	0
73759.01	0.02714648	0
73763.01	0.02712784	0
73767.01	0.02710934	0
73771.01	0.02708671	0
73775.01	0.02706986	0
73779.01	0.02704246	0
73783.01	0.02702385	0
73787.01	0.02701154	0
73791.01	0.02699061	0
73795.01	0.02697889	0
73799.01	0.02695567	0
73803.01	0.02694482	0
73807.01	0.02693392	0
73811.01	0.02691639	0
73815.01	0.02689422	0
73819.01	0.0268696	0
73823.01	0.02683913	0
73827.01	0.02680167	0
73831.01	0.02678116	0
73835.01	0.02675398	0
73839.01	0.02672373	0
73843.01	0.02670414	0
73847.01	0.02667892	0
73851.01	0.02666315	0
73855.01	0.02664099	0
73859.01	0.02661897	0
73863.01	0.02659888	0
73867.01	0.02657801	0
73871.01	0.02656235	0
73875.01	0.02654065	0
73879.01	0.02652004	0
73883.01	0.02649946	0
73887.01	0.02648312	0
73891.01	0.02646517	0
73895.01	0.02645174	0
73899.01	0.02642313	0
73903.01	0.02639978	0
73907.01	0.02638439	0
73911.01	0.02638285	0
73915.01	0.02636492	0
73919.01	0.02635078	0
73923.01	0.0263373	0
73927.01	0.02632315	0
73931.01	0.02630571	0
73935.01	0.02628441	0
73939.01	0.02626941	0
73943.01	0.02625232	0
73947.01	0.02624604	0
73951.01	0.0262291	0
73955.01	0.0262103	0
73959.01	0.02617757	0
73963.01	0.02615097	0
73967.01	0.02613338	0
73971.01	0.02612175	0
73975.01	0.02607426	0
73979.01	0.02603952	0
73983.01	0.02600827	0
73987.01	0.025976	0
73991.01	0.0259786	0
73995.01	0.02596347	0
73999.01	0.02594661	0
74003.01	0.02592824	0
74007.01	0.02592574	0
74011.01	0.02590618	0
74015.01	0.02587794	0
74019.01	0.02586092	0
74023.01	0.02584136	0
74027.01	0.02582277	0
74031.01	0.02580276	0
74035.01	0.02578781	0
74039.01	0.02577695	0
74043.01	0.02575623	0
74047.01	0.02574445	0
74051.01	0.02572963	0
74055.01	0.02571211	0
74059.01	0.02569794	0
74063.01	0.02568104	0
74067.01	0.02566796	0
74071.01	0.02564948	0
74075.01	0.0256339	0
74079.01	0.02561862	0
74083.01	0.02559584	0
74087.01	0.0255729	0
74091.01	0.02554897	0
74095.01	0.02552562	0
74099.01	0.02550289	0
74103.01	0.02548726	0
74107.01	0.02546566	0
74111.01	0.02544073	0
74115.01	0.02542005	0
74119.01	0.02540152	0
74123.01	0.02538419	0
74127.01	0.02536717	0
74131.01	0.02534683	0
74135.01	0.02532984	0
74139.01	0.02531167	0
74143.01	0.02529054	0
74147.01	0.02527387	0
74151.01	0.025254	0
74155.01	0.02523842	0
74159.01	0.02522087	0
74163.01	0.02520751	0
74167.01	0.025195	0
74171.01	0.02519099	0
74175.01	0.0251759	0
74179.01	0.02516311	0
74183.01	0.02514535	0
74187.01	0.02512938	0
74191.01	0.02512042	0
74195.01	0.02511319	0
74199.01	0.02509619	0
74203.01	0.02508313	0
74207.01	0.02505562	0
74211.01	0.02502872	0
74215.01	0.02501981	0
74219.01	0.02500798	0
74223.01	0.02500163	0
74227.01	0.0249834	0
74231.01	0.02497439	0
74235.01	0.02495852	0
74239.01	0.02493463	0
74243.01	0.02492556	0
74247.01	0.02490642	0
74251.01	0.0248913	0
74255.01	0.02488211	0
74259.01	0.02486401	0
74263.01	0.02484505	0
74267.01	0.02483533	0
74271.01	0.02481815	0
74275.01	0.02480613	0
74279.01	0.02478197	0
74283.01	0.02477377	0
74287.01	0.02476497	0
74291.01	0.02474382	0
74295.01	0.02474319	0
74299.01	0.0247333	0
74303.01	0.02471252	0
74307.01	0.02471191	0
74311.01	0.02469496	0
74315.01	0.02468786	0
74319.01	0.02467113	0
74323.01	0.02465165	0
74327.01	0.02463689	0
74331.01	0.02462913	0
74335.01	0.0246048	0
74339.01	0.02459254	0
74343.01	0.02456806	0
74347.01	0.02455962	0
74351.01	0.02454148	0
74355.01	0.0245181	0
74359.01	0.0245023	0
74363.01	0.02449732	0
74367.01	0.02447358	0
74371.01	0.02446714	0
74375.01	0.0244518	0
74379.01	0.02444509	0
74383.01	0.02442121	0
74387.01	0.02439465	0
74391.01	0.02437826	0
74395.01	0.02435408	0
74399.01	0.02433694	0
74403.01	0.0243272	0
74407.01	0.02430825	0
74411.01	0.02430204	0
74415.01	0.02428748	0
74419.01	0.02426013	0
74423.01	0.02425106	0
74427.01	0.02423987	0
74431.01	0.02421939	0
74435.01	0.02420586	0
74439.01	0.02418944	0
74443.01	0.02417269	0
74447.01	0.02414476	0
74451.01	0.02412083	0
74455.01	0.02411463	0
74459.01	0.02411131	0
74463.01	0.02409652	0
74467.01	0.02407338	0
74471.01	0.02404978	0
74475.01	0.02403302	0
74479.01	0.02400477	0
74483.01	0.02399081	0
74487.01	0.02398325	0
74491.01	0.02397715	0
74495.01	0.02398014	0
74499.01	0.02396456	0
74503.01	0.02395053	0
74507.01	0.02393066	0
74511.01	0.02392294	0
74515.01	0.0239089	0
74519.01	0.02389746	0
74523.01	0.02388192	0
74527.01	0.02386063	0
74531.01	0.02384417	0
74535.01	0.02381863	0
74539.01	0.02380545	0
74543.01	0.02378896	0
74547.01	0.02377639	0
74551.01	0.02376102	0
74555.01	0.02373122	0
74559.01	0.02372152	0
74563.01	0.02371541	0
74567.01	0.02370433	0
74571.01	0.02368957	0
74575.01	0.02368332	0
74579.01	0.02367043	0
74583.01	0.02365042	0
74587.01	0.02363475	0
74591.01	0.02361734	0
74595.01	0.02359867	0
74599.01	0.02358587	0
74603.01	0.02357588	0
74607.01	0.0235693	0
74611.01	0.02355547	0
74615.01	0.02354184	0
74619.01	0.02352538	0
74623.01	0.02351172	0
74627.01	0.02349967	0
74631.01	0.02348448	0
74635.01	0.0234612	0
74639.01	0.02344629	0
74643.01	0.0234344	0
74647.01	0.02341832	0
74651.01	0.02340698	0
74655.01	0.0233961	0
74659.01	0.02337702	0
74663.01	0.02336256	0
74667.01	0.02333716	0
74671.01	0.02332104	0
74675.01	0.02329489	0
74679.01	0.02327626	0
74683.01	0.02325675	0
74687.01	0.0232375	0
74691.01	0.023231	0
74695.01	0.02322798	0
74699.01	0.02322593	0
74703.01	0.02321385	0
74707.01	0.02318836	0
74711.01	0.02317867	0
74715.01	0.02316651	0
74719.01	0.02314936	0
74723.01	0.02313871	0
74727.01	0.0231354	0
74731.01	0.02313513	0
74735.01	0.02312516	0
74739.01	0.02310523	0
74743.01	0.02310339	0
74747.01	0.02309503	0
74751.01	0.0230845	0
74755.01	0.02308828	0
74759.01	0.02307907	0
74763.01	0.02306622	0
74767.01	0.02305375	0
74771.01	0.02303582	0
74775.01	0.02302909	0
74779.01	0.02302645	0
74783.01	0.02301474	0
74787.01	0.02299821	0
74791.01	0.02297637	0
74795.01	0.02297099	0
74799.01	0.02295551	0
74803.01	0.02293559	0
74807.01	0.02291336	0
74811.01	0.02291202	0
74815.01	0.02290694	0
74819.01	0.02289405	0
74823.01	0.02288429	0
74827.01	0.02287966	0
74831.01	0.02286458	0
74835.01	0.02284821	0
74839.01	0.02283589	0
74843.01	0.02282639	0
74847.01	0.02281888	0
74851.01	0.02279967	0
74855.01	0.02278671	0
74859.01	0.02277196	0
74863.01	0.02275407	0
74867.01	0.02273459	0
74871.01	0.02272944	0
74875.01	0.02271798	0
74879.01	0.02270527	0
74883.01	0.02269254	0
74887.01	0.02268614	0
74891.01	0.0226831	0
74895.01	0.02267102	0
74899.01	0.02265617	0
74903.01	0.02263297	0
74907.01	0.02262315	0
74911.01	0.02261622	0
74915.01	0.02259914	0
74919.01	0.02258103	0
74923.01	0.02257526	0
74927.01	0.02256794	0
74931.01	0.02255154	0
74935.01	0.02254101	0
74939.01	0.02252365	0
74943.01	0.02250879	0
74947.01	0.0224939	0
74951.01	0.02247881	0
74955.01	0.02247352	0
74959.01	0.02245843	0
74963.01	0.02244804	0
74967.01	0.02243997	0
74971.01	0.02242626	0
74975.01	0.02241496	0
74979.01	0.02240411	0
74983.01	0.022407	0
74987.01	0.02240747	0
74991.01	0.02240305	0
74995.01	0.0223879	0
74999.01	0.02237068	0
75003.01	0.02235752	0
75007.01	0.02233798	0
75011.01	0.02231997	0
75015.01	0.02230557	0
75019.01	0.02229524	0
75023.01	0.02228604	0
75027.01	0.02226589	0
75031.01	0.02225606	0
75035.01	0.02224471	0
75039.01	0.02223458	0
75043.01	0.02223472	0
75047.01	0.02222857	0
75051.01	0.02222874	0
75055.01	0.02222556	0
75059.01	0.02221876	0
75063.01	0.02220479	0
75067.01	0.02219282	0
75071.01	0.02218135	0
75075.01	0.02216835	0
75079.01	0.02216552	0
75083.01	0.0221521	0
75087.01	0.02213825	0
75091.01	0.02212205	0
75095.01	0.02211625	0
75099.01	0.02210362	0
75103.01	0.02207826	0
75107.01	0.02205757	0
75111.01	0.02204967	0
75115.01	0.02203247	0
75119.01	0.0220249	0
75123.01	0.02201424	0
75127.01	0.02199687	0
75131.01	0.02199025	0
75135.01	0.02198532	0
75139.01	0.02197459	0
75143.01	0.0219569	0
75147.01	0.02194146	0
75151.01	0.02193067	0
75155.01	0.02190862	0
75159.01	0.02190123	0
75163.01	0.02188723	0
75167.01	0.02186191	0
75171.01	0.02186028	0
75175.01	0.02184846	0
75179.01	0.02183743	0
75183.01	0.02183316	0
75187.01	0.02183594	0
75191.01	0.02183466	0
75195.01	0.02181659	0
75199.01	0.02180483	0
75203.01	0.02180733	0
75207.01	0.02180525	0
75211.01	0.02179534	0
75215.01	0.02179202	0
75219.01	0.02178484	0
75223.01	0.02177171	0
75227.01	0.02175621	0
75231.01	0.02174025	0
75235.01	0.02174029	0
75239.01	0.02173524	0
75243.01	0.02172374	0
75247.01	0.02172002	0
75251.01	0.02170142	0
75255.01	0.02168998	0
75259.01	0.02167315	0
75263.01	0.02168097	0
75267.01	0.02166612	0
75271.01	0.02165171	0
75275.01	0.02163862	0
75279.01	0.02161786	0
75283.01	0.02158397	0
75287.01	0.02157261	0
75291.01	0.02156559	0
75295.01	0.02155088	0
75299.01	0.02154782	0
75303.01	0.02153879	0
75307.01	0.02153842	0
75311.01	0.02153934	0
75315.01	0.02152379	0
75319.01	0.02151632	0
75323.01	0.02150023	0
75327.01	0.02148912	0
75331.01	0.02146806	0
75335.01	0.02146021	0
75339.01	0.02145643	0
75343.01	0.02144531	0
75347.01	0.02143496	0
75351.01	0.02142368	0
75355.01	0.0214163	0
75359.01	0.02141044	0
75363.01	0.0213892	0
75367.01	0.02137885	0
75371.01	0.02135915	0
75375.01	0.02134553	0
75379.01	0.02133926	0
75383.01	0.02130779	0
75387.01	0.02131561	0
75391.01	0.02132229	0
75395.01	0.02131762	0
75399.01	0.02131838	0
75403.01	0.02130936	0
75407.01	0.02129136	0
75411.01	0.02129065	0
75415.01	0.02128745	0
75419.01	0.02127742	0
75423.01	0.0212683	0
75427.01	0.02126389	0
75431.01	0.02124902	0
75435.01	0.02124043	0
75439.01	0.02124254	0
75443.01	0.02123485	0
75447.01	0.02123616	0
75451.01	0.02123259	0
75455.01	0.02122587	0
75459.01	0.02120624	0
75463.01	0.02118334	0
75467.01	0.02116943	0
75471.01	0.02115384	0
75475.01	0.02113454	0
75479.01	0.02111901	0
75483.01	0.02111131	0
75487.01	0.02109601	0
75491.01	0.02108234	0
75495.01	0.0210767	0
75499.01	0.02106575	0
75503.01	0.02104593	0
75507.01	0.02102719	0
75511.01	0.02102204	0
75515.01	0.02101675	0
75519.01	0.02101199	0
75523.01	0.02100728	0
75527.01	0.02099588	0
75531.01	0.02098293	0
75535.01	0.02097308	0
75539.01	0.02097053	0
75543.01	0.02096906	0
75547.01	0.02095491	0
75551.01	0.02094296	0
75555.01	0.02093165	0
75559.01	0.02091753	0
75563.01	0.02091272	0
75567.01	0.02090395	0
75571.01	0.020901	0
75575.01	0.02087972	0
75579.01	0.02086406	0
75583.01	0.02084527	0
75587.01	0.02083692	0
75591.01	0.02082789	0
75595.01	0.02082656	0
75599.01	0.02081121	0
75603.01	0.02079954	0
75607.01	0.02078665	0
75611.01	0.02078621	0
75615.01	0.02077701	0
75619.01	0.02076602	0
75623.01	0.02075777	0
75627.01	0.02075001	0
75631.01	0.02075889	0
75635.01	0.02074784	0
75639.01	0.02075241	0
75643.01	0.02075006	0
75647.01	0.02075721	0
75651.01	0.02076003	0
75655.01	0.02075178	0
75659.01	0.02074613	0
75663.01	0.02072759	0
75667.01	0.0207035	0
75671.01	0.02070754	0
75675.01	0.02071376	0
75679.01	0.02070303	0
75683.01	0.02069353	0
75687.01	0.02068442	0
75691.01	0.02067558	0
75695.01	0.02066097	0
75699.01	0.02064678	0
75703.01	0.02064687	0
75707.01	0.02065722	0
75711.01	0.02064731	0
75715.01	0.02063887	0
75719.01	0.02062935	0
75723.01	0.02062117	0
75727.01	0.02061041	0
75731.01	0.02059193	0
75735.01	0.02057401	0
75739.01	0.02056327	0
75743.01	0.02055731	0
75747.01	0.0205549	0
75751.01	0.02054082	0
75755.01	0.02053407	0
75759.01	0.02051046	0
75763.01	0.02049962	0
75767.01	0.0204843	0
75771.01	0.02047297	0
75775.01	0.02046255	0
75779.01	0.02045187	0
75783.01	0.0204496	0
75787.01	0.02044313	0
75791.01	0.02043669	0
75795.01	0.02042998	0
75799.01	0.02043138	0
75803.01	0.0204309	0
75807.01	0.02044616	0
75811.01	0.02043902	0
75815.01	0.02040781	0
75819.01	0.02041512	0
75823.01	0.02038747	0
75827.01	0.02038541	0
75831.01	0.02039872	0
75835.01	0.02038836	0
75839.01	0.02037897	0
75843.01	0.02036363	0
75847.01	0.02036116	0
75851.01	0.0203457	0
75855.01	0.02033638	0
75859.01	0.02034775	0
75863.01	0.02033742	0
75867.01	0.02033235	0
75871.01	0.02032646	0
75875.01	0.02031929	0
75879.01	0.02031286	0
75883.01	0.02030534	0
75887.01	0.02029179	0
75891.01	0.02027919	0
75895.01	0.02027461	0
75899.01	0.02024758	0
75903.01	0.02023911	0
75907.01	0.02021204	0
75911.01	0.02018853	0
75915.01	0.02018038	0
75919.01	0.02015758	0
75923.01	0.02016171	0
75927.01	0.02014731	0
75931.01	0.0201343	0
75935.01	0.02011607	0
75939.01	0.02009549	0
75943.01	0.02007432	0
75947.01	0.02006865	0
75951.01	0.02005572	0
75955.01	0.02004523	0
75959.01	0.02004332	0
75963.01	0.02003889	0
75967.01	0.0200327	0
75971.01	0.02002124	0
75975.01	0.02002279	0
75979.01	0.02001526	0
75983.01	0.02000477	0
75987.01	0.0200024	0
75991.01	0.01999907	0
75995.01	0.01998808	0
75999.01	0.01998508	0
76003.01	0.01998029	0
76007.01	0.01996929	0
76011.01	0.01996025	0
76015.01	0.01995579	0
76019.01	0.0199458	0
76023.01	0.01994126	0
76027.01	0.01992523	0
76031.01	0.01991555	0
76035.01	0.01991714	0
76039.01	0.01991672	0
76043.01	0.0199086	0
76047.01	0.01990531	0
76051.01	0.01990503	0
76055.01	0.01989306	0
76059.01	0.01987497	0
76063.01	0.01988474	0
76067.01	0.01988735	0
76071.01	0.01988649	0
76075.01	0.01988047	0
76079.01	0.0198785	0
76083.01	0.01987208	0
76087.01	0.01986532	0
76091.01	0.01987381	0
76095.01	0.01987417	0
76099.01	0.01987854	0
76103.01	0.01987274	0
76107.01	0.01986256	0
76111.01	0.01984804	0
76115.01	0.01984565	0
76119.01	0.0198328	0
76123.01	0.01982366	0
76127.01	0.01980981	0
76131.01	0.01979856	0
76135.01	0.01978995	0
76139.01	0.01978435	0
76143.01	0.01978022	0
76147.01	0.01978086	0
76151.01	0.01976416	0
76155.01	0.01974205	0
76159.01	0.01971853	0
76163.01	0.01970897	0
76167.01	0.01970796	0
76171.01	0.01969834	0
76175.01	0.01969868	0
76179.01	0.01969513	0
76183.01	0.01969449	0
76187.01	0.01969247	0
76191.01	0.01968692	0
76195.01	0.0196842	0
76199.01	0.01967456	0
76203.01	0.019679	0
76207.01	0.01967199	0
76211.01	0.0196653	0
76215.01	0.01966135	0
76219.01	0.01964978	0
76223.01	0.01963398	0
76227.01	0.01965216	0
76231.01	0.01964596	0
76235.01	0.0196461	0
76239.01	0.01962975	0
76243.01	0.01961937	0
76247.01	0.01960538	0
76251.01	0.01960285	0
76255.01	0.01959459	0
76259.01	0.01957982	0
76263.01	0.01957099	0
76267.01	0.01954805	0
76271.01	0.01953219	0
76275.01	0.01952561	0
76279.01	0.01951734	0
76283.01	0.01950871	0
76287.01	0.01949953	0
76291.01	0.01947964	0
76295.01	0.01944536	0
76299.01	0.01944389	0
76303.01	0.01945171	0
76307.01	0.01944886	0
76311.01	0.01943782	0
76315.01	0.01943633	0
76319.01	0.01942703	0
76323.01	0.01941355	0
76327.01	0.01941157	0
76331.01	0.01940153	0
76335.01	0.0193923	0
76339.01	0.01938763	0
76343.01	0.01938798	0
76347.01	0.01937795	0
76351.01	0.01937728	0
76355.01	0.01937872	0
76359.01	0.01937185	0
76363.01	0.01935871	0
76367.01	0.01935189	0
76371.01	0.01934415	0
76375.01	0.0193333	0
76379.01	0.01932523	0
76383.01	0.0193168	0
76387.01	0.01930642	0
76391.01	0.01930072	0
76395.01	0.01928269	0
76399.01	0.01927815	0
76403.01	0.01927187	0
76407.01	0.01926432	0
76411.01	0.0192564	0
76415.01	0.01924089	0
76419.01	0.01923287	0
76423.01	0.01922803	0
76427.01	0.01921519	0
76429.01	0.01921139	0