File: Y261_creep3.txt
Time	Strain	Shear Stress
[s]	[1]	[Pa]
79790.12	0.100371	100
79790.21	0.1110584	100
79790.31	0.1166314	100
79790.41	0.1205597	100
79790.51	0.1236378	100
79790.61	0.1261383	100
79790.72	0.1282911	100
79790.81	0.1301197	100
79790.91	0.1317309	100
79791.01	0.1331973	100
79791.12	0.1345171	100
79791.21	0.1357172	100
79791.31	0.1368126	100
79791.41	0.1378617	100
79791.51	0.1388266	100
79791.61	0.1397489	100
79791.72	0.1406278	100
79791.81	0.1414262	100
79791.91	0.1422363	100
79792.01	0.1429582	100
79792.12	0.1436697	100
79792.21	0.1443464	100
79792.31	0.1449692	100
79792.41	0.1456323	100
79792.51	0.1462121	100
79792.61	0.1468111	100
79792.72	0.1473909	100
79792.81	0.1479104	100
79792.91	0.148476	100
79793.01	0.1489686	100
79793.12	0.1494731	100
79793.21	0.1499735	100
79793.31	0.1504153	100
79793.41	0.1509055	100
79793.51	0.1513354	100
79793.61	0.1517704	100
79793.72	0.1522176	100
79793.81	0.1526053	100
79793.91	0.1530436	100
79794.01	0.1534259	100
79794.12	0.1538152	100
79794.21	0.1542173	100
79794.31	0.1545651	100
79794.41	0.1549563	100
79794.51	0.1553067	100
79794.61	0.1556539	100
79794.72	0.1560197	100
79794.81	0.1563348	100
79794.91	0.1566823	100
79795.01	0.157001	100
79795.12	0.157314	100
79795.21	0.1576394	100
79795.31	0.1579282	100
79795.41	0.1582404	100
79795.51	0.1585348	100
79795.61	0.1588182	100
79795.72	0.1591153	100
79795.81	0.1593846	100
79795.91	0.1596698	100
79796.01	0.1599394	100
79796.12	0.1602032	100
79796.21	0.160476	100
79796.31	0.1607337	100
79796.41	0.1609941	100
79796.51	0.1612474	100
79796.61	0.1614933	100
79796.72	0.1617473	100
79796.81	0.1619903	100
79796.91	0.1622301	100
79797.01	0.162468	100
79797.12	0.1627016	100
79797.21	0.1629345	100
79797.31	0.1631642	100
79797.41	0.1633877	100
79797.51	0.1636084	100
79797.61	0.1638321	100
79797.72	0.1640433	100
79797.81	0.164262	100
79797.91	0.1644686	100
79798.01	0.1646757	100
79798.12	0.1648879	100
79798.21	0.1650838	100
79798.31	0.1652928	100
79798.41	0.1654898	100
79798.51	0.1656805	100
79798.61	0.1658849	100
79798.72	0.1660649	100
79798.81	0.1662626	100
79798.91	0.1664477	100
79799.01	0.1666309	100
79799.12	0.1668299	100
79799.21	0.1669988	100
79799.31	0.1671895	100
79799.41	0.1673697	100
79799.51	0.1675377	100
79799.61	0.1677336	100
79799.72	0.1678937	100
79799.81	0.1680785	100
79799.91	0.1682514	100
79800.01	0.1684127	100
79800.12	0.1686021	100
79800.21	0.1687492	100
79800.31	0.1689284	100
79800.41	0.1690955	100
79800.51	0.1692451	100
79800.61	0.1694318	100
79800.72	0.1695714	100
79800.81	0.169744	100
79800.91	0.1699054	100
79801.01	0.1700464	100
79801.12	0.1702265	100
79801.21	0.1703571	100
79801.31	0.1705233	100
79801.41	0.1706775	100
79801.51	0.1708128	100
79801.61	0.1709908	100
79801.72	0.1711155	100
79801.81	0.171277	100
79801.91	0.1714279	100
79802.01	0.1715527	100
79802.12	0.1717244	100
79802.21	0.1718448	100
79802.31	0.1719951	100
79802.41	0.172144	100
79802.51	0.1722632	100
79802.61	0.17243	100
79802.72	0.1725457	100
79802.81	0.1726887	100
79802.91	0.1728356	100
79803.01	0.1729451	100
79803.12	0.1731097	100
79803.21	0.1732198	100
79803.31	0.1733578	100
79803.41	0.1735035	100
79803.51	0.173606	100
79803.61	0.1737688	100
79803.72	0.1738725	100
79803.81	0.1740073	100
79803.91	0.1741485	100
79804.01	0.1742461	100
79804.12	0.1744055	100
79804.21	0.1745071	100
79804.31	0.1746381	100
79804.41	0.1747786	100
79804.51	0.1748754	100
79804.61	0.1750314	100
79804.72	0.1751294	100
79804.81	0.1752575	100
79804.91	0.1753901	100
79805.01	0.1754816	100
79805.12	0.175636	100
79805.21	0.1757305	100
79805.31	0.1758558	100
79805.41	0.1759912	100
79805.51	0.1760781	100
79805.61	0.1762294	100
79805.72	0.176326	100
79805.81	0.1764418	100
79805.91	0.1765771	100
79806.01	0.1766591	100
79806.12	0.1768059	100
79806.21	0.1768994	100
79806.31	0.1770126	100
79806.41	0.1771482	100
79806.51	0.1772276	100
79806.61	0.1773719	100
79806.72	0.1774694	100
79806.81	0.1775705	100
79806.91	0.1777085	100
79807.01	0.177783	100
79807.12	0.1779191	100
79807.21	0.1780169	100
79807.31	0.1781121	100
79807.41	0.1782504	100
79807.51	0.1783225	100
79807.61	0.1784532	100
79807.72	0.1785523	100
79807.81	0.178641	100
79807.91	0.1787743	100
79808.01	0.1788447	100
79808.12	0.1789679	100
79808.21	0.1790704	100
79808.31	0.1791509	100
79808.41	0.1792852	100
79808.51	0.1793539	100
79808.61	0.1794718	100
79808.72	0.1795733	100
79808.81	0.1796512	100
79808.91	0.1797849	100
79809.01	0.1798535	100
79809.12	0.1799675	100
79809.21	0.1800671	100
79809.31	0.1801426	100
79809.41	0.1802728	100
79809.51	0.1803393	100
79809.61	0.1804505	100
79809.72	0.180548	100
79809.81	0.1806226	100
79809.91	0.1807488	100
79810.01	0.1808131	100
79810.12	0.1809242	100
79810.21	0.18102	100
79810.31	0.1810938	100
79810.41	0.1812164	100
79810.51	0.181278	100
79810.61	0.1813898	100
79810.72	0.1814796	100
79810.81	0.1815557	100
79810.91	0.1816755	100
79811.01	0.181737	100
79811.12	0.1818462	100
79811.21	0.1819339	100
79811.31	0.1820079	100
79811.41	0.1821248	100
79811.51	0.1821842	100
79811.61	0.1822975	100
79811.72	0.1823783	100
79811.81	0.1824574	100
79811.91	0.1825693	100
79812.01	0.182627	100
79812.12	0.1827371	100
79812.21	0.1828156	100
79812.31	0.1828939	100
79812.41	0.1830001	100
79812.51	0.1830603	100
79812.61	0.1831676	100
79812.72	0.1832457	100
79812.81	0.183321	100
79812.91	0.1834298	100
79813.01	0.1834849	100
79813.12	0.1835931	100
79813.21	0.1836655	100
79813.31	0.183744	100
79813.41	0.1838458	100
79813.51	0.1839031	100
79813.61	0.1840081	100
79813.72	0.1840809	100
79813.81	0.1841588	100
79813.91	0.1842574	100
79814.01	0.1843131	100
79814.12	0.1844169	100
79814.21	0.1844867	100
79814.31	0.1845611	100
79814.41	0.1846608	100
79814.51	0.1847144	100
79814.61	0.1848135	100
79814.72	0.1848867	100
79814.81	0.1849546	100
79814.91	0.1850528	100
79815.01	0.1851059	100
79815.12	0.185203	100
79815.21	0.1852757	100
79815.31	0.1853431	100
79815.41	0.1854414	100
79815.51	0.1854943	100
79815.61	0.1855853	100
79815.72	0.1856563	100
79815.81	0.1857191	100
79815.91	0.1858139	100
79816.01	0.1858705	100
79816.12	0.185956	100
79816.21	0.1860351	100
79816.31	0.1860959	100
79816.41	0.1861904	100
79816.51	0.1862492	100
79816.61	0.1863318	100
79816.72	0.1864116	100
79816.81	0.1864692	100
79816.91	0.1865626	100
79817.01	0.1866223	100
79817.12	0.1867011	100
79817.21	0.1867786	100
79817.31	0.1868338	100
79817.41	0.1869239	100
79817.51	0.1869834	100
79817.61	0.1870582	100
79817.72	0.1871358	100
79817.81	0.1871914	100
79817.91	0.18728	100
79818.01	0.1873367	100
79818.12	0.1874122	100
79818.21	0.1874862	100
79818.31	0.1875416	100
79818.41	0.1876287	100
79818.51	0.1876857	100
79818.61	0.1877571	100
79818.72	0.1878329	100
79818.81	0.1878872	100
79818.91	0.1879716	100
79819.01	0.1880289	100
79819.12	0.188098	100
79819.21	0.1881712	100
79819.31	0.1882248	100
79819.41	0.1883048	100
79819.51	0.1883627	100
79819.61	0.1884313	100
79819.72	0.1885022	100
79819.81	0.1885563	100
79819.91	0.1886345	100
79820.01	0.188691	100
79820.12	0.1887574	100
79820.21	0.1888281	100
79820.31	0.1888829	100
79820.41	0.1889609	100
79820.51	0.1890193	100
79820.61	0.1890848	100
79820.72	0.1891549	100
79820.81	0.1892095	100
79820.91	0.189283	100
79821.01	0.189342	100
79821.12	0.1894069	100
79821.21	0.1894745	100
79821.31	0.189529	100
79821.41	0.1896027	100
79821.51	0.1896587	100
79821.61	0.1897226	100
79821.72	0.1897888	100
79821.81	0.1898437	100
79821.91	0.1899139	100
79822.01	0.1899715	100
79822.12	0.1900359	100
79822.21	0.1901032	100
79822.31	0.190158	100
79822.41	0.1902276	100
79822.51	0.1902875	100
79822.61	0.1903485	100
79822.72	0.1904145	100
79822.81	0.190472	100
79822.91	0.1905406	100
79823.01	0.1905989	100
79823.12	0.1906599	100
79823.21	0.1907241	100
79823.31	0.1907797	100
79823.41	0.1908452	100
79823.51	0.1909017	100
79823.61	0.1909609	100
79823.72	0.1910242	100
79823.81	0.1910794	100
79823.91	0.1911437	100
79824.01	0.1912017	100
79824.12	0.1912611	100
79824.21	0.1913212	100
79824.31	0.1913768	100
79824.41	0.1914404	100
79824.51	0.191498	100
79824.61	0.1915561	100
79824.72	0.1916162	100
79824.81	0.1916733	100
79824.91	0.1917356	100
79825.01	0.1917927	100
79825.12	0.1918506	100
79825.21	0.1919089	100
79825.31	0.1919662	100
79825.41	0.1920262	100
79825.51	0.1920829	100
79825.61	0.1921408	100
79825.72	0.1921972	100
79825.81	0.1922546	100
79825.91	0.1923124	100
79826.01	0.192368	100
79826.12	0.1924261	100
79826.21	0.1924816	100
79826.31	0.1925392	100
79826.41	0.1925973	100
79826.51	0.1926546	100
79826.61	0.192711	100
79826.72	0.192763	100
79826.81	0.1928216	100
79826.91	0.1928779	100
79827.01	0.1929319	100
79827.12	0.1929882	100
79827.21	0.1930407	100
79827.31	0.1930994	100
79827.41	0.1931515	100
79827.51	0.1932059	100
79827.61	0.1932606	100
79827.72	0.1933134	100
79827.81	0.193371	100
79827.91	0.1934217	100
79828.01	0.1934774	100
79828.12	0.1935328	100
79828.21	0.1935826	100
79828.31	0.1936415	100
79828.41	0.19369	100
79828.51	0.1937452	100
79828.61	0.1938008	100
79828.72	0.1938477	100
79828.81	0.1939089	100
79828.91	0.1939575	100
79829.01	0.1940113	100
79829.12	0.1940666	100
79829.21	0.1941119	100
79829.31	0.1941718	100
79829.41	0.1942178	100
79829.51	0.1942707	100
79829.61	0.194324	100
79829.72	0.1943697	100
79829.81	0.1944309	100
79829.91	0.1944763	100
79830.01	0.1945268	100
79830.12	0.1945826	100
79830.21	0.1946239	100
79830.31	0.1946826	100
79830.41	0.1947297	100
79830.51	0.1947776	100
79830.61	0.1948339	100
79830.72	0.1948768	100
79830.81	0.1949356	100
79830.91	0.1949862	100
79831.01	0.1950315	100
79831.12	0.1950886	100
79831.21	0.1951285	100
79831.31	0.1951889	100
79831.41	0.1952358	100
79831.51	0.1952796	100
79831.61	0.1953374	100
79831.72	0.1953776	100
79831.81	0.1954349	100
79831.91	0.1954818	100
79832.01	0.1955243	100
79832.12	0.1955837	100
79832.21	0.1956211	100
79832.31	0.1956785	100
79832.41	0.1957264	100
79832.51	0.1957679	100
79832.61	0.1958271	100
79832.72	0.1958642	100
79832.81	0.1959165	100
79832.91	0.1959664	100
79833.01	0.1960047	100
79833.12	0.1960669	100
79833.21	0.196105	100
79833.31	0.1961578	100
79833.41	0.1962102	100
79833.51	0.1962463	100
79833.61	0.1963092	100
79833.72	0.1963456	100
79833.81	0.1963983	100
79833.91	0.1964519	100
79834.01	0.1964844	100
79834.12	0.1965462	100
79834.21	0.1965844	100
79834.31	0.1966332	100
79834.41	0.196686	100
79834.51	0.1967195	100
79834.61	0.1967831	100
79834.72	0.1968194	100
79834.81	0.1968681	100
79834.91	0.1969218	100
79835.01	0.1969531	100
79835.12	0.1970157	100
79835.21	0.1970515	100
79835.31	0.1970966	100
79835.41	0.1971523	100
79835.51	0.1971818	100
79835.61	0.1972457	100
79835.72	0.1972816	100
79835.81	0.1973288	100
79835.91	0.1973833	100
79836.01	0.1974121	100
79836.12	0.1974765	100
79836.21	0.197512	100
79836.31	0.1975561	100
79836.41	0.1976147	100
79836.51	0.1976404	100
79836.61	0.1977058	100
79836.72	0.197741	100
79836.81	0.1977864	100
79836.91	0.1978398	100
79837.01	0.1978674	100
79837.12	0.197933	100
79837.21	0.1979664	100
79837.31	0.1980109	100
79837.41	0.1980687	100
79837.51	0.1980915	100
79837.61	0.198157	100
79837.72	0.198192	100
79837.81	0.1982342	100
79837.91	0.1982914	100
79838.01	0.1983169	100
79838.12	0.1983813	100
79838.21	0.1984145	100
79838.31	0.1984563	100
79838.41	0.1985157	100
79838.51	0.1985385	100
79838.61	0.1986018	100
79838.72	0.1986373	100
79838.81	0.1986775	100
79838.91	0.1987372	100
79839.01	0.1987593	100
79839.12	0.1988234	100
79839.21	0.1988585	100
79839.31	0.1988989	100
79839.41	0.1989575	100
79839.51	0.1989791	100
79839.61	0.1990434	100
79839.72	0.1990779	100
79839.81	0.1991157	100
79839.91	0.1991767	100
79840.01	0.1991965	100
79840.12	0.1992592	100
79840.21	0.1992947	100
79840.31	0.1993288	100
79840.41	0.199391	100
79840.51	0.1994103	100
79840.61	0.1994706	100
79840.72	0.1995077	100
79840.81	0.1995406	100
79840.91	0.199603	100
79841.01	0.1996207	100
79841.12	0.1996803	100
79841.21	0.1997204	100
79841.31	0.199749	100
79841.41	0.199813	100
79841.51	0.1998316	100
79841.61	0.1998862	100
79841.72	0.1999298	100
79841.81	0.1999551	100
79841.91	0.2000219	100
79842.01	0.2000395	100
79842.12	0.2000962	100
79842.21	0.2001353	100
79842.31	0.2001615	100
79842.41	0.2002284	100
79842.51	0.2002453	100
79842.61	0.2003	100
79842.72	0.2003442	100
79842.81	0.2003684	100
79842.91	0.2004352	100
79843.01	0.2004549	100
79843.12	0.2005044	100
79843.21	0.2005537	100
79843.31	0.20057	100
79843.41	0.2006378	100
79843.51	0.2006607	100
79843.61	0.2007051	100
79843.72	0.2007587	100
79843.81	0.2007744	100
79843.91	0.2008404	100
79844.01	0.200865	100
79844.12	0.2009041	100
79844.21	0.2009611	100
79844.31	0.200974	100
79844.41	0.2010423	100
79844.51	0.2010684	100
79844.61	0.2011041	100
79844.72	0.2011631	100
79844.81	0.2011745	100
79844.91	0.2012407	100
79845.01	0.2012664	100
79845.12	0.2013014	100
79845.21	0.2013625	100
79845.31	0.2013747	100
79845.41	0.201435	100
79845.51	0.2014677	100
79845.61	0.2014977	100
79845.72	0.2015604	100
79845.81	0.2015714	100
79845.91	0.2016306	100
79846.01	0.2016657	100
79846.12	0.2016908	100
79846.21	0.2017557	100
79846.31	0.2017669	100
79846.41	0.2018251	100
79846.51	0.2018648	100
79846.61	0.2018826	100
79846.72	0.2019507	100
79846.81	0.2019629	100
79846.91	0.2020136	100
79847.01	0.202058	100
79847.12	0.2020753	100
79847.21	0.2021439	100
79847.31	0.2021596	100
79847.41	0.2022074	100
79847.51	0.2022577	100
79847.61	0.2022667	100
79847.72	0.2023353	100
79847.81	0.2023527	100
79847.91	0.2023924	100
79848.01	0.2024471	100
79848.12	0.2024582	100
79848.21	0.2025218	100
79848.31	0.2025445	100
79848.41	0.2025783	100
79848.51	0.2026375	100
79848.61	0.2026449	100
79848.72	0.2027087	100
79848.81	0.2027365	100
79848.91	0.2027667	100
79849.01	0.2028282	100
79849.12	0.202834	100
79849.21	0.2028975	100
79849.31	0.2029275	100
79849.41	0.2029517	100
79849.51	0.2030159	100
79849.61	0.2030214	100
79849.72	0.203079	100
79849.81	0.2031152	100
79849.91	0.2031326	100
79850.01	0.2032007	100
79850.12	0.2032094	100
79850.21	0.2032639	100
79850.31	0.2033029	100
79850.41	0.203319	100
79850.51	0.2033859	100
79850.61	0.2033945	100
79850.72	0.203446	100
79850.81	0.203488	100
79850.91	0.2034998	100
79851.01	0.2035684	100
79851.12	0.2035808	100
79851.21	0.2036254	100
79851.31	0.2036752	100
79851.41	0.2036806	100
79851.51	0.2037485	100
79851.61	0.2037655	100
79851.72	0.2038015	100
79851.81	0.2038584	100
79851.91	0.203863	100
79852.01	0.2039293	100
79852.12	0.2039505	100
79852.21	0.2039782	100
79852.31	0.2040381	100
79852.41	0.2040409	100
79852.51	0.2041029	100
79852.61	0.2041347	100
79852.72	0.2041517	100
79852.81	0.2042198	100
79852.91	0.2042257	100
79853.01	0.2042771	100
79853.12	0.2043203	100
79853.21	0.2043313	100
79853.31	0.2043989	100
79853.41	0.2044085	100
79853.51	0.2044538	100
79853.61	0.2045019	100
79853.72	0.2045073	100
79853.81	0.2045749	100
79853.91	0.2045893	100
79854.01	0.2046257	100
79854.12	0.2046807	100
79854.21	0.204685	100
79854.31	0.2047507	100
79854.41	0.2047725	100
79854.51	0.2048013	100
79854.61	0.2048613	100
79854.72	0.2048637	100
79854.81	0.2049245	100
79854.91	0.2049514	100
79855.01	0.2049708	100
79855.12	0.2050358	100
79855.21	0.2050382	100
79855.31	0.2050921	100
79855.41	0.205129	100
79855.51	0.2051414	100
79855.61	0.2052081	100
79855.72	0.2052144	100
79855.81	0.2052587	100
79855.91	0.2053066	100
79856.01	0.2053091	100
79856.12	0.2053758	100
79856.21	0.2053936	100
79856.31	0.2054234	100
79856.41	0.2054827	100
79856.51	0.2054837	100
79856.61	0.2055436	100
79856.72	0.2055723	100
79856.81	0.2055904	100
79856.91	0.2056556	100
79857.01	0.2056574	100
79857.12	0.2057111	100
79857.21	0.2057482	100
79857.31	0.205757	100
79857.41	0.2058233	100
79857.51	0.2058333	100
79857.61	0.2058743	100
79857.72	0.2059268	100
79857.81	0.2059268	100
79857.91	0.2059958	100
79858.01	0.2060109	100
79858.12	0.2060392	100
79858.21	0.2060979	100
79858.31	0.2060978	100
79858.41	0.2061555	100
79858.51	0.206186	100
79858.61	0.2061997	100
79858.72	0.2062671	100
79858.81	0.206269	100
79858.91	0.206319	100
79859.01	0.2063591	100
79859.12	0.2063636	100
79859.21	0.2064297	100
79859.31	0.2064402	100
79859.41	0.2064692	100
79859.51	0.2065279	100
79859.61	0.2065267	100
79859.72	0.2065853	100
79859.81	0.2066125	100
79859.91	0.2066271	100
79860.01	0.2066931	100
79860.12	0.2066943	100
79860.21	0.2067398	100
79860.31	0.206781	100
79860.41	0.2067858	100
79860.51	0.2068533	100
79860.61	0.2068607	100
79860.72	0.2068994	100
79860.81	0.2069489	100
79860.91	0.2069489	100
79861.01	0.2070147	100
79861.12	0.2070303	100
79861.21	0.2070575	100
79861.31	0.2071146	100
79861.41	0.2071126	100
79861.51	0.2071752	100
79861.61	0.2071983	100
79861.72	0.2072169	100
79861.81	0.2072796	100
79861.91	0.2072771	100
79862.01	0.2073333	100
79862.12	0.2073636	100
79862.21	0.207375	100
79862.31	0.2074401	100
79862.41	0.2074417	100
79862.51	0.2074917	100
79862.61	0.2075261	100
79862.72	0.2075323	100
79862.81	0.2075992	100
79862.91	0.2076007	100
79863.01	0.2076468	100
79863.12	0.2076872	100
79863.21	0.2076921	100
79863.31	0.2077563	100
79863.41	0.2077648	100
79863.51	0.2078004	100
79863.61	0.2078508	100
79863.72	0.2078501	100
79863.81	0.2079126	100
79863.91	0.2079284	100
79864.01	0.207956	100
79864.12	0.2080119	100
79864.21	0.2080096	100
79864.31	0.2080695	100
79864.41	0.2080913	100
79864.51	0.2081117	100
79864.61	0.2081715	100
79864.72	0.2081691	100
79864.81	0.2082244	100
79864.91	0.2082541	100
79865.01	0.2082634	100
79865.12	0.2083298	100
79865.21	0.2083292	100
79865.31	0.2083747	100
79865.41	0.2084135	100
79865.51	0.2084159	100
79865.61	0.2084816	100
79865.72	0.2084873	100
79865.81	0.2085272	100
79865.91	0.2085737	100
79866.01	0.2085735	100
79866.12	0.2086381	100
79866.21	0.208648	100
79866.31	0.2086771	100
79866.41	0.2087301	100
79866.51	0.2087272	100
79866.61	0.2087883	100
79866.72	0.2088034	100
79866.81	0.208829	100
79866.91	0.2088855	100
79867.01	0.2088812	100
79867.12	0.2089404	100
79867.21	0.2089555	100
79867.31	0.2089797	100
79867.41	0.2090354	100
79867.51	0.209033	100
79867.61	0.2090906	100
79867.72	0.2091093	100
79867.81	0.2091298	100
79867.91	0.2091857	100
79868.01	0.2091805	100
79868.12	0.2092386	100
79868.21	0.2092589	100
79868.31	0.2092779	100
79868.41	0.2093361	100
79868.51	0.2093337	100
79868.61	0.2093892	100
79868.72	0.2094108	100
79868.81	0.2094278	100
79868.91	0.2094868	100
79869.01	0.2094831	100
79869.12	0.2095375	100
79869.21	0.2095597	100
79869.31	0.2095784	100
79869.41	0.2096359	100
79869.51	0.209634	100
79869.61	0.2096945	100
79869.72	0.2097118	100
79869.81	0.20973	100
79869.91	0.2097858	100
79870.01	0.2097807	100
79870.12	0.2098341	100
79870.21	0.2098607	100
79870.31	0.2098723	100
79870.41	0.2099329	100
79870.51	0.2099296	100
79870.61	0.209977	100
79870.72	0.2100077	100
79870.81	0.210017	100
79870.91	0.2100783	100
79871.01	0.2100772	100
79871.12	0.210121	100
79871.21	0.2101572	100
79871.31	0.210162	100
79871.41	0.2102226	100
79871.51	0.2102261	100
79871.61	0.2102656	100
79871.72	0.2103059	100
79871.81	0.2103087	100
79871.91	0.2103695	100
79872.01	0.2103723	100
79872.12	0.2104114	100
79872.21	0.210449	100
79872.31	0.2104523	100
79872.41	0.2105137	100
79872.51	0.2105159	100
79872.61	0.2105562	100
79872.72	0.2105951	100
79872.81	0.2105967	100
79872.91	0.210658	100
79873.01	0.2106643	100
79873.12	0.2106987	100
79873.21	0.2107435	100
79873.31	0.2107422	100
79873.41	0.2108042	100
79873.51	0.2108132	100
79873.61	0.2108436	100
79873.72	0.2108917	100
79873.81	0.210889	100
79873.91	0.2109481	100
79874.01	0.2109592	100
79874.12	0.2109844	100
79874.21	0.2110364	100
79874.31	0.211034	100
79874.41	0.2110897	100
79874.51	0.2111098	100
79874.61	0.2111286	100
79874.72	0.2111844	100
79874.81	0.2111799	100
79874.91	0.2112312	100
79875.01	0.2112526	100
79875.12	0.211267	100
79875.21	0.2113244	100
79875.31	0.2113227	100
79875.41	0.2113706	100
79875.51	0.2114019	100
79875.61	0.2114101	100
79875.72	0.2114708	100
79875.81	0.2114707	100
79875.91	0.2115121	100
79876.01	0.211547	100
79876.12	0.2115513	100
79876.21	0.211612	100
79876.31	0.2116147	100
79876.41	0.2116519	100
79876.51	0.211691	100
79876.61	0.2116927	100
79876.72	0.2117528	100
79876.81	0.2117557	100
79876.91	0.2117929	100
79877.01	0.2118361	100
79877.12	0.2118381	100
79877.21	0.2118966	100
79877.31	0.2119055	100
79877.41	0.2119359	100
79877.51	0.2119808	100
79877.61	0.2119804	100
79877.72	0.2120388	100
79877.81	0.212046	100
79877.91	0.2120768	100
79878.01	0.2121201	100
79878.12	0.2121219	100
79878.21	0.2121761	100
79878.31	0.2121825	100
79878.41	0.2122128	100
79878.51	0.2122568	100
79878.61	0.2122573	100
79878.72	0.2123135	100
79878.81	0.2123239	100
79878.91	0.2123514	100
79879.01	0.212398	100
79879.12	0.2123981	100
79879.21	0.2124509	100
79879.31	0.2124658	100
79879.41	0.2124884	100
79879.51	0.2125389	100
79879.61	0.2125389	100
79879.72	0.2125915	100
79879.81	0.2126091	100
79879.91	0.2126267	100
79880.01	0.2126788	100
79880.12	0.2126779	100
79880.21	0.2127258	100
79880.31	0.2127533	100
79880.41	0.2127638	100
79880.51	0.2128206	100
79880.61	0.2128227	100
79880.72	0.2128594	100
79880.81	0.2128935	100
79880.91	0.2128969	100
79881.01	0.2129505	100
79881.12	0.2129564	100
79881.21	0.2129858	100
79881.31	0.213029	100
79881.41	0.2130313	100
79881.51	0.2130835	100
79881.61	0.213096	100
79881.72	0.2131174	100
79881.81	0.2131653	100
79881.91	0.2131662	100
79882.01	0.2132128	100
79882.12	0.2132334	100
79882.21	0.2132483	100
79882.31	0.2132978	100
79882.41	0.2132993	100
79882.51	0.2133397	100
79882.61	0.2133677	100
79882.72	0.2133754	100
79882.81	0.213429	100
79882.91	0.2134347	100
79883.01	0.2134713	100
79883.12	0.2135061	100
79883.21	0.2135091	100
79883.31	0.2135622	100
79883.41	0.2135697	100
79883.51	0.2135967	100
79883.61	0.2136385	100
79883.72	0.2136377	100
79883.81	0.2136915	100
79883.91	0.2137002	100
79884.01	0.2137296	100
79884.12	0.213774	100
79884.21	0.2137731	100
79884.31	0.2138253	100
79884.41	0.2138361	100
79884.51	0.2138655	100
79884.61	0.2139071	100
79884.72	0.2139104	100
79884.81	0.2139611	100
79884.91	0.2139747	100
79885.01	0.2139999	100
79885.12	0.2140412	100
79885.21	0.2140404	100
79885.31	0.2140875	100
79885.41	0.2141069	100
79885.51	0.2141252	100
79885.61	0.2141745	100
79885.72	0.2141775	100
79885.81	0.2142229	100
79885.91	0.2142402	100
79886.01	0.2142552	100
79886.12	0.2143055	100
79886.21	0.2143084	100
79886.31	0.2143495	100
79886.41	0.2143782	100
79886.51	0.2143875	100
79886.61	0.2144377	100
79886.72	0.2144418	100
79886.81	0.2144752	100
79886.91	0.2145114	100
79887.01	0.2145176	100
79887.12	0.2145644	100
79887.21	0.2145757	100
79887.31	0.2146005	100
79887.41	0.2146451	100
79887.51	0.2146454	100
79887.61	0.2146915	100
79887.72	0.2147075	100
79887.81	0.2147266	100
79887.91	0.2147721	100
79888.01	0.2147737	100
79888.12	0.2148151	100
79888.21	0.2148395	100
79888.31	0.2148491	100
79888.41	0.2148954	100
79888.51	0.2148991	100
79888.61	0.214934	100
79888.72	0.2149666	100
79888.81	0.2149718	100
79888.91	0.2150182	100
79889.01	0.215032	100
79889.12	0.2150575	100
79889.21	0.2150986	100
79889.31	0.2150996	100
79889.41	0.2151444	100
79889.51	0.2151601	100
79889.61	0.2151794	100
79889.72	0.2152231	100
79889.81	0.2152263	100
79889.91	0.2152673	100
79890.01	0.2152853	100
79890.12	0.2153018	100
79890.21	0.2153473	100
79890.31	0.2153474	100
79890.41	0.2153845	100
79890.51	0.2154089	100
79890.61	0.2154222	100
79890.72	0.2154685	100
79890.81	0.2154758	100
79890.91	0.2155057	100
79891.01	0.2155376	100
79891.12	0.2155443	100
79891.21	0.2155915	100
79891.31	0.2155988	100
79891.41	0.2156294	100
79891.51	0.2156651	100
79891.61	0.2156704	100
79891.72	0.2157144	100
79891.81	0.2157287	100
79891.91	0.2157475	100
79892.01	0.2157871	100
79892.12	0.2157922	100
79892.21	0.2158331	100
79892.31	0.2158529	100
79892.41	0.2158667	100
79892.51	0.2159101	100
79892.61	0.2159168	100
79892.72	0.2159504	100
79892.81	0.215976	100
79892.91	0.2159846	100
79893.01	0.2160294	100
79893.11	0.216038	100
79893.21	0.2160691	100
79893.3	0.2161014	100
79893.41	0.2161093	100
79893.51	0.2161521	100
79893.61	0.2161635	100
79893.71	0.2161856	100
79893.81	0.2162244	100
79893.91	0.2162288	100
79894.01	0.2162715	100
79894.11	0.2162882	100
79894.21	0.2163089	100
79894.3	0.2163488	100
79894.41	0.2163516	100
79894.51	0.21639	100
79894.61	0.2164092	100
79894.71	0.2164262	100
79894.81	0.2164675	100
79894.91	0.2164728	100
79895.01	0.2165111	100
79895.11	0.2165359	100
79895.21	0.2165487	100
79895.3	0.2165889	100
79895.41	0.2165948	100
79895.51	0.216626	100
79895.61	0.2166542	100
79895.71	0.216665	100
79895.81	0.2167061	100
79895.91	0.2167199	100
79896.01	0.2167457	100
79896.11	0.2167788	100
79896.21	0.2167857	100
79896.3	0.2168239	100
79896.41	0.2168383	100
79896.51	0.2168601	100
79896.61	0.2168989	100
79896.71	0.2169057	100
79896.81	0.2169424	100
79896.91	0.216958	100
79897.01	0.2169792	100
79897.11	0.2170176	100
79897.21	0.217024	100
79897.3	0.217058	100
79897.41	0.2170817	100
79897.51	0.2170976	100
79897.61	0.2171375	100
79897.71	0.217143	100
79897.81	0.2171732	100
79897.91	0.2171989	100
79898.01	0.2172111	100
79898.11	0.2172499	100
79898.21	0.2172579	100
79898.3	0.2172863	100
79898.41	0.2173142	100
79898.51	0.2173258	100
79898.61	0.2173636	100
79898.71	0.2173755	100
79898.81	0.2173977	100
79898.91	0.2174299	100
79899.01	0.2174383	100
79899.11	0.217476	100
79899.21	0.2174892	100
79899.3	0.2175123	100
79899.41	0.2175461	100
79899.51	0.2175544	100
79899.61	0.2175871	100
79899.71	0.217606	100
79899.81	0.2176233	100
79899.91	0.2176618	100
79900.01	0.2176697	100
79900.11	0.2177035	100
79900.21	0.2177214	100
79900.3	0.2177384	100
79900.41	0.2177752	100
79900.51	0.2177831	100
79900.61	0.2178135	100
79900.71	0.2178363	100
79900.81	0.2178508	100
79900.91	0.2178865	100
79901.01	0.2178958	100
79901.11	0.2179243	100
79901.21	0.2179492	100
79901.3	0.2179612	100
79901.41	0.217997	100
79901.51	0.2180086	100
79901.61	0.2180326	100
79901.71	0.2180614	100
79901.81	0.2180732	100
79901.91	0.2181084	100
79902.01	0.2181224	100
79902.11	0.2181446	100
79902.21	0.218175	100
79902.3	0.2181854	100
79902.41	0.2182175	100
79902.51	0.2182346	100
79902.61	0.2182526	100
79902.71	0.218286	100
79902.81	0.2182951	100
79902.91	0.2183269	100
79903.01	0.2183456	100
79903.11	0.2183647	100
79903.21	0.2183974	100
79903.3	0.2184088	100
79903.41	0.2184406	100
79903.51	0.2184609	100
79903.61	0.2184781	100
79903.71	0.2185116	100
79903.81	0.2185235	100
79903.91	0.2185531	100
79904.01	0.2185723	100
79904.11	0.2185908	100
79904.21	0.2186227	100
79904.3	0.2186336	100
79904.41	0.2186622	100
79904.51	0.2186839	100
79904.61	0.2187004	100
79904.71	0.2187337	100
79904.81	0.2187495	100
79904.91	0.2187759	100
79905.01	0.2188004	100
79905.11	0.2188152	100
79905.21	0.2188466	100
79905.3	0.2188596	100
79905.41	0.2188838	100
79905.51	0.2189103	100
79905.61	0.2189245	100
79905.71	0.2189548	100
79905.81	0.2189718	100
79905.91	0.2189917	100
79906.01	0.2190207	100
79906.11	0.2190319	100
79906.21	0.2190615	100
79906.3	0.2190799	100
79906.41	0.219099	100
79906.51	0.2191302	100
79906.61	0.2191421	100
79906.71	0.2191691	100
79906.81	0.2191886	100
79906.91	0.2192062	100
79907.01	0.2192363	100
79907.11	0.2192469	100
79907.21	0.2192748	100
79907.3	0.219295	100
79907.41	0.2193123	100
79907.51	0.219343	100
79907.61	0.219354	100
79907.71	0.219378	100
79907.81	0.2194005	100
79907.91	0.2194219	100
79908.01	0.2194528	100
79908.11	0.2194709	100
79908.21	0.2194971	100
79908.3	0.2195196	100
79908.41	0.2195371	100
79908.51	0.2195689	100
79908.61	0.2195828	100
79908.71	0.2196064	100
79908.81	0.2196395	100
79908.91	0.2196544	100
79909.01	0.2196842	100
79909.11	0.2197049	100
79909.21	0.2197249	100
79909.3	0.2197559	100
79909.41	0.2197696	100
79909.51	0.219799	100
79909.61	0.2198161	100
79909.71	0.219838	100
79909.81	0.2198672	100
79909.91	0.2198794	100
79910.01	0.2199072	100
79910.11	0.2199271	100
79910.21	0.2199481	100
79910.3	0.2199785	100
79910.41	0.2199954	100
79910.51	0.2200155	100
79910.61	0.2200387	100
79910.71	0.2200614	100
79910.81	0.2200877	100
79910.91	0.2201016	100
79911.01	0.2201258	100
79911.11	0.2201523	100
79911.21	0.2201699	100
79911.3	0.2201949	100
79911.41	0.2202109	100
79911.51	0.2202314	100
79911.61	0.2202551	100
79911.71	0.2202739	100
79911.81	0.2202998	100
79911.91	0.22032	100
79912.01	0.2203386	100
79912.11	0.2203651	100
79912.21	0.2203805	100
79912.3	0.2204037	100
79912.41	0.220423	100
79912.51	0.2204407	100
79912.61	0.220466	100
79912.71	0.2204843	100
79912.81	0.2205067	100
79912.91	0.2205271	100
79913.01	0.2205436	100
79913.11	0.2205664	100
79913.21	0.2205859	100
79913.3	0.2206059	100
79913.41	0.220629	100
79913.51	0.2206466	100
79913.61	0.2206729	100
79913.71	0.2206898	100
79913.81	0.2207136	100
79913.91	0.2207362	100
79914.01	0.2207525	100
79914.11	0.2207763	100
79914.21	0.220796	100
79914.3	0.2208154	100
79914.41	0.2208388	100
79914.51	0.220858	100
79914.61	0.22088	100
79914.71	0.2209016	100
79914.81	0.2209215	100
79914.91	0.2209416	100
79915.01	0.220958	100
79915.11	0.2209829	100
79915.21	0.221006	100
79915.3	0.2210247	100
79915.41	0.221048	100
79915.51	0.2210663	100
79915.61	0.2210882	100
79915.71	0.221113	100
79915.81	0.2211319	100
79915.91	0.2211538	100
79916.01	0.2211715	100
79916.11	0.2211952	100
79916.21	0.2212184	100
79916.3	0.2212366	100
79916.41	0.22126	100
79916.51	0.2212866	100
79916.61	0.2213041	100
79916.71	0.2213295	100
79916.81	0.2213441	100
79916.91	0.221365	100
79917.01	0.2213875	100
79917.11	0.2214144	100
79917.21	0.2214332	100
79917.3	0.2214492	100
79917.41	0.2214728	100
79917.51	0.2214937	100
79917.61	0.2215127	100
79917.71	0.2215333	100
79917.81	0.2215506	100
79917.91	0.2215725	100
79918.01	0.2215943	100
79918.11	0.2216164	100
79918.21	0.221635	100
79918.3	0.2216492	100
79918.41	0.2216723	100
79918.51	0.2216909	100
79918.61	0.2217144	100
79918.71	0.2217318	100
79918.81	0.2217523	100
79918.91	0.2217751	100
79919.01	0.2217957	100
79919.11	0.2218136	100
79919.21	0.2218309	100
79919.3	0.2218494	100
79919.41	0.2218695	100
79919.51	0.2218883	100
79919.61	0.2219126	100
79919.71	0.221928	100
79919.81	0.2219519	100
79919.91	0.2219727	100
79920.01	0.2219939	100
79920.11	0.2220165	100
79920.21	0.2220299	100
79920.3	0.2220497	100
79920.41	0.2220739	100
79920.51	0.2221003	100
79920.61	0.2221227	100
79920.71	0.2221396	100
79920.81	0.2221606	100
79920.91	0.2221851	100
79921.01	0.2221974	100
79921.11	0.222214	100
79921.21	0.2222363	100
79921.3	0.2222572	100
79921.41	0.2222813	100
79921.51	0.2222992	100
79921.61	0.2223192	100
79921.71	0.2223334	100
79921.81	0.2223504	100
79921.91	0.2223727	100
79922.01	0.2223907	100
79922.11	0.2224153	100
79922.21	0.2224334	100
79922.3	0.2224528	100
79922.41	0.2224771	100
79922.51	0.2224928	100
79922.61	0.2225114	100
79922.71	0.2225273	100
79922.81	0.2225482	100
79922.91	0.2225719	100
79923.01	0.2225911	100
79923.11	0.2226116	100
79923.21	0.2226316	100
79923.3	0.2226468	100
79923.41	0.2226704	100
79923.51	0.2226823	100
79923.61	0.2227045	100
79923.71	0.2227243	100
79923.81	0.222742	100
79923.91	0.2227692	100
79924.01	0.2227877	100
79924.11	0.2228073	100
79924.21	0.2228251	100
79924.3	0.2228421	100
79924.41	0.2228634	100
79924.51	0.2228789	100
79924.61	0.2229	100
79924.72	0.2229204	100
79924.81	0.2229377	100
79924.91	0.2229676	100
79925.01	0.2229824	100
79925.12	0.2229982	100
79925.21	0.2230184	100

79925.31	0.2230349	100
79925.72	0.2231177	100
79926.12	0.2231924	100
79926.51	0.2232759	100
79926.91	0.2233565	100
79927.31	0.223425	100
79927.72	0.2235077	100
79928.12	0.223583	100
79928.51	0.2236627	100
79928.91	0.2237397	100
79929.31	0.223814	100
79929.72	0.2238907	100
79930.12	0.2239702	100
79930.51	0.224043	100
79930.91	0.2241287	100
79931.31	0.2241902	100
79931.72	0.2242712	100
79932.12	0.2243457	100
79932.51	0.2244164	100
79932.91	0.2245056	100
79933.31	0.224565	100
79933.72	0.2246461	100
79934.12	0.2247181	100
79934.51	0.2247857	100
79934.91	0.2248668	100
79935.31	0.2249297	100
79935.72	0.2250045	100
79936.12	0.2250816	100
79936.51	0.2251419	100
79936.91	0.2252329	100
79937.31	0.2252974	100
79937.72	0.2253711	100
79938.12	0.2254514	100
79938.51	0.2255168	100
79938.91	0.2256015	100
79939.31	0.2256584	100
79939.72	0.2257318	100
79940.12	0.2258081	100
79940.51	0.225868	100
79940.91	0.2259551	100
79941.31	0.2260111	100
79941.72	0.2260836	100
79942.12	0.2261644	100
79942.51	0.2262189	100
79942.91	0.2263053	100
79943.31	0.2263691	100
79943.72	0.2264364	100
79944.12	0.2265145	100
79944.51	0.2265666	100
79944.91	0.2266503	100
79945.31	0.2267118	100
79945.72	0.2267778	100
79946.12	0.2268689	100
79946.51	0.2269254	100
79946.91	0.2270132	100
79947.31	0.2270795	100
79947.72	0.2271418	100
79948.12	0.2272297	100
79948.51	0.2272806	100
79948.91	0.227369	100
79949.31	0.2274215	100
79949.72	0.2274979	100
79950.12	0.2275664	100
79950.51	0.2276239	100
79950.91	0.2277083	100
79951.31	0.2277528	100
79951.72	0.2278361	100
79952.12	0.2278961	100
79952.51	0.2279651	100
79952.91	0.2280472	100
79953.31	0.2280959	100
79953.72	0.2281888	100
79954.12	0.2282312	100
79954.51	0.2283212	100
79954.91	0.2283757	100
79955.31	0.2284511	100
79955.72	0.2285146	100
79956.12	0.2285769	100
79956.51	0.2286562	100
79956.91	0.2287058	100
79957.31	0.228796	100
79957.72	0.2288375	100
79958.12	0.2289271	100
79958.51	0.2289714	100
79958.91	0.2290558	100
79959.31	0.2291106	100
79959.72	0.22918	100
79960.12	0.2292535	100
79960.51	0.2293114	100
79960.91	0.2293906	100
79961.31	0.229442	100
79961.72	0.2295249	100
79962.12	0.2295673	100
79962.51	0.229654	100
79962.91	0.2296923	100
79963.31	0.2297803	100
79963.72	0.2298154	100
79964.12	0.2299046	100
79964.51	0.2299405	100
79964.91	0.2300411	100
79965.31	0.2300789	100
79965.72	0.230172	100
79966.12	0.2302082	100
79966.51	0.2303002	100
79966.91	0.2303409	100
79967.31	0.230426	100
79967.72	0.2304624	100
79968.12	0.2305483	100
79968.51	0.2305912	100
79968.91	0.2306766	100
79969.31	0.2307179	100
79969.72	0.2308047	100
79970.12	0.2308417	100
79970.51	0.2309319	100
79970.91	0.2309662	100
79971.31	0.231057	100
79971.72	0.2310895	100
79972.12	0.2311791	100
79972.51	0.231209	100
79972.91	0.2312983	100
79973.31	0.2313295	100
79973.72	0.23142	100
79974.12	0.2314545	100
79974.51	0.2315403	100
79974.91	0.2315791	100
79975.31	0.2316692	100
79975.72	0.2317123	100
79976.12	0.231787	100
79976.51	0.2318424	100
79976.91	0.2319084	100
79977.31	0.2319786	100
79977.72	0.2320248	100
79978.12	0.2321017	100
79978.51	0.2321352	100
79978.91	0.2322267	100
79979.31	0.2322546	100
79979.72	0.2323493	100
79980.12	0.2323802	100
79980.51	0.2324627	100
79980.91	0.2325085	100
79981.31	0.2325783	100
79981.72	0.2326373	100
79982.12	0.23269	100
79982.51	0.2327668	100
79982.91	0.2328012	100
79983.31	0.2328913	100
79983.72	0.2329202	100
79984.12	0.2330122	100
79984.51	0.2330374	100
79984.91	0.2331259	100
79985.31	0.2331643	100
79985.72	0.2332338	100
79986.12	0.2332894	100
79986.51	0.2333356	100
79986.91	0.2334197	100
79987.31	0.2334465	100
79987.72	0.2335374	100
79988.12	0.2335682	100
79988.51	0.233651	100
79988.91	0.2336969	100
79989.31	0.2337524	100
79989.72	0.2338291	100
79990.12	0.2338608	100
79990.51	0.2339503	100
79990.91	0.233976	100
79991.31	0.234064	100
79991.72	0.2341123	100
79992.12	0.2341612	100
79992.51	0.2342439	100
79992.91	0.2342712	100
79993.31	0.2343561	100
79993.72	0.2344013	100
79994.12	0.234457	100
79994.51	0.2345331	100
79994.91	0.2345585	100
79995.31	0.2346482	100
79995.72	0.2346867	100
79996.12	0.2347484	100
79996.51	0.2348224	100
79996.91	0.2348515	100
79997.31	0.2349405	100
79997.72	0.2349795	100
79998.12	0.2350374	100
79998.51	0.2351195	100
79998.91	0.2351427	100
79999.31	0.2352338	100
79999.72	0.2352643	100
80000.12	0.2353346	100
80000.51	0.235404	100
80000.91	0.2354342	100
80001.31	0.2355268	100
80001.72	0.2355618	100
80002.12	0.2356252	100
80002.51	0.2357022	100
80002.91	0.2357278	100
80003.31	0.2358164	100
80003.72	0.235853	100
80004.12	0.2359099	100
80004.51	0.2359926	100
80004.91	0.236019	100
80005.31	0.2361034	100
80005.72	0.2361519	100
80006.12	0.2361976	100
80006.51	0.236281	100
80006.91	0.2363086	100
80007.31	0.2363704	100
80007.72	0.2364494	100
80008.12	0.236472	100
80008.51	0.2365554	100
80008.91	0.2366074	100
80009.31	0.2366413	100
80009.72	0.2367302	100
80010.12	0.2367685	100
80010.51	0.2368177	100
80010.91	0.236901	100
80011.31	0.2369279	100
80011.72	0.2369884	100
80012.12	0.2370691	100
80012.51	0.2370911	100
80012.91	0.2371686	100
80013.31	0.2372277	100
80013.72	0.2372565	100
80014.12	0.2373377	100
80014.51	0.2373899	100
80014.91	0.2374203	100
80015.31	0.2375058	100
80015.72	0.2375443	100
80016.12	0.237585	100
80016.51	0.2376695	100
80016.91	0.2377009	100
80017.31	0.2377498	100
80017.72	0.2378324	100
80018.12	0.2378591	100
80018.51	0.2379131	100
80018.91	0.2379914	100
80019.31	0.2380146	100
80019.72	0.2380801	100
80020.12	0.2381483	100
80020.51	0.2381747	100
80020.91	0.2382485	100
80021.31	0.2383063	100
80021.72	0.2383362	100
80022.12	0.2384154	100
80022.51	0.2384625	100
80022.91	0.2384969	100
80023.31	0.2385803	100
80023.72	0.2386138	100
80024.12	0.2386584	100
80024.51	0.2387394	100
80024.91	0.2387699	100
80025.31	0.2388205	100
80025.72	0.2389014	100
80026.12	0.2389274	100
80026.51	0.2389866	100
80026.91	0.2390617	100
80027.31	0.2390864	100
80027.72	0.2391428	100
80028.12	0.2392192	100
80028.51	0.2392451	100
80028.91	0.2393037	100
80029.31	0.2393784	100
80029.72	0.2394043	100
80030.12	0.2394588	100
80030.51	0.2395323	100
80030.91	0.2395643	100
80031.31	0.2396065	100
80031.72	0.2396838	100
80032.12	0.2397257	100
80032.51	0.2397592	100
80032.91	0.2398359	100
80033.31	0.2398902	100
80033.72	0.2399158	100
80034.12	0.2399793	100
80034.51	0.2400483	100
80034.91	0.2400799	100
80035.31	0.240121	100
80035.72	0.2401961	100
80036.12	0.2402392	100
80036.51	0.2402712	100
80036.91	0.2403394	100
80037.31	0.2403994	100
80037.72	0.2404229	100
80038.12	0.2404816	100
80038.51	0.24055	100
80038.91	0.2405788	100
80039.31	0.2406191	100
80039.72	0.2406934	100
80040.12	0.2407453	100
80040.51	0.2407676	100
80040.91	0.240833	100
80041.31	0.2409013	100
80041.72	0.2409318	100
80042.12	0.2409787	100
80042.51	0.2410491	100
80042.91	0.2410943	100
80043.31	0.2411207	100
80043.72	0.2411779	100
80044.12	0.241247	100
80044.51	0.2412879	100
80044.91	0.2413161	100
80045.31	0.2413759	100
80045.72	0.2414427	100
80046.12	0.2414849	100
80046.51	0.2415139	100
80046.91	0.2415729	100
80047.31	0.2416375	100
80047.72	0.2416774	100
80048.12	0.2417057	100
80048.51	0.2417645	100
80048.91	0.2418327	100
80049.31	0.2418729	100
80049.72	0.241903	100
80050.12	0.2419627	100
80050.51	0.2420323	100
80050.91	0.2420723	100
80051.31	0.2421035	100
80051.72	0.2421529	100
80052.12	0.242222	100
80052.51	0.2422698	100
80052.91	0.2422989	100
80053.31	0.2423441	100
80053.72	0.2424118	100
80054.12	0.2424648	100
80054.51	0.2424967	100
80054.91	0.2425377	100
80055.31	0.2426058	100
80055.72	0.2426615	100
80056.13	0.2426925	100
80056.52	0.2427329	100
80056.92	0.2427977	100
80057.32	0.2428531	100
80057.73	0.2428824	100
80058.13	0.2429238	100
80058.52	0.2429879	100
80058.92	0.2430415	100
80059.32	0.2430691	100
80059.73	0.2431103	100
80060.13	0.2431748	100
80060.52	0.2432283	100
80060.92	0.2432597	100
80061.32	0.2432947	100
80061.73	0.2433564	100
80062.13	0.2434224	100
80062.52	0.24347	100
80062.92	0.2435057	100
80063.32	0.2435509	100
80063.73	0.2436099	100
80064.13	0.2436648	100
80064.52	0.2437062	100
80064.92	0.2437378	100
80065.32	0.2437832	100
80065.73	0.2438436	100
80066.13	0.2439004	100
80066.52	0.2439419	100
80066.92	0.2439787	100
80067.32	0.2440289	100
80067.73	0.2440897	100
80068.13	0.2441434	100
80068.52	0.2441848	100
80068.92	0.2442199	100
80069.32	0.244261	100
80069.73	0.2443171	100
80070.13	0.2443784	100
80070.52	0.2444264	100
80070.92	0.2444672	100
80071.32	0.2445026	100
80071.73	0.2445521	100
80072.13	0.2446088	100
80072.52	0.2446628	100
80072.92	0.2447061	100
80073.32	0.2447437	100
80073.73	0.2447877	100
80074.13	0.2448418	100
80074.52	0.2449005	100
80074.92	0.2449462	100
80075.32	0.2449862	100
80075.73	0.2450238	100
80076.13	0.2450706	100
80076.52	0.2451243	100
80076.92	0.2451789	100
80077.32	0.2452236	100
80077.73	0.2452623	100
80078.13	0.2452984	100
80078.52	0.2453408	100
80078.92	0.2453947	100
80079.32	0.2454508	100
80079.73	0.2454975	100
80080.13	0.2455337	100
80080.52	0.2455733	100
80080.92	0.2456211	100
80081.32	0.2456772	100
80081.73	0.2457297	100
80082.13	0.2457765	100
80082.52	0.2458119	100
80082.92	0.2458483	100
80083.32	0.2458952	100
80083.73	0.2459476	100
80084.13	0.245998	100
80084.52	0.2460409	100
80084.92	0.2460789	100
80085.32	0.2461156	100
80085.73	0.246157	100
80086.13	0.2462047	100
80086.52	0.2462565	100
80086.92	0.2463023	100
80087.32	0.2463438	100
80087.73	0.2463829	100
80088.13	0.2464165	100
80088.52	0.2464579	100
80088.92	0.2465067	100
80089.32	0.2465579	100
80089.73	0.2466042	100
80090.13	0.2466465	100
80090.52	0.2466831	100
80090.92	0.2467198	100
80091.32	0.2467622	100
80091.73	0.2468112	100
80092.13	0.246862	100
80092.52	0.2469035	100
80092.92	0.2469463	100
80093.32	0.2469836	100
80093.73	0.2470229	100
80094.13	0.2470676	100
80094.52	0.2471192	100
80094.92	0.2471688	100
80095.32	0.2472099	100
80095.73	0.2472468	100
80096.13	0.2472849	100
80096.52	0.2473257	100
80096.92	0.2473699	100
80097.32	0.2474205	100
80097.73	0.2474678	100
80098.13	0.2475084	100
80098.52	0.2475455	100
80098.92	0.2475813	100
80099.32	0.2476231	100
80099.73	0.2476702	100
80100.13	0.2477181	100
80100.52	0.2477642	100
80100.92	0.2478063	100
80101.32	0.2478448	100
80101.73	0.2478812	100
80102.13	0.2479222	100
80102.52	0.2479663	100
80102.92	0.2480107	100
80103.32	0.248055	100
80103.73	0.2480978	100
80104.13	0.2481343	100
80104.52	0.2481708	100
80104.92	0.2482115	100
80105.32	0.2482561	100
80105.73	0.2483042	100
80106.13	0.2483479	100
80106.52	0.2483897	100
80106.92	0.2484277	100
80107.32	0.2484689	100
80107.73	0.2485076	100
80108.13	0.2485538	100
80108.52	0.2486024	100
80108.92	0.2486462	100
80109.32	0.2486879	100
80109.73	0.248728	100
80110.13	0.2487663	100
80110.52	0.2488056	100
80110.92	0.2488519	100
80111.32	0.248895	100
80111.73	0.2489353	100
80112.13	0.248971	100
80112.52	0.2490099	100
80112.92	0.2490476	100
80113.32	0.2490919	100
80113.73	0.2491338	100
80114.13	0.2491733	100
80114.52	0.2492134	100
80114.92	0.2492524	100
80115.32	0.2492958	100
80115.73	0.2493409	100
80116.13	0.2493863	100
80116.52	0.2494282	100
80116.92	0.2494719	100
80117.32	0.2495129	100
80117.73	0.2495532	100
80118.13	0.2495958	100
80118.52	0.2496389	100
80118.92	0.2496828	100
80119.32	0.2497268	100
80119.73	0.2497685	100
80120.13	0.2498091	100
80120.52	0.2498495	100
80120.92	0.2498894	100
80121.32	0.2499308	100
80121.73	0.2499771	100
80122.13	0.2500232	100
80122.52	0.2500655	100
80122.92	0.2501051	100
80123.32	0.2501466	100
80123.73	0.2501897	100
80124.13	0.2502299	100
80124.52	0.2502703	100
80124.92	0.2503148	100
80125.32	0.2503581	100
80125.73	0.2503987	100
80126.13	0.2504366	100
80126.52	0.2504764	100
80126.92	0.2505198	100
80127.32	0.2505611	100
80127.73	0.250599	100
80128.13	0.2506404	100
80128.52	0.2506818	100
80128.92	0.2507254	100
80129.32	0.2507695	100
80129.73	0.2508104	100
80130.13	0.2508492	100
80130.52	0.250891	100
80130.92	0.2509316	100
80131.32	0.2509724	100
80131.73	0.2510115	100
80132.13	0.2510533	100
80132.52	0.2510947	100
80132.92	0.2511373	100
80133.32	0.2511792	100
80133.73	0.2512206	100
80134.13	0.2512587	100
80134.52	0.2512978	100
80134.92	0.2513404	100
80135.32	0.2513824	100
80135.73	0.2514178	100
80136.13	0.2514562	100
80136.52	0.2514943	100
80136.92	0.2515332	100
80137.32	0.2515736	100
80137.73	0.2516162	100
80138.13	0.2516543	100
80138.52	0.2516926	100
80138.92	0.2517288	100
80139.32	0.251769	100
80139.73	0.2518065	100
80140.13	0.2518433	100
80140.52	0.2518816	100
80140.92	0.2519244	100
80141.32	0.251964	100
80141.73	0.2520044	100
80142.13	0.2520454	100
80142.52	0.2520865	100
80142.92	0.2521279	100
80143.32	0.2521664	100
80143.73	0.2522061	100
80144.13	0.2522434	100
80144.52	0.2522806	100
80144.92	0.2523165	100
80145.32	0.2523547	100
80145.73	0.2523921	100
80146.13	0.2524317	100
80146.52	0.252471	100
80146.92	0.2525089	100
80147.32	0.2525475	100
80147.73	0.2525868	100
80148.13	0.2526278	100
80148.52	0.2526646	100
80148.92	0.2527035	100
80149.32	0.2527468	100
80149.73	0.2527845	100
80150.13	0.2528223	100
80150.52	0.2528585	100
80150.92	0.2528969	100
80151.32	0.2529328	100
80151.73	0.2529729	100
80152.13	0.2530122	100
80152.52	0.2530512	100
80152.92	0.2530883	100
80153.32	0.2531263	100
80153.73	0.2531655	100
80154.13	0.2532033	100
80154.52	0.2532458	100
80154.92	0.253288	100
80155.32	0.2533287	100
80155.73	0.2533614	100
80156.13	0.2534044	100
80156.52	0.2534467	100
80156.92	0.2534837	100
80157.32	0.2535239	100
80157.73	0.2535657	100
80158.13	0.2536051	100
80158.52	0.2536421	100
80158.92	0.2536831	100
80159.32	0.2537213	100
80159.73	0.2537616	100
80160.13	0.2538026	100
80160.52	0.2538414	100
80160.92	0.2538828	100
80161.32	0.2539201	100
80161.73	0.2539587	100
80162.13	0.2539975	100
80162.52	0.254034	100
80162.92	0.2540725	100
80163.32	0.2541121	100
80163.73	0.2541523	100
80164.13	0.2541902	100
80164.52	0.2542289	100
80164.92	0.254268	100
80165.32	0.2543041	100
80165.73	0.2543421	100
80166.13	0.2543766	100
80166.52	0.2544133	100
80166.92	0.2544492	100
80167.32	0.2544861	100
80167.73	0.254524	100
80168.13	0.2545592	100
80168.52	0.2545961	100
80168.92	0.2546304	100
80169.32	0.2546656	100
80169.73	0.2547038	100
80170.13	0.2547405	100
80170.52	0.2547793	100
80170.92	0.2548164	100
80171.32	0.2548524	100
80171.73	0.2548892	100
80172.13	0.2549291	100
80172.52	0.2549616	100
80172.92	0.2549992	100
80173.32	0.255033	100
80173.73	0.2550686	100
80174.13	0.2551042	100
80174.52	0.2551421	100
80174.92	0.2551824	100
80175.32	0.2552209	100
80175.73	0.2552586	100
80176.13	0.2552962	100
80176.52	0.255336	100
80176.92	0.2553739	100
80177.32	0.2554127	100
80177.73	0.2554516	100
80178.13	0.2554917	100
80178.52	0.2555302	100
80178.92	0.2555703	100
80179.32	0.2556107	100
80179.73	0.2556491	100
80180.13	0.2556884	100
80180.52	0.2557259	100
80180.92	0.2557645	100
80181.32	0.2558035	100
80181.73	0.2558407	100
80182.13	0.2558806	100
80182.52	0.2559188	100
80182.92	0.2559599	100
80183.32	0.2559984	100
80183.73	0.2560378	100
80184.13	0.256075	100
80184.52	0.2561141	100
80184.92	0.2561527	100
80185.32	0.2561917	100
80185.73	0.2562336	100
80186.13	0.2562692	100
80186.52	0.2563085	100
80186.92	0.2563451	100
80187.33	0.2563824	100
80187.73	0.2564201	100
80188.13	0.2564596	100
80188.53	0.2564972	100
80188.93	0.2565344	100
80189.33	0.2565719	100
80189.73	0.2566091	100
80190.13	0.2566457	100
80190.53	0.2566831	100
80190.93	0.25672	100
80191.33	0.2567566	100
80191.73	0.2567936	100
80192.13	0.256831	100
80192.53	0.2568678	100
80192.93	0.2569013	100
80193.33	0.2569359	100
80193.73	0.256971	100
80194.13	0.2570056	100
80194.53	0.2570412	100
80194.93	0.2570769	100
80195.33	0.2571116	100
80195.73	0.2571438	100
80196.13	0.2571785	100
80196.53	0.2572145	100
80196.93	0.2572535	100
80197.33	0.2572904	100
80197.73	0.2573264	100
80198.13	0.2573634	100
80198.53	0.2573989	100
80198.93	0.2574322	100
80199.33	0.257467	100
80199.73	0.2575042	100
80200.13	0.2575402	100
80200.53	0.2575787	100
80200.93	0.2576198	100
80201.33	0.2576588	100
80201.73	0.2576961	100
80202.13	0.2577347	100
80202.53	0.2577726	100
80202.93	0.2578092	100
80203.33	0.2578467	100
80203.73	0.2578854	100
80204.13	0.2579248	100
80204.53	0.257961	100
80204.93	0.2579975	100
80205.33	0.2580313	100
80205.73	0.2580687	100
80206.13	0.2581056	100
80206.53	0.2581419	100
80206.93	0.2581764	100
80207.33	0.2582097	100
80207.73	0.2582428	100
80208.13	0.2582762	100
80208.53	0.2583083	100
80208.93	0.2583403	100
80209.33	0.2583743	100
80209.73	0.2584073	100
80210.13	0.2584413	100
80210.53	0.2584757	100
80210.93	0.2585129	100
80211.33	0.2585517	100
80211.73	0.258589	100
80212.13	0.2586266	100
80212.53	0.2586626	100
80212.93	0.2586999	100
80213.33	0.2587371	100
80213.73	0.2587805	100
80214.13	0.2588169	100
80214.53	0.2588567	100
80214.93	0.2588917	100
80215.33	0.2589282	100
80215.73	0.2589611	100
80216.13	0.2589977	100
80216.53	0.2590357	100
80216.93	0.2590673	100
80217.33	0.2591005	100
80217.73	0.2591301	100
80218.13	0.2591634	100
80218.53	0.2591963	100
80218.93	0.259231	100
80219.33	0.259265	100
80219.73	0.259303	100
80220.13	0.2593383	100
80220.53	0.2593759	100
80220.93	0.259412	100
80221.33	0.2594484	100
80221.73	0.2594841	100
80222.13	0.259527	100
80222.53	0.2595687	100
80222.93	0.2596064	100
80223.33	0.2596433	100
80223.73	0.2596805	100
80224.13	0.2597173	100
80224.53	0.2597533	100
80224.93	0.2597885	100
80225.33	0.2598191	100
80225.73	0.2598516	100
80226.13	0.259881	100
80226.53	0.2599168	100
80226.93	0.2599506	100
80227.33	0.259982	100
80227.73	0.2600124	100
80228.13	0.2600474	100
80228.53	0.2600857	100
80228.93	0.2601237	100
80229.33	0.2601654	100
80229.73	0.2602047	100
80230.13	0.2602436	100
80230.53	0.2602795	100
80230.93	0.2603157	100
80231.33	0.2603486	100
80231.73	0.2603795	100
80232.13	0.2604106	100
80232.53	0.2604411	100
80232.93	0.2604677	100
80233.33	0.2604981	100
80233.73	0.2605299	100
80234.13	0.2605635	100
80234.53	0.2606012	100
80234.93	0.260643	100
80235.33	0.2606848	100
80235.73	0.2607209	100
80236.13	0.2607604	100
80236.53	0.2607953	100
80236.93	0.2608314	100
80237.33	0.2608607	100
80237.73	0.2608907	100
80238.13	0.2609183	100
80238.53	0.2609495	100
80238.93	0.2609799	100
80239.33	0.2610139	100
80239.73	0.2610499	100
80240.13	0.2610859	100
80240.53	0.2611254	100
80240.93	0.2611649	100
80241.33	0.2612036	100
80241.73	0.2612412	100
80242.13	0.261278	100
80242.53	0.2613116	100
80242.93	0.2613397	100
80243.33	0.2613625	100
80243.73	0.2613875	100
80244.13	0.2614188	100
80244.53	0.2614522	100
80244.93	0.2614886	100
80245.33	0.261525	100
80245.73	0.2615656	100
80246.13	0.2616078	100
80246.53	0.2616486	100
80246.93	0.2616823	100
80247.33	0.2617107	100
80247.73	0.2617384	100
80248.13	0.2617607	100
80248.53	0.2617873	100
80248.93	0.2618204	100
80249.33	0.2618618	100
80249.73	0.2619045	100
80250.13	0.2619444	100
80250.53	0.2619831	100
80250.93	0.2620186	100
80251.33	0.2620472	100
80251.73	0.2620711	100
80252.13	0.2620995	100
80252.53	0.2621261	100
80252.93	0.2621547	100
80253.33	0.2621922	100
80253.73	0.2622362	100
80254.13	0.2622745	100
80254.53	0.2623111	100
80254.93	0.2623454	100
80255.33	0.2623703	100
80255.73	0.2623932	100
80256.13	0.2624177	100
80256.53	0.2624475	100
80256.93	0.2624864	100
80257.33	0.2625239	100
80257.73	0.2625667	100
80258.13	0.2626061	100
80258.53	0.2626389	100
80258.93	0.2626691	100
80259.33	0.2626909	100
80259.73	0.2627145	100
80260.13	0.2627402	100
80260.53	0.2627732	100
80260.93	0.2628106	100
80261.33	0.2628464	100
80261.73	0.2628866	100
80262.13	0.2629281	100
80262.53	0.2629633	100
80262.93	0.2629935	100
80263.33	0.2630249	100
80263.73	0.2630435	100
80264.13	0.2630716	100
80264.53	0.2631042	100
80264.93	0.2631438	100
80265.33	0.2631822	100
80265.73	0.2632269	100
80266.13	0.2632661	100
80266.53	0.2632965	100
80266.93	0.2633198	100
80267.33	0.2633422	100
80267.73	0.2633717	100
80268.13	0.263402	100
80268.53	0.2634413	100
80268.93	0.2634829	100
80269.33	0.2635286	100
80269.73	0.2635626	100
80270.13	0.2635929	100
80270.53	0.2636157	100
80270.93	0.263638	100
80271.33	0.2636629	100
80271.73	0.2636977	100
80272.13	0.2637424	100
80272.53	0.263787	100
80272.93	0.2638273	100
80273.33	0.2638593	100
80273.73	0.2638809	100
80274.13	0.2638996	100
80274.53	0.2639231	100
80274.93	0.2639555	100
80275.33	0.2639989	100
80275.73	0.2640421	100
80276.13	0.2640783	100
80276.53	0.2641077	100
80276.93	0.2641263	100
80277.33	0.2641488	100
80277.73	0.2641725	100
80278.13	0.2642054	100
80278.53	0.2642465	100
80278.93	0.2642863	100
80279.33	0.264325	100
80279.73	0.2643573	100
80280.13	0.2643862	100
80280.53	0.2644102	100
80280.93	0.2644309	100
80281.33	0.2644528	100
80281.73	0.2644878	100
80282.13	0.2645305	100
80282.53	0.26457	100
80282.93	0.2646115	100
80283.33	0.2646374	100
80283.73	0.264657	100
80284.13	0.264677	100
80284.53	0.264704	100
80284.93	0.2647436	100
80285.33	0.2647921	100
80285.73	0.2648355	100
80286.13	0.2648664	100
80286.53	0.2648831	100
80286.93	0.2649014	100
80287.33	0.2649288	100
80287.73	0.264965	100
80288.13	0.2650099	100
80288.53	0.2650511	100
80288.93	0.2650861	100
80289.33	0.2651047	100
80289.73	0.2651243	100
80290.13	0.2651469	100
80290.53	0.26518	100
80290.93	0.265223	100
80291.33	0.265266	100
80291.73	0.2653005	100
80292.13	0.2653216	100
80292.53	0.2653429	100
80292.93	0.2653602	100
80293.33	0.2653927	100
80293.73	0.2654381	100
80294.13	0.2654831	100
80294.53	0.2655192	100
80294.93	0.2655477	100
80295.33	0.265566	100
80295.73	0.2655874	100
80296.13	0.2656159	100
80296.53	0.2656552	100
80296.93	0.2657004	100
80297.33	0.2657367	100
80297.73	0.2657617	100
80298.13	0.2657802	100
80298.53	0.2657964	100
80298.93	0.2658266	100
80299.33	0.2658688	100
80299.73	0.2659129	100
80300.13	0.2659513	100
80300.53	0.2659782	100
80300.93	0.2659948	100
80301.33	0.2660137	100
80301.73	0.2660443	100
80302.13	0.2660879	100
80302.53	0.2661316	100
80302.93	0.2661659	100
80303.33	0.2661879	100
80303.73	0.2662032	100
80304.13	0.266226	100
80304.53	0.2662601	100
80304.93	0.2663051	100
80305.33	0.2663457	100
80305.73	0.2663804	100
80306.13	0.2664047	100
80306.53	0.2664251	100
80306.93	0.2664443	100
80307.33	0.2664738	100
80307.73	0.2665112	100
80308.13	0.266555	100
80308.53	0.2665935	100
80308.93	0.266625	100
80309.33	0.2666462	100
80309.73	0.2666625	100
80310.13	0.2666831	100
80310.53	0.2667153	100
80310.93	0.2667585	100
80311.33	0.2668016	100
80311.73	0.2668368	100
80312.13	0.2668671	100
80312.53	0.2668879	100
80312.93	0.2669058	100
80313.33	0.2669279	100
80313.73	0.2669606	100
80314.13	0.2670001	100
80314.53	0.2670461	100
80314.93	0.2670838	100
80315.33	0.2671149	100
80315.73	0.2671351	100
80316.13	0.2671543	100
80316.53	0.2671844	100
80316.93	0.2672188	100
80317.33	0.2672599	100
80317.73	0.2673029	100
80318.13	0.2673398	100
80318.53	0.267366	100
80318.93	0.2673832	100
80319.33	0.267401	100
80319.73	0.2674285	100
80320.13	0.2674716	100
80320.53	0.2675168	100
80320.93	0.2675543	100
80321.33	0.2675807	100
80321.73	0.2675954	100
80322.13	0.2676147	100
80322.53	0.2676454	100
80322.93	0.2676858	100
80323.33	0.2677323	100
80323.73	0.2677737	100
80324.13	0.2677986	100
80324.53	0.2678185	100
80324.93	0.267835	100
80325.33	0.2678595	100
80325.73	0.2678958	100
80326.13	0.2679384	100
80326.53	0.2679799	100
80326.93	0.2680094	100
80327.33	0.2680336	100
80327.73	0.268047	100
80328.13	0.2680671	100
80328.53	0.268097	100
80328.93	0.268141	100
80329.33	0.2681853	100
80329.73	0.2682205	100
80330.13	0.2682455	100
80330.53	0.2682622	100
80330.92	0.2682848	100
80331.32	0.2683159	100
80331.73	0.2683587	100
80332.13	0.2684	100
80332.52	0.2684345	100
80332.92	0.2684608	100
80333.32	0.2684759	100
80333.73	0.2684908	100
80334.13	0.2685189	100
80334.52	0.2685554	100
80334.92	0.2685945	100
80335.32	0.2686334	100
80335.73	0.2686633	100
80336.13	0.268682	100
80336.52	0.2687003	100
80336.92	0.2687209	100
80337.32	0.2687513	100
80337.73	0.2687837	100
80338.13	0.2688258	100
80338.52	0.2688668	100
80338.92	0.2689001	100
80339.32	0.2689237	100
80339.73	0.2689456	100
80340.13	0.2689627	100
80340.52	0.2689814	100
80340.92	0.2690073	100
80341.32	0.2690417	100
80341.73	0.2690778	100
80342.13	0.2691121	100
80342.52	0.2691464	100
80342.92	0.269173	100
80343.32	0.2691916	100
80343.73	0.2692086	100
80344.13	0.269232	100
80344.52	0.2692641	100
80344.92	0.2693016	100
80345.32	0.2693403	100
80345.73	0.269377	100
80346.13	0.2694064	100
80346.52	0.2694295	100
80346.92	0.2694503	100
80347.32	0.2694698	100
80347.73	0.2694932	100
80348.13	0.2695214	100
80348.52	0.2695537	100
80348.92	0.2695902	100
80349.32	0.2696315	100
80349.73	0.2696641	100
80350.13	0.2696914	100
80350.52	0.2697151	100
80350.92	0.2697355	100
80351.32	0.2697612	100
80351.73	0.2697879	100
80352.13	0.2698212	100
80352.52	0.269861	100
80352.92	0.2699	100
80353.32	0.2699382	100
80353.73	0.2699681	100
80354.13	0.26999	100
80354.52	0.2700088	100
80354.92	0.2700272	100
80355.32	0.2700537	100
80355.73	0.2700879	100
80356.13	0.2701251	100
80356.52	0.2701625	100
80356.92	0.2701987	100
80357.32	0.2702318	100
80357.73	0.2702551	100
80358.13	0.2702748	100
80358.52	0.2702905	100
80358.92	0.2703091	100
80359.32	0.2703368	100
80359.73	0.270369	100
80360.13	0.2704089	100
80360.52	0.2704442	100
80360.92	0.270478	100
80361.32	0.2705045	100
80361.73	0.2705266	100
80362.13	0.2705471	100
80362.52	0.2705669	100
80362.92	0.2705938	100
80363.32	0.2706232	100
80363.72	0.2706633	100
80364.12	0.270704	100
80364.51	0.2707405	100
80364.91	0.2707672	100
80365.31	0.2707881	100
80365.72	0.2708068	100
80366.12	0.2708291	100
80366.51	0.2708554	100
80366.91	0.2708865	100
80367.31	0.2709236	100
80367.72	0.2709615	100
80368.12	0.2709958	100
80368.51	0.2710223	100
80368.91	0.2710434	100
80369.31	0.2710611	100
80369.72	0.2710825	100
80370.12	0.2711079	100
80370.51	0.2711427	100
80370.91	0.2711782	100
80371.31	0.2712158	100
80371.72	0.2712457	100
80372.12	0.2712686	100
80372.51	0.2712881	100
80372.91	0.2713072	100
80373.31	0.2713281	100
80373.72	0.2713563	100
80374.12	0.2713912	100
80374.51	0.2714272	100
80374.91	0.2714636	100
80375.31	0.2714955	100
80375.72	0.271524	100
80376.12	0.2715487	100
80376.51	0.271573	100
80376.91	0.2715942	100
80377.31	0.2716178	100
80377.72	0.2716439	100
80378.12	0.2716713	100
80378.51	0.2717067	100
80378.91	0.2717423	100
80379.31	0.2717805	100
80379.72	0.2718129	100
80380.12	0.2718415	100
80380.51	0.2718637	100
80380.91	0.2718851	100
80381.31	0.2719097	100
80381.72	0.2719294	100
80382.12	0.2719562	100
80382.51	0.2719844	100
80382.91	0.2720195	100
80383.31	0.2720537	100
80383.72	0.2720923	100
80384.12	0.2721245	100
80384.51	0.2721559	100
80384.91	0.2721844	100
80385.31	0.2722109	100
80385.72	0.2722342	100
80386.12	0.2722548	100
80386.51	0.2722784	100
80386.91	0.272304	100
80387.31	0.2723304	100
80387.72	0.2723583	100
80388.12	0.2723912	100
80388.51	0.2724247	100
80388.91	0.272459	100
80389.31	0.2724909	100
80389.72	0.2725226	100
80390.01	0.2725276	100