File: Y261_recov4.txt
Time	Strain	Shear Stress
[s]	[1]	[Pa]
89450.12	0.2073582	0.0000000000000000000000007965861
89450.51	0.1881765	0
89450.92	0.1810377	0
89451.33	0.1763462	0
89451.73	0.1728131	0
89452.13	0.1699034	0
89452.51	0.1674467	0
89452.91	0.1652879	0
89453.31	0.1633556	0
89453.72	0.1616214	0
89454.12	0.1600447	0
89454.51	0.15859	0
89454.91	0.1572333	0
89455.31	0.1559623	0
89455.72	0.1547859	0
89456.12	0.1536816	0
89456.51	0.1526432	0
89456.91	0.1516525	0
89457.31	0.150702	0
89457.72	0.1497965	0
89458.12	0.1489271	0
89458.51	0.1481002	0
89458.91	0.1473103	0
89459.31	0.1465458	0
89459.73	0.1458167	0
89460.13	0.1451043	0
89460.52	0.1444133	0
89460.92	0.1437428	0
89461.33	0.1430861	0
89461.73	0.1424532	0
89462.13	0.1418281	0
89462.52	0.141231	0
89462.92	0.1406435	0
89463.33	0.1400762	0
89463.73	0.1395222	0
89464.13	0.1389827	0
89464.52	0.138451	0
89464.92	0.1379339	0
89465.33	0.1374274	0
89465.73	0.1369248	0
89466.13	0.1364362	0
89466.52	0.1359536	0
89466.92	0.1354823	0
89467.33	0.1350187	0
89467.73	0.1345615	0
89468.13	0.1341159	0
89468.52	0.1336785	0
89468.92	0.1332512	0
89469.33	0.1328265	0
89469.73	0.1324163	0
89470.13	0.1320136	0
89470.52	0.1316134	0
89470.92	0.1312222	0
89471.33	0.1308418	0
89471.73	0.1304589	0
89472.13	0.1300888	0
89472.52	0.1297201	0
89472.92	0.1293566	0
89473.33	0.1289974	0
89473.73	0.1286452	0
89474.13	0.1282937	0
89474.52	0.1279484	0
89474.92	0.1276122	0
89475.33	0.1272763	0
89475.73	0.1269429	0
89476.13	0.1266198	0
89476.52	0.1263012	0
89476.92	0.1259879	0
89477.33	0.1256764	0
89477.73	0.1253679	0
89478.13	0.1250677	0
89478.52	0.1247745	0
89478.92	0.1244784	0
89479.33	0.1241892	0
89479.73	0.1239035	0
89480.13	0.1236223	0
89480.52	0.1233451	0
89480.92	0.123068	0
89481.33	0.1227901	0
89481.73	0.1225196	0
89482.13	0.1222524	0
89482.52	0.1219828	0
89482.92	0.1217226	0
89483.33	0.12146	0
89483.73	0.1212009	0
89484.13	0.1209447	0
89484.52	0.1206939	0
89484.92	0.1204431	0
89485.33	0.1201931	0
89485.73	0.119947	0
89486.13	0.1197002	0
89486.52	0.1194604	0
89486.92	0.1192205	0
89487.33	0.1189819	0
89487.72	0.1187459	0
89488.12	0.1185145	0
89488.51	0.1182841	0
89488.91	0.1180568	0
89489.31	0.1178331	0
89489.72	0.1176109	0
89490.12	0.1173903	0
89490.51	0.1171684	0
89490.91	0.1169541	0
89491.31	0.1167428	0
89491.72	0.1165318	0
89492.12	0.1163208	0
89492.51	0.1161131	0
89492.91	0.115905	0
89493.31	0.115697	0
89493.72	0.1154958	0
89494.12	0.115295	0
89494.51	0.1150954	0
89494.91	0.1148909	0
89495.31	0.1146919	0
89495.72	0.1144905	0
89496.12	0.1142957	0
89496.51	0.1140993	0
89496.91	0.1139017	0
89497.31	0.1137063	0
89497.72	0.1135139	0
89498.12	0.1133233	0
89498.51	0.1131321	0
89498.91	0.1129423	0
89499.31	0.1127513	0
89499.72	0.1125648	0
89500.12	0.1123785	0
89500.51	0.1121927	0
89500.91	0.1120046	0
89501.31	0.111825	0
89501.72	0.1116375	0
89502.12	0.1114572	0
89502.51	0.1112765	0
89502.91	0.1110998	0
89503.31	0.1109234	0
89503.72	0.1107492	0
89504.12	0.1105744	0
89504.51	0.1104013	0
89504.91	0.1102337	0
89505.31	0.1100613	0
89505.72	0.1098932	0
89506.12	0.109728	0
89506.51	0.1095609	0
89506.91	0.1093922	0
89507.31	0.109226	0
89507.72	0.1090582	0
89508.12	0.1088915	0
89508.51	0.1087295	0
89508.91	0.1085666	0
89509.31	0.1084085	0
89509.72	0.1082493	0
89510.12	0.1080925	0
89510.51	0.107934	0
89510.91	0.1077774	0
89511.31	0.1076189	0
89511.72	0.1074619	0
89512.12	0.1073053	0
89512.51	0.1071523	0
89512.91	0.1070028	0
89513.31	0.1068517	0
89513.72	0.1067014	0
89514.12	0.1065461	0
89514.51	0.1063944	0
89514.91	0.1062411	0
89515.31	0.1060899	0
89515.72	0.1059429	0
89516.12	0.1057919	0
89516.51	0.1056443	0
89516.91	0.1054994	0
89517.31	0.1053554	0
89517.72	0.1052094	0
89518.12	0.105067	0
89518.51	0.1049235	0
89518.91	0.104779	0
89519.31	0.104638	0
89519.72	0.1044976	0
89520.12	0.1043574	0
89520.51	0.1042162	0
89520.91	0.1040796	0
89521.31	0.10394	0
89521.72	0.1038048	0
89522.12	0.1036684	0
89522.51	0.1035294	0
89522.91	0.1033954	0
89523.31	0.1032605	0
89523.72	0.1031253	0
89524.12	0.1029933	0
89524.51	0.1028625	0
89524.91	0.1027303	0
89525.31	0.1025986	0
89525.72	0.1024709	0
89526.12	0.1023417	0
89526.51	0.1022127	0
89526.91	0.1020853	0
89527.31	0.1019551	0
89527.72	0.101827	0
89528.12	0.1017027	0
89528.51	0.1015733	0
89528.91	0.1014502	0
89529.31	0.1013273	0
89529.72	0.1012024	0
89530.12	0.1010789	0
89530.51	0.1009577	0
89530.91	0.1008364	0
89531.31	0.1007119	0
89531.72	0.1005897	0
89532.12	0.1004688	0
89532.51	0.1003484	0
89532.91	0.1002296	0
89533.31	0.1001097	0
89533.72	0.09999142	0
89534.12	0.09986969	0
89534.51	0.0997513	0
89534.91	0.09963101	0
89535.31	0.09951285	0
89535.72	0.0993947	0
89536.12	0.09927745	0
89536.51	0.09916224	0
89536.91	0.09904628	0
89537.31	0.09893184	0
89537.72	0.09881745	0
89538.12	0.09870216	0
89538.51	0.0985885	0
89538.91	0.09847678	0
89539.31	0.09835973	0
89539.72	0.09824474	0
89540.12	0.09813149	0
89540.51	0.09801885	0
89540.91	0.09790617	0
89541.31	0.09779584	0
89541.72	0.0976871	0
89542.12	0.0975785	0
89542.51	0.09746904	0
89542.91	0.09735877	0
89543.31	0.09724642	0
89543.72	0.09714338	0
89544.12	0.09703416	0
89544.51	0.09692572	0
89544.91	0.09681787	0
89545.31	0.09671134	0
89545.72	0.09660447	0
89546.12	0.09650223	0
89546.51	0.09639697	0
89546.91	0.09629454	0
89547.31	0.09619177	0
89547.72	0.09608815	0
89548.12	0.09598348	0
89548.51	0.09588198	0
89548.91	0.09577903	0
89549.31	0.09567558	0
89549.72	0.09557451	0
89551.02	0.09530747	0
89555.02	0.09433958	0
89559.02	0.09340807	0
89563.02	0.09250795	0
89567.02	0.09163119	0
89571.02	0.0907827	0
89575.02	0.08995841	0
89579.02	0.08914921	0
89583.02	0.08837085	0
89587.02	0.08762158	0
89591.02	0.08689604	0
89595.02	0.08617585	0
89599.02	0.0854833	0
89603.02	0.084825	0
89607.02	0.08416715	0
89611.02	0.08353181	0
89615.02	0.08290244	0
89619.02	0.08229657	0
89623.02	0.08169398	0
89627.02	0.08111415	0
89631.02	0.08053657	0
89635.02	0.07997236	0
89639.02	0.07941871	0
89643.02	0.0788836	0
89647.02	0.07834576	0
89651.02	0.07782259	0
89655.02	0.07732347	0
89659.02	0.07682789	0
89663.02	0.07634041	0
89667.02	0.07585965	0
89671.02	0.07539583	0
89675.02	0.07494561	0
89679.02	0.07450257	0
89683.02	0.07406619	0
89687.02	0.07364866	0
89691.02	0.07322931	0
89695.02	0.07280416	0
89699.02	0.07238715	0
89703.02	0.0719851	0
89707.02	0.07160115	0
89711.02	0.07121021	0
89715.02	0.07082443	0
89719.02	0.07046426	0
89723.02	0.07009614	0
89727.02	0.06975095	0
89731.02	0.06940465	0
89735.02	0.06904954	0
89739.02	0.06870411	0
89743.02	0.06836485	0
89747.02	0.06803513	0
89751.02	0.06770574	0
89755.02	0.06739172	0
89759.02	0.06707678	0
89763.02	0.0667731	0
89767.02	0.06645385	0
89771.02	0.06615665	0
89775.02	0.06587289	0
89779.02	0.06557238	0
89783.02	0.06529106	0
89787.02	0.06500742	0
89791.02	0.06472594	0
89795.02	0.06443156	0
89799.02	0.06412914	0
89803.02	0.06385826	0
89807.02	0.06360425	0
89811.02	0.06335048	0
89815.02	0.06308721	0
89819.02	0.06284468	0
89823.02	0.06258619	0
89827.02	0.06233475	0
89831.02	0.06208107	0
89835.02	0.06184251	0
89839.02	0.0615871	0
89843.02	0.06135786	0
89847.02	0.06113435	0
89851.02	0.06090066	0
89855.02	0.06067161	0
89859.02	0.06043901	0
89863.02	0.0602177	0
89867.02	0.06000134	0
89871.02	0.05977842	0
89875.02	0.05954488	0
89879.02	0.05933387	0
89883.02	0.05911974	0
89887.02	0.05891022	0
89891.02	0.05870477	0
89895.02	0.05847736	0
89899.02	0.0582351	0
89903.02	0.05803556	0
89907.02	0.05784652	0
89911.02	0.05766224	0
89915.02	0.0574686	0
89919.02	0.05727412	0
89923.02	0.05708892	0
89927.02	0.05690359	0
89931.02	0.05672151	0
89935.02	0.05653509	0
89939.02	0.05635238	0
89943.02	0.05616639	0
89947.02	0.05598948	0
89951.02	0.05580262	0
89955.02	0.0556386	0
89959.02	0.05544398	0
89963.02	0.05526873	0
89967.02	0.05507763	0
89971.02	0.05490337	0
89975.02	0.05472887	0
89979.02	0.05457207	0
89983.02	0.0544097	0
89987.02	0.05423469	0
89991.02	0.05407145	0
89995.02	0.05391672	0
89999.02	0.05376124	0
90003.02	0.05360656	0
90007.02	0.05344305	0
90011.02	0.05328291	0
90015.02	0.05312055	0
90019.02	0.05295881	0
90023.02	0.05279512	0
90027.02	0.05264359	0
90031.02	0.05249529	0
90035.02	0.05234532	0
90039.02	0.05220474	0
90043.02	0.05206142	0
90047.02	0.05192345	0
90051.02	0.0517874	0
90055.02	0.05164925	0
90059.02	0.05151238	0
90063.02	0.05137688	0
90067.02	0.0512408	0
90071.02	0.05110418	0
90075.02	0.0509733	0
90079.02	0.05086649	0
90083.02	0.05076107	0
90087.02	0.05062862	0
90091.02	0.05049084	0
90095.02	0.05036885	0
90099.02	0.05024804	0
90103.02	0.05013646	0
90107.02	0.05001507	0
90111.02	0.04990084	0
90115.02	0.04978091	0
90119.02	0.04964505	0
90123.02	0.04951822	0
90127.02	0.0493945	0
90131.02	0.04926449	0
90135.02	0.04914333	0
90139.02	0.04901832	0
90143.02	0.04889573	0
90147.02	0.04876805	0
90151.02	0.04864613	0
90155.02	0.04853179	0
90159.02	0.04841509	0
90163.02	0.04829145	0
90167.02	0.04816844	0
90171.02	0.04804361	0
90175.02	0.04789717	0
90179.02	0.04777945	0
90183.02	0.04768871	0
90187.02	0.04758681	0
90191.02	0.04747836	0
90195.02	0.04736434	0
90199.02	0.04725786	0
90203.02	0.04717064	0
90207.02	0.04707916	0
90211.02	0.04697724	0
90215.02	0.04687889	0
90219.02	0.04677858	0
90223.02	0.04668058	0
90227.02	0.0465793	0
90231.02	0.04647956	0
90235.02	0.04636114	0
90239.02	0.04626058	0
90243.02	0.04616597	0
90247.02	0.04607663	0
90251.02	0.0459901	0
90255.02	0.04589295	0
90259.02	0.04578988	0
90263.02	0.04568877	0
90267.02	0.04559842	0
90271.02	0.04550108	0
90275.02	0.04542068	0
90279.02	0.04533243	0
90283.02	0.04523516	0
90287.02	0.0451439	0
90291.02	0.04505784	0
90295.02	0.04496471	0
90299.02	0.04487306	0
90303.02	0.04477732	0
90307.02	0.04468651	0
90311.02	0.04459974	0
90315.02	0.04450638	0
90319.02	0.04441134	0
90323.02	0.04432719	0
90327.02	0.04423515	0
90331.02	0.04413434	0
90335.02	0.04404361	0
90339.02	0.04395727	0
90343.02	0.04386814	0
90347.02	0.04378132	0
90351.02	0.04369346	0
90355.02	0.04359626	0
90359.02	0.04351106	0
90363.02	0.04343168	0
90367.02	0.04334366	0
90371.02	0.04324999	0
90375.02	0.04316639	0
90379.02	0.04309179	0
90383.02	0.04301882	0
90387.02	0.04294171	0
90391.02	0.04286588	0
90395.02	0.04277979	0
90399.02	0.04267956	0
90403.02	0.04260718	0
90407.02	0.04252988	0
90411.02	0.04245459	0
90415.02	0.04238053	0
90419.02	0.04230493	0
90423.02	0.04222371	0
90427.02	0.04215715	0
90431.02	0.0420892	0
90435.02	0.04201897	0
90439.02	0.04193964	0
90443.02	0.0418631	0
90447.02	0.0417864	0
90451.02	0.0417195	0
90455.02	0.04164317	0
90459.02	0.0415676	0
90463.02	0.04149168	0
90467.02	0.04142061	0
90471.02	0.04135511	0
90475.02	0.04129293	0
90479.02	0.04122306	0
90483.02	0.04114922	0
90487.02	0.0410942	0
90491.02	0.04103521	0
90495.02	0.04096704	0
90499.02	0.04090317	0
90503.02	0.04082379	0
90507.02	0.04074815	0
90511.02	0.04067062	0
90515.02	0.04061364	0
90519.02	0.04054217	0
90523.02	0.04048213	0
90527.02	0.0404127	0
90531.02	0.04033228	0
90535.02	0.04026768	0
90539.02	0.04020061	0
90543.02	0.04013543	0
90547.02	0.04007922	0
90551.02	0.04003003	0
90555.02	0.03997551	0
90559.02	0.03990494	0
90563.02	0.03983491	0
90567.02	0.03977563	0
90571.02	0.03971817	0
90575.02	0.03966186	0
90579.02	0.03960532	0
90583.02	0.03954931	0
90587.02	0.03948012	0
90591.02	0.03941371	0
90595.02	0.03934991	0
90599.02	0.03928624	0
90603.02	0.03923113	0
90607.02	0.03918066	0
90611.02	0.03911911	0
90615.02	0.03906513	0
90619.02	0.0390163	0
90623.02	0.0389538	0
90627.02	0.0388909	0
90631.02	0.03883164	0
90635.02	0.03876896	0
90639.02	0.03870336	0
90643.02	0.03864639	0
90647.02	0.0385894	0
90651.02	0.038535	0
90655.02	0.03847796	0
90659.02	0.03842915	0
90663.02	0.03838563	0
90667.02	0.03834481	0
90671.02	0.03828412	0
90675.02	0.03822405	0
90679.02	0.0381732	0
90683.02	0.03812043	0
90687.02	0.03806391	0
90691.02	0.03801123	0
90695.02	0.03794912	0
90699.02	0.03787736	0
90703.02	0.0378128	0
90707.02	0.03776538	0
90711.02	0.03770187	0
90715.02	0.03764511	0
90719.02	0.0375885	0
90723.02	0.03753603	0
90727.02	0.03748291	0
90731.02	0.03743639	0
90735.02	0.03738528	0
90739.02	0.03733313	0
90743.02	0.03728578	0
90747.02	0.0372401	0
90751.02	0.03718615	0
90755.02	0.03712759	0
90759.02	0.037076	0
90763.02	0.03703089	0
90767.02	0.03699303	0
90771.02	0.03694664	0
90775.02	0.03688981	0
90779.02	0.03683624	0
90783.02	0.03677087	0
90787.02	0.03671596	0
90791.02	0.03668713	0
90795.02	0.03665575	0
90799.02	0.03661621	0
90803.02	0.03656974	0
90807.02	0.03652376	0
90811.02	0.03647472	0
90815.02	0.03642111	0
90819.02	0.03638015	0
90823.02	0.03633873	0
90827.02	0.03629203	0
90831.02	0.0362533	0
90835.02	0.03621084	0
90839.02	0.03617607	0
90843.02	0.03612932	0
90847.02	0.03608693	0
90851.02	0.03605203	0
90855.02	0.03601872	0
90859.02	0.0359696	0
90863.02	0.03593226	0
90867.02	0.03589327	0
90871.02	0.03585332	0
90875.02	0.03581344	0
90879.02	0.03578131	0
90883.02	0.03574237	0
90887.02	0.03570461	0
90891.02	0.03566898	0
90895.02	0.0356145	0
90899.02	0.03555657	0
90903.02	0.03549825	0
90907.02	0.03544592	0
90911.02	0.0353943	0
90915.02	0.03533777	0
90919.02	0.03529276	0
90923.02	0.03523764	0
90927.02	0.03519571	0
90931.02	0.03514614	0
90935.02	0.03509688	0
90939.02	0.03505093	0
90943.02	0.03500275	0
90947.02	0.0349623	0
90951.02	0.03492769	0
90955.02	0.03487996	0
90959.02	0.03483921	0
90963.02	0.03479879	0
90967.02	0.03476867	0
90971.02	0.03472779	0
90975.02	0.03468683	0
90979.02	0.03463276	0
90983.02	0.03458844	0
90987.02	0.03454642	0
90991.02	0.03451157	0
90995.02	0.03447934	0
90999.02	0.03444866	0
91003.02	0.03440767	0
91007.02	0.03436304	0
91011.02	0.03433332	0
91015.02	0.03430185	0
91019.02	0.03425586	0
91023.02	0.03422647	0
91027.02	0.03417671	0
91031.02	0.03412604	0
91035.02	0.03409703	0
91039.02	0.03407299	0
91043.02	0.03402104	0
91047.02	0.03396322	0
91051.02	0.03393018	0
91055.02	0.03391095	0
91059.02	0.03387575	0
91063.02	0.03383511	0
91067.02	0.03378051	0
91071.02	0.03373964	0
91075.02	0.0336884	0
91079.02	0.03365869	0
91083.02	0.03362763	0
91087.02	0.03359537	0
91091.02	0.03356364	0
91095.02	0.03352091	0
91099.02	0.03347767	0
91103.02	0.03343954	0
91107.02	0.03340969	0
91111.02	0.03338353	0
91115.02	0.03335031	0
91119.02	0.03331141	0
91123.02	0.03328022	0
91127.02	0.03325174	0
91131.02	0.03320292	0
91135.02	0.03316854	0
91139.02	0.03314097	0
91143.02	0.03310728	0
91147.02	0.03307178	0
91151.02	0.03302692	0
91155.02	0.03299029	0
91159.02	0.03294634	0
91163.02	0.03290942	0
91167.02	0.03288733	0
91171.02	0.03287498	0
91175.02	0.0328452	0
91179.02	0.03281452	0
91183.02	0.03278141	0
91187.02	0.03275308	0
91191.02	0.03272811	0
91195.02	0.0326914	0
91199.02	0.03266061	0
91203.02	0.03263288	0
91207.02	0.03260313	0
91211.02	0.0325782	0
91215.02	0.03253839	0
91219.02	0.03250806	0
91223.02	0.03246307	0
91227.02	0.03241539	0
91231.02	0.03236466	0
91235.02	0.03233059	0
91239.02	0.03229514	0
91243.02	0.03226671	0
91247.02	0.03224551	0
91251.02	0.03221916	0
91255.02	0.03219578	0
91259.02	0.03216617	0
91263.02	0.03214455	0
91267.02	0.03212576	0
91271.02	0.03208902	0
91275.02	0.0320563	0
91279.02	0.0320282	0
91283.02	0.03200669	0
91287.02	0.03197901	0
91291.02	0.03194622	0
91295.02	0.03192112	0
91299.02	0.03188594	0
91303.02	0.03185205	0
91307.02	0.03182492	0
91311.02	0.03179835	0
91315.02	0.03177603	0
91319.02	0.0317397	0
91323.02	0.03170864	0
91327.02	0.03168045	0
91331.02	0.03165177	0
91335.02	0.03162792	0
91339.02	0.03159297	0
91343.02	0.03155942	0
91347.02	0.03153174	0
91351.02	0.03150171	0
91355.02	0.03147469	0
91359.02	0.03144355	0
91363.02	0.0314163	0
91367.02	0.0313753	0
91371.02	0.03134148	0
91375.02	0.031315	0
91379.02	0.03129005	0
91383.02	0.03126512	0
91387.02	0.03123573	0
91391.02	0.03121234	0
91395.02	0.03117112	0
91399.02	0.03113609	0
91403.02	0.03109851	0
91407.02	0.03107816	0
91411.02	0.03105246	0
91415.02	0.03103752	0
91419.02	0.03100595	0
91423.02	0.0309777	0
91427.02	0.0309514	0
91431.02	0.03093269	0
91435.02	0.03091078	0
91439.02	0.03088928	0
91443.02	0.03085966	0
91447.02	0.03082354	0
91451.02	0.03078121	0
91455.02	0.03075022	0
91459.02	0.0307224	0
91463.02	0.03070424	0
91467.02	0.03066983	0
91471.02	0.03064151	0
91475.02	0.03061713	0
91479.02	0.0305937	0
91483.02	0.03057096	0
91487.02	0.03054342	0
91491.02	0.03052259	0
91495.02	0.03050636	0
91499.02	0.03047659	0
91503.02	0.03045516	0
91507.02	0.03042907	0
91511.02	0.03040013	0
91515.02	0.03035994	0
91519.02	0.03033746	0
91523.02	0.03032092	0
91527.02	0.0302986	0
91531.02	0.03027737	0
91535.02	0.03025041	0
91539.02	0.03022374	0
91543.02	0.03020551	0
91547.02	0.03018039	0
91551.02	0.03015571	0
91555.02	0.030135	0
91559.02	0.03010857	0
91563.02	0.03008629	0
91567.02	0.03006612	0
91571.02	0.03005523	0
91575.02	0.03003528	0
91579.02	0.0300161	0
91583.02	0.02999765	0
91587.02	0.02997927	0
91591.02	0.02996414	0
91595.02	0.02994594	0
91599.02	0.02991854	0
91603.02	0.02990354	0
91607.02	0.02987276	0
91611.02	0.02985745	0
91615.02	0.02982539	0
91619.02	0.02980011	0
91623.02	0.02975361	0
91627.02	0.02971314	0
91631.02	0.02969831	0
91635.02	0.02968752	0
91639.02	0.02965509	0
91643.02	0.02963624	0
91647.02	0.02961119	0
91651.02	0.02959593	0
91655.02	0.02956542	0
91659.02	0.02952769	0
91663.02	0.02949681	0
91667.02	0.02947168	0
91671.02	0.02944508	0
91675.02	0.0294273	0
91679.02	0.02940132	0
91683.02	0.02939035	0
91687.02	0.02937512	0
91691.02	0.02934967	0
91695.02	0.0293125	0
91699.02	0.02927741	0
91703.02	0.02925345	0
91707.02	0.02922231	0
91711.02	0.02920895	0
91715.02	0.02917179	0
91719.02	0.0291425	0
91723.02	0.02912922	0
91727.02	0.02912951	0
91731.02	0.02910156	0
91735.02	0.02906871	0
91739.02	0.02904384	0
91743.02	0.02902039	0
91747.02	0.02899859	0
91751.02	0.02896847	0
91755.02	0.02894807	0
91759.02	0.028928	0
91763.02	0.02891131	0
91767.02	0.0288862	0
91771.02	0.02885589	0
91775.02	0.02883134	0
91779.02	0.02881571	0
91783.02	0.02877988	0
91787.02	0.02875267	0
91791.02	0.02873697	0
91795.02	0.02869588	0
91799.02	0.02868681	0
91803.02	0.02867007	0
91807.02	0.02865523	0
91811.02	0.0286405	0
91815.02	0.0286243	0
91819.02	0.02861762	0
91823.02	0.02859525	0
91827.02	0.02856116	0
91831.02	0.02853512	0
91835.02	0.02850479	0
91839.02	0.02847123	0
91843.02	0.02845046	0
91847.02	0.02842118	0
91851.02	0.02839463	0
91855.02	0.02837706	0
91859.02	0.02835804	0
91863.02	0.02834143	0
91867.02	0.02831415	0
91871.02	0.02830243	0
91875.02	0.02829144	0
91879.02	0.02825894	0
91883.02	0.02823155	0
91887.02	0.02821368	0
91891.02	0.02819438	0
91895.02	0.02815728	0
91899.02	0.02813142	0
91903.02	0.02811308	0
91907.02	0.02808326	0
91911.02	0.02806498	0
91915.02	0.02804413	0
91919.02	0.02800937	0
91923.02	0.02801175	0
91927.02	0.02801205	0
91931.02	0.02800178	0
91935.02	0.02800002	0
91939.02	0.02798277	0
91943.02	0.02796811	0
91947.02	0.02795362	0
91951.02	0.02792108	0
91955.02	0.02788949	0
91959.02	0.02788443	0
91963.02	0.02786807	0
91967.02	0.02785209	0
91971.02	0.0278239	0
91975.02	0.02779821	0
91979.02	0.02778716	0
91983.02	0.02777583	0
91987.02	0.02777065	0
91991.02	0.02776753	0
91995.02	0.02774861	0
91999.02	0.02774322	0
92003.02	0.02773821	0
92007.02	0.02772877	0
92011.02	0.02771383	0
92015.02	0.0277035	0
92019.02	0.02768923	0
92023.02	0.02767183	0
92027.02	0.0276652	0
92031.02	0.02764711	0
92035.02	0.02761254	0
92039.02	0.02760293	0
92043.02	0.02758882	0
92047.02	0.0275722	0
92051.02	0.02755426	0
92055.02	0.02754121	0
92059.02	0.02753218	0
92063.02	0.02752109	0
92067.02	0.02750363	0
92071.02	0.02748303	0
92075.02	0.027468	0
92079.02	0.02745386	0
92083.02	0.02743715	0
92087.02	0.02741437	0
92091.02	0.02738768	0
92095.02	0.02736956	0
92099.02	0.02735071	0
92103.02	0.02733705	0
92107.02	0.02731335	0
92111.02	0.02729728	0
92115.02	0.02728218	0
92119.02	0.0272685	0
92123.02	0.02724369	0
92127.02	0.02721894	0
92131.02	0.02719522	0
92135.02	0.02717931	0
92139.02	0.02716498	0
92143.02	0.02715142	0
92147.02	0.02713785	0
92151.02	0.02712709	0
92155.02	0.02711093	0
92159.02	0.02708489	0
92163.02	0.02706354	0
92167.02	0.02704544	0
92171.02	0.02703707	0
92175.02	0.02702285	0
92179.02	0.02701148	0
92183.02	0.02700526	0
92187.02	0.02699924	0
92191.02	0.02697719	0
92195.02	0.02695396	0
92199.02	0.02692288	0
92203.02	0.0269144	0
92207.02	0.02690022	0
92211.02	0.02686184	0
92215.02	0.02683479	0
92219.02	0.0268273	0
92223.02	0.02681	0
92227.02	0.02680225	0
92231.02	0.02678983	0
92235.02	0.02676686	0
92239.02	0.02674996	0
92243.02	0.0267365	0
92247.02	0.02673813	0
92251.02	0.02672403	0
92255.02	0.02670597	0
92259.02	0.02667593	0
92263.02	0.02666673	0
92267.02	0.02665447	0
92271.02	0.02664164	0
92275.02	0.02662795	0
92279.02	0.02661706	0
92283.02	0.02659434	0
92287.02	0.02657877	0
92291.02	0.02656476	0
92295.02	0.02655365	0
92299.02	0.02653242	0
92303.02	0.02650838	0
92307.02	0.02648066	0
92311.02	0.02645662	0
92315.02	0.02644142	0
92319.02	0.02643241	0
92323.02	0.02641274	0
92327.02	0.02639026	0
92331.02	0.02637785	0
92335.02	0.0263679	0
92339.02	0.02635207	0
92343.02	0.02633793	0
92347.02	0.02631557	0
92351.02	0.02629505	0
92355.02	0.02627551	0
92359.02	0.02626173	0
92363.02	0.0262458	0
92367.02	0.02621851	0
92371.02	0.02619319	0
92375.02	0.02617942	0
92379.02	0.02616981	0
92383.02	0.02614538	0
92387.02	0.02614827	0
92391.02	0.02613863	0
92395.02	0.02612671	0
92399.02	0.02611646	0
92403.02	0.02610788	0
92407.02	0.02609539	0
92411.02	0.02608248	0
92415.02	0.02606267	0
92419.02	0.0260411	0
92423.02	0.02602301	0
92427.02	0.02599759	0
92431.02	0.02598051	0
92435.02	0.02595879	0
92439.02	0.02595235	0
92443.02	0.02593907	0
92447.02	0.02593635	0
92451.02	0.02593179	0
92455.02	0.02592502	0
92459.02	0.02591343	0
92463.02	0.02589834	0
92467.02	0.02588838	0
92471.02	0.02586466	0
92475.02	0.02584929	0
92479.02	0.02583455	0
92483.02	0.02582996	0
92487.02	0.0258225	0
92491.02	0.02580052	0
92495.02	0.02576478	0
92499.02	0.02574368	0
92503.02	0.02572438	0
92507.02	0.02571529	0
92511.02	0.0257099	0
92515.02	0.02569638	0
92519.02	0.02567652	0
92523.02	0.02563894	0
92527.02	0.02562098	0
92531.02	0.02559398	0
92535.02	0.02557512	0
92539.02	0.02556897	0
92543.02	0.02554716	0
92547.02	0.02552059	0
92551.02	0.02551395	0
92555.02	0.02549921	0
92559.02	0.02548003	0
92563.02	0.02545723	0
92567.02	0.02544094	0
92571.02	0.02543717	0
92575.02	0.02542537	0
92579.02	0.02540361	0
92583.02	0.025404	0
92587.02	0.0254001	0
92591.02	0.02538429	0
92595.02	0.02535997	0
92599.02	0.02533845	0
92603.02	0.02531453	0
92607.02	0.02530112	0
92611.02	0.02530264	0
92615.02	0.02529952	0
92619.02	0.02527093	0
92623.02	0.02524217	0
92627.02	0.02522842	0
92631.02	0.02522119	0
92635.02	0.02520744	0
92639.02	0.02519194	0
92643.02	0.02518195	0
92647.02	0.02516634	0
92651.02	0.02514871	0
92655.02	0.02513596	0
92659.02	0.02512781	0
92663.02	0.0251084	0
92667.02	0.02509503	0
92671.02	0.02509285	0
92675.02	0.02508513	0
92679.02	0.02506655	0
92683.02	0.02505357	0
92687.02	0.02505615	0
92691.02	0.02503912	0
92695.02	0.02502458	0
92699.02	0.02501305	0
92703.02	0.02502108	0
92707.02	0.02500942	0
92711.02	0.02498572	0
92715.02	0.02497843	0
92719.02	0.02495463	0
92723.02	0.02493252	0
92727.02	0.02492227	0
92731.02	0.02492559	0
92735.02	0.02491088	0
92739.02	0.02489389	0
92743.02	0.02488863	0
92747.02	0.02489126	0
92751.02	0.02488243	0
92755.02	0.02484794	0
92759.02	0.02486014	0
92763.02	0.02484308	0
92767.02	0.02482142	0
92771.02	0.02480298	0
92775.02	0.02479189	0
92779.02	0.02479046	0
92783.02	0.02477639	0
92787.02	0.02475652	0
92791.02	0.02475888	0
92795.02	0.0247485	0
92799.02	0.02474497	0
92803.02	0.02471275	0
92807.02	0.02469926	0
92811.02	0.0246797	0
92815.02	0.02466839	0
92819.02	0.02467119	0
92823.02	0.0246585	0
92827.02	0.02463752	0
92831.02	0.02461718	0
92835.02	0.02462323	0
92839.02	0.02461658	0
92843.02	0.02458749	0
92847.02	0.02456754	0
92851.02	0.02456578	0
92855.02	0.02455639	0
92859.02	0.02454165	0
92863.02	0.02454343	0
92867.02	0.02451412	0
92871.02	0.02448932	0
92875.02	0.02448517	0
92879.02	0.02447168	0
92883.02	0.02446167	0
92887.02	0.02446381	0
92891.02	0.02445678	0
92895.02	0.02445525	0
92899.02	0.02444181	0
92903.02	0.02442905	0
92907.02	0.02442222	0
92911.02	0.02441555	0
92915.02	0.02440735	0
92919.02	0.02441369	0
92923.02	0.02440455	0
92927.02	0.02438469	0
92931.02	0.02438141	0
92935.02	0.02437629	0
92939.02	0.02434431	0
92943.02	0.02433705	0
92947.02	0.02431905	0
92951.02	0.02432053	0
92955.02	0.02430065	0
92959.02	0.02428561	0
92963.02	0.02427087	0
92967.02	0.02425742	0
92971.02	0.02425509	0
92975.02	0.02423745	0
92979.02	0.02422688	0
92983.02	0.02421075	0
92987.02	0.02419128	0
92991.02	0.02418676	0
92995.02	0.02416579	0
92999.02	0.02416582	0
93003.02	0.02415003	0
93007.02	0.02412292	0
93011.02	0.02410686	0
93015.02	0.02408888	0
93019.02	0.0240759	0
93023.02	0.02407996	0
93027.02	0.02408011	0
93031.02	0.02405861	0
93035.02	0.02405797	0
93039.02	0.0240348	0
93043.02	0.024016	0
93047.02	0.02400036	0
93051.02	0.02399077	0
93055.02	0.02398534	0
93059.02	0.02396608	0
93063.02	0.02396173	0
93067.02	0.02394347	0
93071.02	0.02393158	0
93075.02	0.02391659	0
93079.02	0.02390752	0
93083.02	0.02389745	0
93087.02	0.02389324	0
93091.02	0.02387847	0
93095.02	0.02388643	0
93099.02	0.02386195	0
93103.02	0.02383904	0
93107.02	0.02382902	0
93111.02	0.02380963	0
93115.02	0.02380875	0
93119.02	0.02380071	0
93123.02	0.02380446	0
93127.02	0.02379969	0
93131.02	0.02378843	0
93135.02	0.02377709	0
93139.02	0.02378788	0
93143.02	0.02377744	0
93147.02	0.02377249	0
93151.02	0.0237612	0
93155.02	0.02376524	0
93159.02	0.02373847	0
93163.02	0.02372695	0
93167.02	0.0237351	0
93171.02	0.02372061	0
93175.02	0.02368927	0
93179.02	0.02367258	0
93183.02	0.02366468	0
93187.02	0.02366459	0
93191.02	0.02365057	0
93195.02	0.02363887	0
93199.02	0.02361484	0
93203.02	0.02362158	0
93207.02	0.02360529	0
93211.02	0.02361118	0
93215.02	0.02359133	0
93219.02	0.02356951	0
93223.02	0.02355004	0
93227.02	0.02356179	0
93231.02	0.02356408	0
93235.02	0.02355164	0
93239.02	0.02354814	0
93243.02	0.02355007	0
93247.02	0.02354439	0
93251.02	0.02354399	0
93255.02	0.02352788	0
93259.02	0.02350713	0
93263.02	0.02348517	0
93267.02	0.02346565	0
93271.02	0.02346936	0
93275.02	0.02346474	0
93279.02	0.02346314	0
93283.02	0.02345836	0
93287.02	0.02345178	0
93291.02	0.02344697	0
93295.02	0.02345296	0
93299.02	0.02344906	0
93303.02	0.02344126	0
93307.02	0.02341993	0
93311.02	0.02340585	0
93315.02	0.02338877	0
93319.02	0.0233751	0
93323.02	0.02336229	0
93327.02	0.02336082	0
93331.02	0.02335626	0
93335.02	0.02336362	0
93339.02	0.02337057	0
93343.02	0.02336269	0
93347.02	0.02335395	0
93351.02	0.02335914	0
93355.02	0.02334586	0
93359.02	0.02334778	0
93363.02	0.0233214	0
93367.02	0.02331248	0
93371.02	0.02330644	0
93375.02	0.02330477	0
93379.02	0.02329003	0
93383.02	0.02327123	0
93387.02	0.02325818	0
93391.02	0.02326217	0
93395.02	0.02324901	0
93399.02	0.02322918	0
93403.02	0.02321507	0
93407.02	0.02318829	0
93411.02	0.02319789	0
93415.02	0.02318495	0
93419.02	0.0231733	0
93423.02	0.02316882	0
93427.02	0.02316255	0
93431.02	0.02316672	0
93435.02	0.02315913	0
93439.02	0.02315346	0
93443.02	0.02313984	0
93447.02	0.02312491	0
93451.02	0.02312623	0
93455.02	0.02312874	0
93459.02	0.02312733	0
93463.02	0.02311451	0
93467.02	0.02312093	0
93471.02	0.02311089	0
93475.02	0.02310873	0
93479.02	0.02310802	0
93483.02	0.02309388	0
93487.02	0.02306732	0
93491.02	0.02303773	0
93495.02	0.02302934	0
93499.02	0.02303058	0
93503.02	0.02301872	0
93507.02	0.02300935	0
93511.02	0.02299502	0
93515.02	0.02299537	0
93519.02	0.02298755	0
93523.02	0.02296769	0
93527.02	0.02295623	0
93531.02	0.02294591	0
93535.02	0.02291328	0
93539.02	0.02290514	0
93543.02	0.02291564	0
93547.02	0.0229052	0
93551.02	0.02289652	0
93555.02	0.02289886	0
93559.02	0.02287572	0
93563.02	0.02285713	0
93567.02	0.02285458	0
93571.02	0.02285731	0
93575.02	0.02285021	0
93579.02	0.02284822	0
93583.02	0.02284638	0
93587.02	0.02284229	0
93591.02	0.02283953	0
93595.02	0.02284273	0
93599.02	0.02282658	0
93603.02	0.02282147	0
93607.02	0.02281472	0
93611.02	0.02281162	0
93615.02	0.02280449	0
93619.02	0.02280373	0
93623.02	0.02279014	0
93627.02	0.02278709	0
93631.02	0.02277992	0
93635.02	0.0227786	0
93639.02	0.0227567	0
93643.02	0.02273643	0
93647.02	0.02271619	0
93651.02	0.02268433	0
93655.02	0.0226767	0
93659.02	0.02265749	0
93663.02	0.02265498	0
93667.02	0.02264492	0
93671.02	0.02263208	0
93675.02	0.02262054	0
93679.02	0.02260075	0
93683.02	0.02259123	0
93687.02	0.02257697	0
93691.02	0.02257135	0
93695.02	0.02255422	0
93699.02	0.02254962	0
93703.02	0.02252908	0
93707.02	0.02252978	0
93711.02	0.02251491	0
93715.02	0.02250848	0
93719.02	0.02249063	0
93723.02	0.02249102	0
93727.02	0.02247849	0
93731.02	0.02245526	0
93735.02	0.02245018	0
93739.02	0.02244324	0
93743.02	0.02244311	0
93747.02	0.02244386	0
93751.02	0.02242797	0
93755.02	0.02240165	0
93759.02	0.02239377	0
93763.02	0.02238455	0
93767.02	0.02237526	0
93771.02	0.02236533	0
93775.02	0.02233967	0
93779.02	0.02232883	0
93783.02	0.02233094	0
93787.02	0.02232699	0
93791.02	0.02231972	0
93795.02	0.022322	0
93799.02	0.02231299	0
93803.02	0.02228882	0
93807.02	0.02227754	0
93811.02	0.02228373	0
93815.02	0.02228839	0
93819.02	0.02228004	0
93823.02	0.02227689	0
93827.02	0.02228196	0
93831.02	0.02224609	0
93835.02	0.02223751	0
93839.02	0.02223921	0
93843.02	0.02224195	0
93847.02	0.02221828	0
93851.02	0.02221702	0
93855.02	0.02220193	0
93859.02	0.02219744	0
93863.02	0.02219196	0
93867.02	0.02219062	0
93871.02	0.02217184	0
93875.02	0.02216048	0
93879.02	0.02214605	0
93883.02	0.02214206	0
93887.02	0.02212671	0
93891.02	0.02212168	0
93895.02	0.0221251	0
93899.02	0.02211729	0
93903.02	0.02211347	0
93907.02	0.02210243	0
93911.02	0.02209465	0
93915.02	0.02207523	0
93919.02	0.02205934	0
93923.02	0.02205516	0
93927.02	0.02203822	0
93931.02	0.02204775	0
93935.02	0.02204504	0
93939.02	0.0220368	0
93943.02	0.02203082	0
93947.02	0.02202235	0
93951.02	0.022004	0
93955.02	0.0219909	0
93959.02	0.02197901	0
93963.02	0.02196851	0
93967.02	0.02196503	0
93971.02	0.02195765	0
93975.02	0.02194639	0
93979.02	0.02195012	0
93983.02	0.02194311	0
93987.02	0.02193903	0
93991.02	0.02192923	0
93995.02	0.02192134	0
93999.02	0.02191764	0
94003.02	0.02192172	0
94007.02	0.02191955	0
94011.02	0.02191896	0
94015.02	0.02191126	0
94019.02	0.02190368	0
94023.02	0.02190852	0
94027.02	0.02191529	0
94031.02	0.02191373	0
94035.02	0.02191449	0
94039.02	0.0218833	0
94043.02	0.02188806	0
94047.02	0.02187435	0
94051.02	0.02186885	0
94055.02	0.02185615	0
94059.02	0.02184388	0
94063.02	0.02182362	0
94067.02	0.0218216	0
94071.02	0.02183528	0
94075.02	0.0218227	0
94079.02	0.0217971	0
94083.02	0.02181898	0
94087.02	0.02181937	0
94091.02	0.02180929	0
94095.02	0.02179749	0
94099.02	0.02176702	0
94103.02	0.02177368	0
94107.02	0.02179017	0
94111.02	0.02177575	0
94115.02	0.02177569	0
94119.02	0.02177825	0
94123.02	0.02178201	0
94127.02	0.02177823	0
94131.02	0.02175548	0
94135.02	0.02174728	0
94139.02	0.02174871	0
94143.02	0.02173119	0
94147.02	0.02173216	0
94151.02	0.02173254	0
94155.02	0.02171657	0
94159.02	0.02169966	0
94163.02	0.02168511	0
94167.02	0.02166624	0
94171.02	0.02167664	0
94175.02	0.02166327	0
94179.02	0.02166188	0
94183.02	0.02166716	0
94187.02	0.02164776	0
94191.02	0.02164549	0
94195.02	0.02164382	0
94199.02	0.02163877	0
94203.02	0.02164413	0
94207.02	0.02162253	0
94211.02	0.02164313	0
94215.02	0.02163125	0
94219.02	0.02162266	0
94223.02	0.02161108	0
94227.02	0.02160777	0
94231.02	0.02159986	0
94235.02	0.02159627	0
94239.02	0.02159414	0
94243.02	0.0215808	0
94247.02	0.02156638	0
94251.02	0.02154149	0
94255.02	0.02153311	0
94259.02	0.02153702	0
94263.02	0.02153882	0
94267.02	0.02154839	0
94271.02	0.02155248	0
94275.02	0.02155864	0
94279.02	0.02154774	0
94283.02	0.02153943	0
94287.02	0.02154289	0
94291.02	0.02153386	0
94295.02	0.02153071	0
94299.02	0.02152748	0
94303.02	0.02151465	0
94307.02	0.02151928	0
94311.02	0.02153594	0
94315.02	0.02152529	0
94319.02	0.02151972	0
94323.02	0.02150012	0
94327.02	0.02150583	0
94331.02	0.02149857	0
94335.02	0.02150208	0
94339.02	0.02148581	0
94343.02	0.02147601	0
94347.02	0.02145676	0
94351.02	0.02144801	0
94355.02	0.02142216	0
94359.02	0.02143824	0
94363.02	0.02142892	0
94367.02	0.02141202	0
94371.02	0.02139544	0
94375.02	0.02138312	0
94379.02	0.02137773	0
94383.02	0.02137315	0
94387.02	0.02136036	0
94391.02	0.02134035	0
94395.02	0.02132505	0
94399.02	0.02131842	0
94403.02	0.0213143	0
94407.02	0.02131407	0
94411.02	0.02130278	0
94415.02	0.02128571	0
94419.02	0.02129919	0
94423.02	0.02127625	0
94427.02	0.02126586	0
94431.02	0.02125193	0
94435.02	0.02124785	0
94439.02	0.02123795	0
94443.02	0.02124953	0
94447.02	0.02124202	0
94451.02	0.0212293	0
94455.02	0.02121287	0
94459.02	0.02120221	0
94463.02	0.02119382	0
94467.02	0.02119385	0
94471.02	0.02118672	0
94475.02	0.02116959	0
94479.02	0.02116563	0
94483.02	0.02115807	0
94487.02	0.02114517	0
94491.02	0.02112697	0
94495.02	0.02113056	0
94499.02	0.02113197	0
94503.02	0.02113905	0
94507.02	0.0211392	0
94511.02	0.02113792	0
94515.02	0.02113004	0
94519.02	0.02111451	0
94523.02	0.02111119	0
94527.02	0.0210917	0
94531.02	0.02107954	0
94535.02	0.02108428	0
94539.02	0.02107247	0
94543.02	0.02107964	0
94547.02	0.02105997	0
94549.02	0.02105989	0