File: Y261_creep4.txt
Time	Strain	Shear Stress
[s]	[1]	[Pa]
88850.12	0.09833232	100
88850.51	0.1210635	100
88850.91	0.1290325	100
88851.31	0.1341804	100
88851.72	0.1380586	100
88852.12	0.1411496	100
88852.51	0.1437348	100
88852.91	0.1459586	100
88853.31	0.1479156	100
88853.72	0.1496753	100
88854.12	0.1512797	100
88854.51	0.1527366	100
88854.91	0.1540792	100
88855.31	0.1553336	100
88855.72	0.156517	100
88856.12	0.1576341	100
88856.51	0.1586882	100
88856.91	0.1596816	100
88857.31	0.1606246	100
88857.72	0.1615203	100
88858.12	0.1623714	100
88858.51	0.1631898	100
88858.91	0.1639766	100
88859.31	0.1647314	100
88859.72	0.1654597	100
88860.12	0.1661542	100
88860.51	0.1668255	100
88860.91	0.1674668	100
88861.31	0.1680904	100
88861.72	0.1686899	100
88862.12	0.1692713	100
88862.51	0.1698364	100
88862.91	0.1703858	100
88863.31	0.1709254	100
88863.72	0.1714473	100
88864.12	0.1719619	100
88864.51	0.1724604	100
88864.91	0.1729473	100
88865.31	0.1734202	100
88865.72	0.1738825	100
88866.12	0.1743305	100
88866.51	0.1747674	100
88866.91	0.1751937	100
88867.31	0.1756132	100
88867.72	0.1760188	100
88868.12	0.1764212	100
88868.51	0.1768201	100
88868.91	0.1772088	100
88869.31	0.1775921	100
88869.72	0.1779734	100
88870.12	0.1783455	100
88870.51	0.1787091	100
88870.91	0.1790731	100
88871.31	0.1794276	100
88871.72	0.1797789	100
88872.12	0.1801202	100
88872.51	0.1804558	100
88872.91	0.1807883	100
88873.31	0.1811141	100
88873.72	0.1814379	100
88874.12	0.1817534	100
88874.51	0.1820667	100
88874.91	0.1823727	100
88875.31	0.182676	100
88875.72	0.1829737	100
88876.12	0.1832676	100
88876.51	0.1835576	100
88876.91	0.1838487	100
88877.31	0.1841313	100
88877.72	0.1844137	100
88878.12	0.1846932	100
88878.51	0.1849669	100
88878.91	0.1852421	100
88879.31	0.1855089	100
88879.72	0.1857767	100
88880.12	0.1860403	100
88880.51	0.186308	100
88880.91	0.1865682	100
88881.31	0.1868232	100
88881.72	0.1870827	100
88882.12	0.1873374	100
88882.51	0.1875911	100
88882.91	0.1878429	100
88883.31	0.1880856	100
88883.72	0.1883294	100
88884.12	0.1885724	100
88884.51	0.1888102	100
88884.91	0.1890438	100
88885.31	0.1892735	100
88885.72	0.1895049	100
88886.12	0.1897339	100
88886.51	0.1899646	100
88886.91	0.19019	100
88887.31	0.1904136	100
88887.72	0.190633	100
88888.12	0.1908545	100
88888.51	0.1910717	100
88888.91	0.191285	100
88889.31	0.1914959	100
88889.72	0.1917067	100
88890.12	0.1919165	100
88890.51	0.1921244	100
88890.91	0.1923312	100
88891.31	0.1925352	100
88891.72	0.1927375	100
88892.12	0.1929385	100
88892.51	0.1931418	100
88892.91	0.1933391	100
88893.31	0.1935391	100
88893.72	0.1937356	100
88894.12	0.1939309	100
88894.51	0.1941234	100
88894.91	0.1943169	100
88895.31	0.1945071	100
88895.72	0.1946975	100
88896.12	0.1948873	100
88896.51	0.1950741	100
88896.91	0.1952612	100
88897.31	0.1954446	100
88897.72	0.1956273	100
88898.12	0.1958071	100
88898.51	0.1959889	100
88898.91	0.1961651	100
88899.31	0.196344	100
88899.72	0.1965198	100
88900.12	0.1966926	100
88900.51	0.1968653	100
88900.91	0.1970354	100
88901.31	0.1972031	100
88901.72	0.1973729	100
88902.12	0.1975389	100
88902.51	0.197705	100
88902.91	0.1978693	100
88903.31	0.1980328	100
88903.72	0.1981957	100
88904.12	0.1983589	100
88904.51	0.1985213	100
88904.91	0.1986799	100
88905.31	0.1988396	100
88905.72	0.1989965	100
88906.12	0.1991552	100
88906.51	0.1993128	100
88906.91	0.1994703	100
88907.31	0.199622	100
88907.72	0.1997787	100
88908.12	0.1999326	100
88908.51	0.2000842	100
88908.91	0.2002351	100
88909.31	0.2003874	100
88909.72	0.2005366	100
88910.12	0.2006828	100
88910.51	0.2008327	100
88910.91	0.2009788	100
88911.31	0.2011257	100
88911.72	0.2012715	100
88912.12	0.2014185	100
88912.51	0.20156	100
88912.91	0.201707	100
88913.31	0.2018482	100
88913.72	0.2019935	100
88914.12	0.2021362	100
88914.51	0.2022786	100
88914.91	0.2024189	100
88915.31	0.2025593	100
88915.72	0.202697	100
88916.12	0.2028343	100
88916.51	0.2029742	100
88916.91	0.2031112	100
88917.31	0.2032465	100
88917.72	0.2033814	100
88918.12	0.2035167	100
88918.51	0.2036494	100
88918.91	0.2037844	100
88919.31	0.2039149	100
88919.72	0.204047	100
88920.12	0.2041786	100
88920.51	0.2043035	100
88920.91	0.2044315	100
88921.31	0.2045606	100
88921.72	0.2046894	100
88922.12	0.2048164	100
88922.51	0.2049416	100
88922.91	0.2050663	100
88923.31	0.2051906	100
88923.72	0.205316	100
88924.12	0.2054393	100
88924.51	0.2055603	100
88924.91	0.2056804	100
88925.31	0.2058039	100
88925.72	0.2059277	100
88926.12	0.2060524	100
88926.51	0.2061708	100
88926.91	0.2062902	100
88927.31	0.2064092	100
88927.72	0.2065281	100
88928.12	0.206648	100
88928.51	0.2067672	100
88928.91	0.2068841	100
88929.31	0.2070015	100
88929.72	0.2071178	100
88930.12	0.207237	100
88930.51	0.2073559	100
88930.91	0.2074728	100
88931.31	0.2075868	100
88931.72	0.2076995	100
88932.12	0.2078118	100
88932.51	0.2079244	100
88932.91	0.2080396	100
88933.31	0.2081552	100
88933.72	0.208267	100
88934.12	0.2083807	100
88934.51	0.2084953	100
88934.91	0.2086113	100
88935.31	0.2087224	100
88935.72	0.2088338	100
88936.12	0.2089464	100
88936.51	0.2090607	100
88936.91	0.2091746	100
88937.31	0.2092827	100
88937.72	0.209394	100
88938.12	0.2095036	100
88938.51	0.2096136	100
88938.91	0.2097252	100
88939.31	0.2098341	100
88939.72	0.2099386	100
88940.12	0.2100507	100
88940.51	0.210157	100
88940.91	0.2102649	100
88941.31	0.2103699	100
88941.72	0.2104774	100
88942.12	0.2105803	100
88942.51	0.210689	100
88942.91	0.2107923	100
88943.31	0.2108955	100
88943.72	0.2109963	100
88944.12	0.2110992	100
88944.51	0.2112032	100
88944.91	0.211305	100
88945.31	0.2114082	100
88945.72	0.2115097	100
88946.12	0.2116111	100
88946.51	0.2117115	100
88946.91	0.2118129	100
88947.31	0.2119114	100
88947.72	0.2120124	100
88948.12	0.2121086	100
88948.51	0.2122092	100
88948.91	0.2123072	100
88949.31	0.2124058	100
88949.72	0.2125067	100
88950.12	0.2126064	100
88950.51	0.2127046	100
88950.91	0.2128027	100
88951.31	0.2128991	100
88951.72	0.2129985	100
88952.12	0.2131018	100
88952.51	0.2131989	100
88952.91	0.2132921	100
88953.31	0.2133829	100
88953.72	0.2134799	100
88954.12	0.2135718	100
88954.51	0.2136701	100
88954.91	0.2137621	100
88955.31	0.213859	100
88955.72	0.213953	100
88956.12	0.2140491	100
88956.51	0.2141423	100
88956.91	0.2142396	100
88957.31	0.2143332	100
88957.72	0.2144255	100
88958.12	0.2145166	100
88958.51	0.2146051	100
88958.91	0.2147007	100
88959.31	0.2147927	100
88959.72	0.2148906	100
88960.12	0.2149806	100
88960.51	0.2150743	100
88960.91	0.2151658	100
88961.31	0.2152564	100
88961.72	0.2153465	100
88962.12	0.2154387	100
88962.51	0.2155286	100
88962.91	0.2156165	100
88963.31	0.2157067	100
88963.72	0.2157939	100
88964.12	0.2158847	100
88964.51	0.2159739	100
88964.91	0.2160659	100
88965.31	0.2161512	100
88965.72	0.2162392	100
88966.12	0.2163278	100
88966.51	0.2164185	100
88966.91	0.2165108	100
88967.31	0.2166038	100
88967.72	0.2166948	100
88968.12	0.216785	100
88968.51	0.2168714	100
88968.91	0.2169628	100
88969.31	0.2170529	100
88969.72	0.2171397	100
88970.12	0.2172261	100
88970.51	0.2173146	100
88970.91	0.2173993	100
88971.31	0.2174851	100
88971.72	0.2175718	100
88972.12	0.2176542	100
88972.51	0.2177364	100
88972.91	0.2178187	100
88973.31	0.2179012	100
88973.72	0.2179808	100
88974.12	0.2180664	100
88974.51	0.2181504	100
88974.91	0.2182343	100
88975.31	0.2183154	100
88975.72	0.2184007	100
88976.12	0.2184834	100
88976.51	0.2185669	100
88976.91	0.2186487	100
88977.31	0.2187302	100
88977.72	0.2188127	100
88978.12	0.2188949	100
88978.51	0.2189776	100
88978.91	0.2190573	100
88979.31	0.2191392	100
88979.72	0.2192216	100
88980.12	0.2193064	100
88980.51	0.2193855	100
88980.91	0.2194661	100
88981.31	0.2195461	100
88981.72	0.219625	100
88982.12	0.2197046	100
88982.51	0.2197845	100
88982.91	0.2198637	100
88983.31	0.2199412	100
88983.72	0.220019	100
88984.12	0.2200944	100
88984.51	0.220171	100
88984.91	0.220245	100
88985.31	0.2203208	100
88985.72	0.2203969	100
88986.12	0.2204729	100
88986.51	0.2205481	100
88986.91	0.2206249	100
88987.31	0.2207004	100
88987.72	0.2207753	100
88988.12	0.2208519	100
88988.51	0.2209301	100
88988.91	0.2210066	100
88989.31	0.2210825	100
88989.72	0.2211546	100
88990.12	0.221231	100
88990.51	0.2213064	100
88990.91	0.2213826	100
88991.31	0.2214582	100
88991.72	0.2215335	100
88992.12	0.2216078	100
88992.51	0.2216843	100
88992.91	0.2217607	100
88993.31	0.2218354	100
88993.72	0.2219109	100
88994.12	0.2219853	100
88994.51	0.2220622	100
88994.91	0.2221368	100
88995.31	0.2222107	100
88995.72	0.2222869	100
88996.12	0.2223586	100
88996.51	0.222434	100
88996.91	0.2225053	100
88997.31	0.2225808	100
88997.72	0.2226539	100
88998.12	0.2227279	100
88998.51	0.2228042	100
88998.91	0.222875	100
88999.31	0.2229474	100
88999.72	0.2230201	100
89000.12	0.2230928	100
89000.51	0.2231652	100
89000.91	0.2232379	100
89001.31	0.2233091	100
89001.72	0.2233809	100
89002.12	0.223452	100
89002.51	0.2235269	100
89002.91	0.2235989	100
89003.31	0.2236712	100
89003.72	0.2237426	100
89004.12	0.2238146	100
89004.51	0.2238887	100
89004.91	0.2239592	100
89005.31	0.2240312	100
89005.72	0.2241027	100
89006.12	0.2241734	100
89006.51	0.2242434	100
89006.91	0.2243173	100
89007.31	0.2243867	100
89007.72	0.2244556	100
89008.12	0.2245246	100
89008.51	0.2245969	100
89008.91	0.2246671	100
89009.31	0.2247368	100
89009.72	0.2248066	100
89010.12	0.2248734	100
89010.51	0.2249424	100
89010.91	0.2250101	100
89011.31	0.225078	100
89011.72	0.2251459	100
89012.12	0.2252123	100
89012.51	0.2252776	100
89012.91	0.2253437	100
89013.31	0.2254083	100
89013.72	0.2254779	100
89014.12	0.2255438	100
89014.51	0.2256103	100
89014.91	0.2256739	100
89015.31	0.2257403	100
89015.72	0.2258068	100
89016.12	0.2258723	100
89016.51	0.2259372	100
89016.91	0.2259992	100
89017.31	0.2260618	100
89017.72	0.2261266	100
89018.12	0.2261897	100
89018.51	0.2262513	100
89018.91	0.2263118	100
89019.31	0.2263733	100
89019.72	0.2264358	100
89020.12	0.2264962	100
89020.51	0.2265621	100
89020.91	0.2266215	100
89021.31	0.2266848	100
89021.72	0.2267447	100
89022.12	0.2268083	100
89022.51	0.2268713	100
89022.91	0.2269353	100
89023.31	0.2269968	100
89023.72	0.2270609	100
89024.12	0.2271254	100
89024.51	0.2271896	100
89024.91	0.2272502	100
89025.31	0.2273167	100
89025.72	0.2273812	100
89026.12	0.2274447	100
89026.51	0.2275088	100
89026.91	0.2275707	100
89027.31	0.2276357	100
89027.72	0.2276966	100
89028.12	0.2277599	100
89028.51	0.227822	100
89028.91	0.2278848	100
89029.31	0.2279443	100
89029.72	0.2280076	100
89030.12	0.2280684	100
89030.51	0.2281315	100
89030.91	0.2281931	100
89031.31	0.2282554	100
89031.72	0.2283174	100
89032.12	0.2283777	100
89032.51	0.2284412	100
89032.91	0.2285004	100
89033.31	0.2285611	100
89033.73	0.2286211	100
89034.13	0.2286822	100
89034.52	0.2287408	100
89034.92	0.2288018	100
89035.33	0.2288603	100
89035.73	0.22892	100
89036.13	0.2289812	100
89036.52	0.22904	100
89036.92	0.2290995	100
89037.33	0.2291574	100
89037.73	0.2292162	100
89038.13	0.2292751	100
89038.52	0.2293324	100
89038.92	0.2293896	100
89039.33	0.2294514	100
89039.73	0.2295109	100
89040.13	0.2295669	100
89040.52	0.2296251	100
89040.92	0.2296851	100
89041.33	0.2297445	100
89041.73	0.2298029	100
89042.13	0.2298617	100
89042.52	0.2299181	100
89042.92	0.2299769	100
89043.33	0.2300343	100
89043.73	0.2300901	100
89044.13	0.2301463	100
89044.52	0.2302045	100
89044.92	0.2302631	100
89045.33	0.2303196	100
89045.73	0.230376	100
89046.13	0.2304311	100
89046.52	0.2304876	100
89046.92	0.2305445	100
89047.33	0.2306003	100
89047.73	0.2306564	100
89048.13	0.2307145	100
89048.52	0.2307691	100
89048.92	0.2308239	100
89049.33	0.2308792	100
89049.73	0.2309344	100
89050.13	0.2309928	100
89050.52	0.231049	100
89050.92	0.2311051	100
89051.33	0.2311604	100
89051.73	0.2312187	100
89052.13	0.2312767	100
89052.52	0.2313315	100
89052.92	0.2313886	100
89053.33	0.2314431	100
89053.73	0.231499	100
89054.13	0.2315566	100
89054.52	0.2316149	100
89054.92	0.2316703	100
89055.33	0.231728	100
89055.73	0.2317843	100
89056.13	0.2318414	100
89056.52	0.2318977	100
89056.92	0.2319541	100
89057.33	0.2320107	100
89057.73	0.2320679	100
89058.13	0.2321231	100
89058.52	0.2321787	100
89058.92	0.2322354	100
89059.33	0.2322928	100
89059.73	0.2323471	100
89060.13	0.2324059	100
89060.52	0.2324599	100
89060.92	0.232516	100
89061.33	0.2325693	100
89061.73	0.2326244	100
89062.13	0.2326784	100
89062.52	0.232734	100
89062.92	0.2327862	100
89063.33	0.2328402	100
89063.73	0.2328951	100
89064.13	0.232948	100
89064.52	0.2330029	100
89064.92	0.2330566	100
89065.33	0.2331126	100
89065.73	0.2331665	100
89066.13	0.23322	100
89066.52	0.2332747	100
89066.92	0.2333283	100
89067.33	0.2333843	100
89067.73	0.2334383	100
89068.13	0.2334915	100
89068.52	0.2335437	100
89068.92	0.2335948	100
89069.33	0.2336464	100
89069.73	0.2336981	100
89070.13	0.2337504	100
89070.52	0.2338029	100
89070.92	0.2338574	100
89071.33	0.2339115	100
89071.73	0.2339644	100
89072.13	0.2340148	100
89072.52	0.2340684	100
89072.92	0.2341213	100
89073.33	0.2341755	100
89073.73	0.2342279	100
89074.13	0.2342813	100
89074.52	0.2343339	100
89074.92	0.2343855	100
89075.33	0.2344373	100
89075.73	0.2344882	100
89076.13	0.2345412	100
89076.52	0.2345918	100
89076.92	0.2346429	100
89077.33	0.2346955	100
89077.73	0.2347474	100
89078.13	0.2348005	100
89078.52	0.2348489	100
89078.92	0.2348984	100
89079.33	0.2349498	100
89079.73	0.2350017	100
89080.13	0.2350511	100
89080.52	0.2351025	100
89080.92	0.2351548	100
89081.33	0.2352055	100
89081.73	0.2352547	100
89082.13	0.2353058	100
89082.52	0.2353561	100
89082.92	0.2354037	100
89083.33	0.2354563	100
89083.73	0.2355074	100
89084.13	0.2355623	100
89084.52	0.2356145	100
89084.92	0.2356684	100
89085.33	0.2357206	100
89085.73	0.2357711	100
89086.13	0.2358258	100
89086.52	0.2358761	100
89086.92	0.2359267	100
89087.33	0.235977	100
89087.73	0.2360267	100
89088.13	0.236077	100
89088.52	0.2361237	100
89088.92	0.2361732	100
89089.33	0.2362237	100
89089.73	0.2362739	100
89090.13	0.2363213	100
89090.52	0.2363689	100
89090.92	0.2364148	100
89091.33	0.2364631	100
89091.73	0.2365106	100
89092.13	0.2365575	100
89092.52	0.2366061	100
89092.92	0.2366529	100
89093.33	0.2367028	100
89093.73	0.2367479	100
89094.13	0.2367966	100
89094.52	0.2368461	100
89094.92	0.2368962	100
89095.33	0.2369465	100
89095.73	0.2369954	100
89096.13	0.2370458	100
89096.52	0.2370944	100
89096.92	0.2371435	100
89097.33	0.2371963	100
89097.73	0.2372463	100
89098.13	0.237293	100
89098.52	0.2373443	100
89098.92	0.2373932	100
89099.33	0.2374431	100
89099.73	0.2374919	100
89100.13	0.2375408	100
89100.52	0.2375895	100
89100.92	0.2376394	100
89101.33	0.2376912	100
89101.73	0.2377408	100
89102.13	0.2377909	100
89102.52	0.2378368	100
89102.92	0.2378875	100
89103.33	0.2379358	100
89103.73	0.2379833	100
89104.13	0.2380309	100
89104.52	0.2380764	100
89104.92	0.2381248	100
89105.33	0.2381717	100
89105.73	0.238221	100
89106.13	0.2382692	100
89106.52	0.2383186	100
89106.92	0.2383656	100
89107.33	0.2384156	100
89107.73	0.2384634	100
89108.13	0.2385115	100
89108.52	0.2385595	100
89108.92	0.2386057	100
89109.33	0.2386516	100
89109.73	0.2387014	100
89110.13	0.2387485	100
89110.52	0.2387966	100
89110.92	0.2388424	100
89111.33	0.2388868	100
89111.73	0.2389346	100
89112.13	0.2389822	100
89112.52	0.239027	100
89112.92	0.2390738	100
89113.33	0.2391176	100
89113.73	0.2391629	100
89114.13	0.2392083	100
89114.52	0.2392552	100
89114.92	0.2393025	100
89115.33	0.2393471	100
89115.73	0.2393915	100
89116.13	0.2394366	100
89116.52	0.2394825	100
89116.92	0.2395287	100
89117.33	0.2395751	100
89117.73	0.2396207	100
89118.13	0.2396681	100
89118.52	0.2397143	100
89118.92	0.2397603	100
89119.33	0.2398061	100
89119.73	0.239854	100
89120.13	0.2399002	100
89120.52	0.2399449	100
89120.92	0.2399925	100
89121.33	0.2400382	100
89121.73	0.240081	100
89122.13	0.2401296	100
89122.52	0.2401739	100
89122.92	0.2402223	100
89123.33	0.2402674	100
89123.73	0.2403149	100
89124.13	0.2403604	100
89124.52	0.2404059	100
89124.92	0.2404498	100
89125.33	0.2404942	100
89125.73	0.24054	100
89126.13	0.2405833	100
89126.52	0.2406288	100
89126.92	0.2406719	100
89127.33	0.2407162	100
89127.73	0.2407617	100
89128.13	0.240809	100
89128.52	0.2408554	100
89128.92	0.2408994	100
89129.33	0.2409429	100
89129.73	0.2409868	100
89130.13	0.2410305	100
89130.52	0.2410757	100
89130.92	0.2411213	100
89131.33	0.2411661	100
89131.73	0.241211	100
89132.13	0.2412544	100
89132.52	0.2412969	100
89132.92	0.2413424	100
89133.33	0.2413862	100
89133.73	0.2414345	100
89134.13	0.2414825	100
89134.52	0.241528	100
89134.92	0.2415716	100
89135.33	0.2416201	100
89135.73	0.2416618	100
89136.13	0.2417074	100
89136.52	0.2417536	100
89136.92	0.241797	100
89137.33	0.2418412	100
89137.73	0.2418841	100
89138.13	0.2419259	100
89138.52	0.2419721	100
89138.92	0.2420164	100
89139.33	0.2420615	100
89139.73	0.2421048	100
89140.13	0.2421484	100
89140.52	0.2421915	100
89140.92	0.2422344	100
89141.33	0.2422765	100
89141.73	0.2423206	100
89142.13	0.2423615	100
89142.52	0.2424044	100
89142.92	0.2424479	100
89143.33	0.2424901	100
89143.73	0.2425314	100
89144.13	0.242571	100
89144.52	0.2426151	100
89144.92	0.2426577	100
89145.33	0.2427047	100
89145.73	0.2427483	100
89146.13	0.2427906	100
89146.52	0.2428341	100
89146.92	0.2428752	100
89147.33	0.2429175	100
89147.73	0.2429619	100
89148.13	0.2430055	100
89148.52	0.2430504	100
89148.92	0.2430939	100
89149.33	0.2431375	100
89149.73	0.2431809	100
89150.13	0.2432248	100
89150.52	0.243265	100
89150.92	0.243308	100
89151.33	0.2433476	100
89151.73	0.2433927	100
89152.13	0.2434344	100
89152.52	0.2434749	100
89152.92	0.2435158	100
89153.33	0.2435597	100
89153.73	0.2436038	100
89154.13	0.2436434	100
89154.52	0.2436844	100
89154.92	0.2437237	100
89155.33	0.2437618	100
89155.73	0.2438043	100
89156.13	0.2438491	100
89156.52	0.2438892	100
89156.92	0.2439284	100
89157.33	0.2439695	100
89157.73	0.2440123	100
89158.13	0.2440544	100
89158.52	0.2440962	100
89158.92	0.2441376	100
89159.33	0.2441782	100
89159.73	0.2442195	100
89160.13	0.2442589	100
89160.52	0.244304	100
89160.92	0.2443501	100
89161.33	0.2443922	100
89161.73	0.2444409	100
89162.13	0.244482	100
89162.52	0.244522	100
89162.92	0.2445656	100
89163.33	0.2446101	100
89163.73	0.2446501	100
89164.13	0.2446936	100
89164.52	0.2447359	100
89164.92	0.2447787	100
89165.34	0.2448226	100
89165.73	0.2448626	100
89166.13	0.2449053	100
89166.53	0.2449451	100
89166.93	0.2449902	100
89167.34	0.2450316	100
89167.73	0.2450728	100
89168.13	0.2451085	100
89168.53	0.2451511	100
89168.93	0.2451902	100
89169.34	0.2452281	100
89169.73	0.2452683	100
89170.13	0.24531	100
89170.53	0.245351	100
89170.93	0.2453915	100
89171.34	0.245436	100
89171.73	0.2454764	100
89172.13	0.2455228	100
89172.53	0.2455614	100
89172.93	0.245603	100
89173.34	0.2456429	100
89173.73	0.2456866	100
89174.13	0.2457244	100
89174.53	0.2457626	100
89174.93	0.2458006	100
89175.34	0.2458416	100
89175.73	0.2458809	100
89176.13	0.2459207	100
89176.53	0.2459599	100
89176.93	0.2460001	100
89177.34	0.2460371	100
89177.73	0.2460785	100
89178.13	0.2461197	100
89178.53	0.2461576	100
89178.93	0.2461967	100
89179.34	0.2462363	100
89179.73	0.2462775	100
89180.13	0.2463186	100
89180.53	0.2463569	100
89180.93	0.2463964	100
89181.34	0.2464369	100
89181.73	0.2464791	100
89182.13	0.2465236	100
89182.53	0.2465669	100
89182.93	0.2466066	100
89183.34	0.246648	100
89183.73	0.2466917	100
89184.13	0.2467293	100
89184.53	0.2467741	100
89184.93	0.246816	100
89185.34	0.2468533	100
89185.73	0.2468906	100
89186.13	0.2469326	100
89186.53	0.2469753	100
89186.93	0.2470147	100
89187.34	0.247052	100
89187.73	0.2470929	100
89188.13	0.2471339	100
89188.53	0.2471771	100
89188.93	0.2472198	100
89189.34	0.2472558	100
89189.73	0.2472978	100
89190.13	0.2473371	100
89190.53	0.2473786	100
89190.93	0.2474194	100
89191.34	0.2474573	100
89191.73	0.2474904	100
89192.13	0.2475264	100
89192.53	0.2475657	100
89192.93	0.2476047	100
89193.34	0.2476431	100
89193.73	0.2476784	100
89194.13	0.2477199	100
89194.53	0.2477607	100
89194.93	0.2478028	100
89195.34	0.2478417	100
89195.73	0.2478807	100
89196.13	0.2479188	100
89196.53	0.2479587	100
89196.93	0.247998	100
89197.34	0.2480352	100
89197.73	0.2480749	100
89198.13	0.2481153	100
89198.53	0.248155	100
89198.93	0.2481918	100
89199.34	0.2482299	100
89199.73	0.2482717	100
89200.13	0.2483109	100
89200.53	0.2483504	100
89200.93	0.2483882	100
89201.34	0.2484274	100
89201.73	0.2484623	100
89202.13	0.2485001	100
89202.53	0.2485381	100
89202.93	0.2485783	100
89203.34	0.2486163	100
89203.73	0.2486565	100
89204.13	0.2486929	100
89204.53	0.2487316	100
89204.93	0.2487677	100
89205.34	0.2488056	100
89205.73	0.2488438	100
89206.13	0.2488837	100
89206.53	0.2489225	100
89206.93	0.248961	100
89207.34	0.2490014	100
89207.73	0.249043	100
89208.13	0.249081	100
89208.53	0.2491205	100
89208.93	0.2491593	100
89209.34	0.2492002	100
89209.73	0.2492387	100
89210.13	0.2492767	100
89210.53	0.2493169	100
89210.93	0.249351	100
89211.34	0.2493845	100
89211.73	0.2494214	100
89212.13	0.2494605	100
89212.53	0.2494932	100
89212.93	0.2495332	100
89213.34	0.2495728	100
89213.73	0.2496086	100
89214.13	0.2496467	100
89214.53	0.2496836	100
89214.93	0.2497218	100
89215.34	0.2497602	100
89215.73	0.2497988	100
89216.13	0.2498381	100
89216.53	0.2498774	100
89216.93	0.2499121	100
89217.34	0.2499486	100
89217.73	0.2499873	100
89218.13	0.2500236	100
89218.53	0.2500595	100
89218.93	0.2500977	100
89219.34	0.2501309	100
89219.73	0.2501667	100
89220.13	0.2502034	100
89220.53	0.2502434	100
89220.93	0.250281	100
89221.34	0.2503193	100
89221.73	0.2503545	100
89222.13	0.2503903	100
89222.53	0.250427	100
89222.93	0.2504628	100
89223.34	0.2504986	100
89223.73	0.2505363	100
89224.13	0.2505752	100
89224.53	0.2506125	100
89224.93	0.2506502	100
89225.34	0.2506867	100
89225.73	0.250725	100
89226.13	0.2507594	100
89226.53	0.2507925	100
89226.93	0.2508247	100
89227.34	0.2508598	100
89227.73	0.250893	100
89228.13	0.2509254	100
89228.53	0.2509597	100
89228.93	0.2509935	100
89229.34	0.2510299	100
89229.73	0.2510679	100
89230.13	0.2511025	100
89230.53	0.2511375	100
89230.93	0.2511703	100
89231.34	0.251204	100
89231.73	0.2512391	100
89232.13	0.2512773	100
89232.53	0.2513153	100
89232.93	0.2513522	100
89233.34	0.2513901	100
89233.73	0.2514259	100
89234.13	0.2514635	100
89234.53	0.2514981	100
89234.93	0.2515346	100
89235.34	0.2515698	100
89235.73	0.2516054	100
89236.13	0.2516413	100
89236.53	0.2516769	100
89236.93	0.2517091	100
89237.34	0.2517464	100
89237.73	0.2517831	100
89238.13	0.2518211	100
89238.53	0.251854	100
89238.93	0.2518881	100
89239.34	0.2519249	100
89239.73	0.2519595	100
89240.13	0.251997	100
89240.53	0.252032	100
89240.93	0.2520692	100
89241.34	0.2521048	100
89241.73	0.2521433	100
89242.13	0.2521794	100
89242.53	0.2522157	100
89242.93	0.2522523	100
89243.34	0.2522885	100
89243.73	0.2523251	100
89244.13	0.2523622	100
89244.53	0.2523999	100
89244.93	0.2524332	100
89245.34	0.252468	100
89245.73	0.2525035	100
89246.13	0.2525402	100
89246.53	0.2525761	100
89246.93	0.2526125	100
89247.34	0.2526474	100
89247.73	0.2526815	100
89248.13	0.2527178	100
89248.53	0.2527531	100
89248.93	0.25279	100
89249.34	0.2528238	100
89249.73	0.2528581	100
89250.13	0.2528924	100
89250.53	0.2529273	100
89250.93	0.2529639	100
89251.34	0.2529993	100
89251.73	0.2530334	100
89252.13	0.2530658	100
89252.53	0.2531033	100
89252.93	0.2531364	100
89253.34	0.2531712	100
89253.73	0.2532037	100
89254.13	0.2532383	100
89254.53	0.2532739	100
89254.93	0.2533084	100
89255.34	0.2533456	100
89255.73	0.2533795	100
89256.13	0.2534125	100
89256.53	0.2534483	100
89256.93	0.2534832	100
89257.34	0.2535173	100
89257.73	0.2535502	100
89258.13	0.2535846	100
89258.53	0.2536183	100
89258.93	0.2536512	100
89259.34	0.2536856	100
89259.73	0.2537195	100
89260.13	0.2537529	100
89260.53	0.253788	100
89260.93	0.2538218	100
89261.34	0.2538537	100
89261.73	0.2538882	100
89262.13	0.2539227	100
89262.53	0.2539581	100
89262.93	0.2539917	100
89263.34	0.2540274	100
89263.73	0.2540615	100
89264.13	0.2541007	100
89264.53	0.2541373	100
89264.93	0.2541719	100
89265.34	0.2542068	100
89265.73	0.25424	100
89266.13	0.2542741	100
89266.53	0.2543064	100
89266.93	0.2543417	100
89267.34	0.2543792	100
89267.73	0.2544164	100
89268.13	0.2544523	100
89268.53	0.2544898	100
89268.93	0.2545234	100
89269.34	0.2545568	100
89269.73	0.2545913	100
89270.13	0.2546269	100
89270.53	0.2546603	100
89270.93	0.2546954	100
89271.34	0.2547295	100
89271.73	0.2547651	100
89272.13	0.2547992	100
89272.53	0.2548335	100
89272.93	0.2548677	100
89273.34	0.2549038	100
89273.73	0.2549385	100
89274.13	0.2549746	100
89274.53	0.2550098	100
89274.93	0.2550441	100
89275.34	0.2550784	100
89275.73	0.2551121	100
89276.13	0.2551442	100
89276.53	0.2551768	100
89276.93	0.2552094	100
89277.34	0.2552419	100
89277.73	0.2552729	100
89278.13	0.255308	100
89278.53	0.2553417	100
89278.93	0.2553788	100
89279.34	0.2554116	100
89279.73	0.255446	100
89280.13	0.2554792	100
89280.53	0.2555142	100
89280.93	0.2555484	100
89281.34	0.2555798	100
89281.73	0.2556143	100
89282.13	0.2556474	100
89282.53	0.2556851	100
89282.93	0.2557169	100
89283.34	0.2557519	100
89283.73	0.2557848	100
89284.13	0.2558204	100
89284.53	0.2558536	100
89284.93	0.2558871	100
89285.34	0.2559221	100
89285.73	0.2559558	100
89286.13	0.2559892	100
89286.53	0.2560224	100
89286.93	0.2560583	100
89287.34	0.2560868	100
89287.73	0.2561199	100
89288.13	0.2561508	100
89288.53	0.2561832	100
89288.93	0.2562149	100
89289.34	0.2562489	100
89289.73	0.2562813	100
89290.13	0.2563129	100
89290.53	0.2563475	100
89290.93	0.2563803	100
89291.34	0.256416	100
89291.73	0.2564514	100
89292.13	0.2564831	100
89292.53	0.2565178	100
89292.93	0.2565506	100
89293.34	0.2565819	100
89293.73	0.2566158	100
89294.13	0.2566511	100
89294.53	0.256682	100
89294.93	0.2567151	100
89295.34	0.256749	100
89295.73	0.2567806	100
89296.13	0.2568159	100
89296.54	0.2568508	100
89296.94	0.2568831	100
89297.34	0.2569159	100
89297.74	0.2569499	100
89298.14	0.2569831	100
89298.54	0.2570159	100
89298.94	0.2570475	100
89299.34	0.2570802	100
89299.74	0.257113	100
89300.14	0.2571458	100
89300.54	0.257179	100
89300.94	0.257215	100
89301.34	0.2572476	100
89301.74	0.2572829	100
89302.14	0.2573169	100
89302.54	0.2573498	100
89302.94	0.2573836	100
89303.34	0.2574142	100
89303.74	0.2574507	100
89304.14	0.257483	100
89304.54	0.2575163	100
89304.94	0.2575491	100
89305.34	0.2575806	100
89305.74	0.2576149	100
89306.14	0.2576452	100
89306.54	0.2576783	100
89306.94	0.2577096	100
89307.34	0.2577419	100
89307.74	0.2577706	100
89308.14	0.2578053	100
89308.54	0.2578367	100
89308.94	0.257868	100
89309.34	0.2579013	100
89309.74	0.2579337	100
89310.14	0.2579659	100
89310.54	0.2579966	100
89310.94	0.2580294	100
89311.34	0.2580596	100
89311.74	0.2580926	100
89312.14	0.2581228	100
89312.54	0.2581553	100
89312.94	0.258188	100
89313.34	0.2582205	100
89313.74	0.258249	100
89314.14	0.258281	100
89314.54	0.2583131	100
89314.94	0.2583452	100
89315.34	0.2583758	100
89315.74	0.2584084	100
89316.14	0.2584406	100
89316.54	0.2584706	100
89316.94	0.2585024	100
89317.34	0.2585328	100
89317.74	0.2585673	100
89318.14	0.2585983	100
89318.54	0.2586309	100
89318.94	0.258662	100
89319.34	0.2586922	100
89319.74	0.2587254	100
89320.14	0.2587554	100
89320.54	0.2587861	100
89320.94	0.2588154	100
89321.34	0.2588476	100
89321.74	0.2588803	100
89322.14	0.2589148	100
89322.54	0.2589463	100
89322.94	0.2589806	100
89323.34	0.2590122	100
89323.74	0.2590446	100
89324.14	0.2590748	100
89324.54	0.2591071	100
89324.94	0.2591388	100
89325.34	0.2591734	100
89325.74	0.2592077	100
89326.14	0.2592377	100
89326.54	0.2592741	100
89326.94	0.2593045	100
89327.34	0.2593392	100
89327.74	0.2593685	100
89328.14	0.2594048	100
89328.54	0.2594337	100
89328.94	0.259466	100
89329.34	0.2594987	100
89329.74	0.2595309	100
89330.14	0.2595625	100
89330.54	0.2595953	100
89330.94	0.2596275	100
89331.34	0.2596563	100
89331.74	0.259687	100
89332.14	0.2597179	100
89332.54	0.2597482	100
89332.94	0.2597784	100
89333.34	0.2598076	100
89333.74	0.259837	100
89334.14	0.2598709	100
89334.54	0.259903	100
89334.94	0.259936	100
89335.34	0.2599671	100
89335.74	0.2599994	100
89336.14	0.2600306	100
89336.54	0.2600624	100
89336.94	0.260091	100
89337.34	0.2601209	100
89337.74	0.2601505	100
89338.14	0.2601825	100
89338.54	0.2602149	100
89338.94	0.2602466	100
89339.34	0.2602782	100
89339.74	0.2603087	100
89340.14	0.2603431	100
89340.54	0.2603759	100
89340.94	0.2604056	100
89341.34	0.2604384	100
89341.74	0.2604694	100
89342.14	0.2605005	100
89342.54	0.2605308	100
89342.94	0.2605647	100
89343.34	0.2605965	100
89343.74	0.2606274	100
89344.14	0.2606577	100
89344.54	0.2606896	100
89344.94	0.2607193	100
89345.34	0.260751	100
89345.74	0.2607783	100
89346.14	0.2608097	100
89346.54	0.2608363	100
89346.94	0.260868	100
89347.34	0.2608951	100
89347.74	0.2609241	100
89348.14	0.2609541	100
89348.54	0.2609842	100
89348.94	0.2610115	100
89349.34	0.2610404	100
89349.74	0.2610694	100
89350.14	0.2610925	100
89350.54	0.2611188	100
89350.94	0.2611432	100
89351.34	0.2611723	100
89351.74	0.2612005	100
89352.14	0.2612328	100
89352.54	0.261261	100
89352.94	0.2612886	100
89353.34	0.2613166	100
89353.74	0.2613463	100
89354.14	0.2613774	100
89354.54	0.2614102	100
89354.94	0.2614427	100
89355.34	0.2614768	100
89355.74	0.2615103	100
89356.14	0.2615409	100
89356.54	0.2615751	100
89356.94	0.2616067	100
89357.34	0.2616412	100
89357.74	0.2616707	100
89358.14	0.2617038	100
89358.54	0.2617323	100
89358.94	0.2617645	100
89359.34	0.2617944	100
89359.74	0.2618241	100
89360.14	0.2618563	100
89360.54	0.2618848	100
89360.94	0.2619162	100
89361.34	0.2619456	100
89361.74	0.2619776	100
89362.14	0.2620061	100
89362.54	0.2620362	100
89362.94	0.2620681	100
89363.34	0.2621016	100
89363.74	0.2621322	100
89364.14	0.2621621	100
89364.54	0.2621915	100
89364.94	0.2622231	100
89365.34	0.2622532	100
89365.74	0.2622832	100
89366.14	0.2623097	100
89366.54	0.2623386	100
89366.94	0.2623663	100
89367.34	0.2623948	100
89367.74	0.2624249	100
89368.14	0.2624558	100
89368.54	0.2624865	100
89368.94	0.2625129	100
89369.34	0.2625464	100
89369.74	0.262579	100
89370.14	0.2626138	100
89370.54	0.2626431	100
89370.94	0.2626749	100
89371.34	0.2627021	100
89371.74	0.262731	100
89372.14	0.2627598	100
89372.54	0.2627918	100
89372.94	0.262816	100
89373.34	0.2628462	100
89373.74	0.2628725	100
89374.14	0.2629004	100
89374.54	0.2629285	100
89374.94	0.2629559	100
89375.34	0.2629816	100
89375.74	0.2630115	100
89376.14	0.2630405	100
89376.54	0.2630681	100
89376.94	0.2630966	100
89377.34	0.2631264	100
89377.74	0.2631532	100
89378.14	0.2631825	100
89378.53	0.2632094	100
89378.93	0.2632356	100
89379.34	0.2632651	100
89379.73	0.2632939	100
89380.13	0.2633237	100
89380.53	0.2633484	100
89380.93	0.263375	100
89381.34	0.2634043	100
89381.73	0.2634346	100
89382.13	0.2634644	100
89382.53	0.2634927	100
89382.93	0.2635234	100
89383.34	0.2635552	100
89383.73	0.2635817	100
89384.13	0.2636116	100
89384.53	0.2636399	100
89384.93	0.2636688	100
89385.34	0.2636963	100
89385.73	0.2637239	100
89386.13	0.2637512	100
89386.53	0.2637826	100
89386.93	0.2638118	100
89387.34	0.263842	100
89387.73	0.2638705	100
89388.13	0.2639008	100
89388.53	0.2639288	100
89388.93	0.2639594	100
89389.34	0.2639885	100
89389.73	0.2640186	100
89390.13	0.2640488	100
89390.53	0.2640789	100
89390.93	0.2641107	100
89391.34	0.2641404	100
89391.73	0.2641685	100
89392.13	0.2641986	100
89392.53	0.2642292	100
89392.93	0.2642573	100
89393.34	0.2642846	100
89393.73	0.2643162	100
89394.13	0.2643436	100
89394.53	0.2643733	100
89394.93	0.2644034	100
89395.34	0.2644302	100
89395.73	0.2644601	100
89396.13	0.2644893	100
89396.53	0.2645166	100
89396.93	0.264548	100
89397.34	0.2645757	100
89397.73	0.2646054	100
89398.13	0.2646319	100
89398.53	0.2646612	100
89398.93	0.2646882	100
89399.34	0.2647157	100
89399.73	0.2647434	100
89400.13	0.2647697	100
89400.53	0.2647982	100
89400.93	0.2648241	100
89401.34	0.2648518	100
89401.73	0.2648811	100
89402.13	0.2649106	100
89402.53	0.2649354	100
89402.93	0.2649654	100
89403.34	0.2649931	100
89403.73	0.2650224	100
89404.13	0.2650524	100
89404.53	0.2650817	100
89404.93	0.2651093	100
89405.34	0.2651361	100
89405.73	0.2651639	100
89406.13	0.2651912	100
89406.53	0.2652186	100
89406.93	0.2652486	100
89407.34	0.2652769	100
89407.73	0.2653014	100
89408.13	0.2653292	100
89408.53	0.2653561	100
89408.93	0.2653837	100
89409.34	0.265413	100
89409.73	0.2654406	100
89410.13	0.2654672	100
89410.53	0.2654931	100
89410.93	0.2655224	100
89411.33	0.2655498	100
89411.73	0.2655771	100
89412.13	0.265603	100
89412.52	0.2656344	100
89412.92	0.265663	100
89413.33	0.2656931	100
89413.73	0.2657221	100
89414.13	0.2657475	100
89414.52	0.2657751	100
89414.92	0.2658034	100
89415.33	0.2658292	100
89415.73	0.2658533	100
89416.13	0.2658813	100
89416.52	0.2659098	100
89416.92	0.2659356	100
89417.33	0.2659621	100
89417.73	0.2659895	100
89418.13	0.2660153	100
89418.52	0.2660422	100
89418.92	0.2660707	100
89419.33	0.2660987	100
89419.73	0.2661259	100
89420.13	0.2661539	100
89420.52	0.2661827	100
89420.92	0.2662092	100
89421.33	0.266238	100
89421.73	0.2662664	100
89422.13	0.2662935	100
89422.52	0.2663197	100
89422.92	0.2663454	100
89423.33	0.2663733	100
89423.73	0.266401	100
89424.13	0.266427	100
89424.52	0.2664508	100
89424.92	0.2664803	100
89425.33	0.2665079	100
89425.73	0.2665347	100
89426.13	0.26656	100
89426.52	0.2665876	100
89426.92	0.2666114	100
89427.33	0.2666374	100
89427.73	0.2666647	100
89428.13	0.2666928	100
89428.52	0.2667164	100
89428.92	0.2667456	100
89429.33	0.2667734	100
89429.73	0.2667998	100
89430.13	0.2668296	100
89430.52	0.2668598	100
89430.92	0.2668846	100
89431.33	0.266912	100
89431.73	0.266938	100
89432.13	0.2669659	100
89432.52	0.2669926	100
89432.92	0.2670162	100
89433.33	0.2670418	100
89433.73	0.2670659	100
89434.13	0.2670931	100
89434.52	0.2671184	100
89434.92	0.2671448	100
89435.33	0.2671737	100
89435.73	0.2672001	100
89436.13	0.2672289	100
89436.52	0.2672554	100
89436.92	0.2672815	100
89437.33	0.2673076	100
89437.73	0.2673319	100
89438.13	0.2673568	100
89438.52	0.2673849	100
89438.92	0.2674101	100
89439.33	0.2674366	100
89439.73	0.2674639	100
89440.13	0.2674889	100
89440.52	0.267513	100
89440.92	0.2675378	100
89441.33	0.2675626	100
89441.73	0.2675871	100
89442.13	0.2676163	100
89442.52	0.2676417	100
89442.92	0.2676699	100
89443.33	0.2676974	100
89443.73	0.2677274	100
89444.12	0.2677516	100
89444.51	0.2677786	100
89444.91	0.2678056	100
89445.31	0.2678326	100
89445.72	0.2678608	100
89446.12	0.2678861	100
89446.51	0.2679159	100
89446.91	0.2679418	100
89447.31	0.2679692	100
89447.72	0.2679944	100
89448.12	0.2680218	100
89448.51	0.2680473	100
89448.91	0.2680742	100
89449.31	0.2681005	100
89449.72	0.2681228	100
89450.02	0.2681428	100