File: Y261_recov3.txt
Time	Strain	Shear Stress
[s]	[1]	[Pa]
80390.12	0.2128205	0.0000000000000000000000007965861
80390.41	0.1963274	0
80390.72	0.1896944	0
80391.01	0.1852027	0
80391.31	0.1817442	0
80391.61	0.1789417	0
80391.91	0.1765095	0
80392.21	0.1744144	0
80392.51	0.1725999	0
80392.81	0.1709283	0
80393.12	0.1693914	0
80393.41	0.1680087	0
80393.72	0.1667155	0
80394.01	0.1655068	0
80394.31	0.1643794	0
80394.61	0.1633072	0
80394.91	0.1622862	0
80395.21	0.1613109	0
80395.51	0.1603814	0
80395.81	0.159505	0
80396.12	0.1586647	0
80396.41	0.1578413	0
80396.72	0.1570636	0
80397.01	0.1563174	0
80397.31	0.1555649	0
80397.61	0.1548588	0
80397.91	0.1541864	0
80398.21	0.1535014	0
80398.51	0.1528568	0
80398.81	0.152258	0
80399.12	0.1516446	0
80399.41	0.1510406	0
80399.72	0.1504966	0
80400.01	0.1499344	0
80400.31	0.1493694	0
80400.61	0.1488565	0
80400.91	0.1483529	0
80401.21	0.147821	0
80401.51	0.1473287	0
80401.81	0.1468699	0
80402.12	0.1463791	0
80402.41	0.1459039	0
80402.72	0.1454736	0
80403.01	0.1450368	0
80403.31	0.14458	0
80403.61	0.1441661	0
80403.91	0.1437732	0
80404.21	0.1433481	0
80404.51	0.1429434	0
80404.81	0.1425714	0
80405.12	0.1421795	0
80405.41	0.1417812	0
80405.72	0.1414181	0
80406.01	0.1410587	0
80406.31	0.1406748	0
80406.61	0.1403205	0
80406.91	0.1399772	0
80407.21	0.1396156	0
80407.51	0.1392651	0
80407.81	0.1389419	0
80408.12	0.1386051	0
80408.41	0.1382619	0
80408.72	0.13795	0
80409.01	0.1376378	0
80409.31	0.13731	0
80409.61	0.1370018	0
80409.91	0.1367055	0
80410.21	0.136398	0
80410.51	0.1360986	0
80410.81	0.1358117	0
80411.12	0.135519	0
80411.41	0.1352219	0
80411.72	0.1349441	0
80412.01	0.1346582	0
80412.31	0.1343716	0
80412.61	0.1340944	0
80412.91	0.1338163	0
80413.21	0.1335407	0
80413.51	0.1332698	0
80413.81	0.133	0
80414.12	0.1327321	0
80414.41	0.1324698	0
80414.72	0.1322076	0
80415.01	0.1319458	0
80415.31	0.1316958	0
80415.61	0.1314465	0
80415.91	0.1311931	0
80416.21	0.1309471	0
80416.51	0.1307059	0
80416.81	0.1304622	0
80417.12	0.1302196	0
80417.41	0.1299886	0
80417.72	0.1297529	0
80418.01	0.1295103	0
80418.31	0.1292875	0
80418.61	0.1290642	0
80418.91	0.1288274	0
80419.21	0.1285974	0
80419.51	0.1283829	0
80419.81	0.1281534	0
80420.12	0.1279208	0
80420.41	0.1277159	0
80420.72	0.1275022	0
80421.01	0.1272686	0
80421.31	0.1270573	0
80421.61	0.1268564	0
80421.91	0.1266349	0
80422.21	0.1264128	0
80422.51	0.1262194	0
80422.81	0.1260148	0
80423.12	0.1257933	0
80423.41	0.125594	0
80423.72	0.1254049	0
80424.01	0.1251872	0
80424.31	0.1249819	0
80424.61	0.1248002	0
80424.91	0.1245902	0
80425.21	0.1243794	0
80425.51	0.1242013	0
80425.81	0.1240135	0
80426.12	0.1237983	0
80426.41	0.1236095	0
80426.72	0.1234429	0
80427.01	0.1232387	0
80427.31	0.1230384	0
80427.61	0.1228787	0
80427.91	0.1226964	0
80428.21	0.1224887	0
80428.51	0.1223201	0
80428.81	0.1221532	0
80429.12	0.1219548	0
80429.41	0.1217746	0
80429.72	0.1216207	0
80430.01	0.1214262	0
80430.31	0.1212392	0
80430.61	0.121093	0
80430.91	0.1209148	0
80431.21	0.1207241	0
80431.51	0.1205744	0
80431.81	0.1204134	0
80432.12	0.1202165	0
80432.41	0.1200639	0
80432.72	0.1199124	0
80433.01	0.1197206	0
80433.31	0.1195614	0
80433.61	0.1194218	0
80433.91	0.1192361	0
80434.21	0.1190681	0
80434.51	0.1189312	0
80434.81	0.1187559	0
80435.12	0.1185849	0
80435.41	0.1184552	0
80435.72	0.11829	0
80436.01	0.118111	0
80436.31	0.1179852	0
80436.61	0.1178225	0
80436.91	0.1176443	0
80437.21	0.1175155	0
80437.51	0.117363	0
80437.81	0.1171853	0
80438.12	0.1170537	0
80438.41	0.1169075	0
80438.72	0.1167324	0
80439.01	0.1166	0
80439.31	0.1164585	0
80439.61	0.1162854	0
80439.91	0.1161554	0
80440.21	0.1160242	0
80440.51	0.1158495	0
80440.81	0.1157226	0
80441.12	0.1155975	0
80441.41	0.1154302	0
80441.72	0.1152932	0
80442.01	0.115173	0
80442.31	0.1150082	0
80442.61	0.1148764	0
80442.91	0.1147534	0
80443.21	0.1145964	0
80443.51	0.1144684	0
80443.81	0.1143494	0
80444.12	0.1141895	0
80444.41	0.1140605	0
80444.72	0.1139489	0
80445.01	0.1137901	0
80445.31	0.113664	0
80445.61	0.1135491	0
80445.91	0.1133926	0
80446.21	0.1132739	0
80446.51	0.1131537	0
80446.81	0.1130032	0
80447.12	0.112888	0
80447.41	0.1127641	0
80447.72	0.1126173	0
80448.01	0.1125052	0
80448.31	0.1123836	0
80448.61	0.1122368	0
80448.91	0.1121282	0
80449.21	0.1120066	0
80449.51	0.1118634	0
80449.81	0.1117541	0
80450.12	0.1116337	0
80450.41	0.1114875	0
80450.72	0.1113818	0
80451.01	0.1112584	0
80451.31	0.1111199	0
80451.61	0.1110179	0
80451.91	0.1108931	0
80452.21	0.1107564	0
80452.51	0.1106574	0
80452.81	0.1105335	0
80453.12	0.1104014	0
80453.41	0.110301	0
80453.72	0.1101784	0
80454.01	0.1100506	0
80454.31	0.1099536	0
80454.61	0.1098308	0
80454.91	0.1097058	0
80455.21	0.1096121	0
80455.51	0.1094813	0
80455.81	0.1093707	0
80456.12	0.1092715	0
80456.41	0.1091419	0
80456.72	0.1090396	0
80457.01	0.1089346	0
80457.31	0.1088088	0
80457.61	0.1087052	0
80457.91	0.1086001	0
80458.21	0.1084774	0
80458.51	0.1083759	0
80458.81	0.1082682	0
80459.12	0.1081476	0
80459.41	0.1080495	0
80459.72	0.1079407	0
80460.01	0.1078234	0
80460.31	0.1077253	0
80460.61	0.1076156	0
80460.91	0.1075033	0
80461.21	0.1074095	0
80461.51	0.1072975	0
80461.81	0.1071909	0
80462.12	0.1070955	0
80462.41	0.1069832	0
80462.72	0.1068812	0
80463.01	0.106791	0
80463.31	0.1066771	0
80463.61	0.1065773	0
80463.91	0.1064804	0
80464.21	0.1063725	0
80464.51	0.1062748	0
80464.81	0.1061723	0
80465.12	0.1060668	0
80465.41	0.1059726	0
80465.72	0.105869	0
80466.01	0.1057644	0
80466.31	0.105676	0
80466.61	0.1055709	0
80466.91	0.1054698	0
80467.21	0.1053777	0
80467.51	0.1052731	0
80467.81	0.105175	0
80468.12	0.1050808	0
80468.41	0.1049781	0
80468.72	0.1048839	0
80469.01	0.104792	0
80469.31	0.1046879	0
80469.61	0.1045929	0
80469.91	0.1044977	0
80470.21	0.1044017	0
80470.51	0.1043057	0
80470.81	0.1042109	0
80471.12	0.104115	0
80471.41	0.1040242	0
80471.72	0.1039283	0
80472.01	0.1038341	0
80472.31	0.1037426	0
80472.61	0.1036488	0
80472.91	0.1035526	0
80473.21	0.1034614	0
80473.51	0.1033682	0
80473.81	0.103278	0
80474.12	0.1031866	0
80474.41	0.1030914	0
80474.72	0.1030028	0
80475.01	0.1029112	0
80475.31	0.1028194	0
80475.61	0.1027272	0
80475.91	0.1026381	0
80476.21	0.1025493	0
80476.51	0.1024556	0
80476.81	0.1023662	0
80477.12	0.1022774	0
80477.41	0.1021876	0
80477.72	0.1021035	0
80478.01	0.1020151	0
80478.31	0.1019256	0
80478.61	0.1018412	0
80478.91	0.1017556	0
80479.21	0.1016621	0
80479.51	0.1015825	0
80479.81	0.1014909	0
80480.12	0.1014043	0
80480.41	0.101322	0
80480.72	0.1012286	0
80481.01	0.1011465	0
80481.31	0.1010649	0
80481.61	0.1009747	0
80481.91	0.1008912	0
80482.21	0.1008097	0
80482.51	0.1007225	0
80482.81	0.1006419	0
80483.12	0.1005586	0
80483.41	0.1004697	0
80483.72	0.1003975	0
80484.01	0.1003031	0
80484.31	0.1002192	0
80484.61	0.1001465	0
80484.91	0.1000537	0
80485.21	0.09997723	0
80485.51	0.09989756	0
80485.81	0.09980857	0
80486.12	0.09973859	0
80486.41	0.09964991	0
80486.72	0.09956411	0
80487.01	0.09949778	0
80487.31	0.09940498	0
80487.61	0.09932833	0
80487.91	0.0992555	0
80488.21	0.09916483	0
80488.51	0.09909479	0
80488.81	0.09900893	0
80489.12	0.09892506	0
80489.41	0.09886141	0
80489.72	0.09876955	0
80490.01	0.09869185	0
80493.01	0.09798259	0
80496.01	0.09722518	0
80499.01	0.09648132	0
80502.01	0.09575625	0
80505.01	0.09504897	0
80508.01	0.09436007	0
80511.01	0.09369145	0
80514.01	0.09303688	0
80517.01	0.09240467	0
80520.01	0.09178279	0
80523.01	0.09119357	0
80526.01	0.09060652	0
80529.01	0.09003236	0
80532.01	0.0894635	0
80535.01	0.08890942	0
80538.01	0.08836185	0
80541.01	0.08783801	0
80544.01	0.0873204	0
80547.01	0.0868165	0
80550.01	0.08631765	0
80553.01	0.08583123	0
80556.01	0.08534672	0
80559.01	0.08487211	0
80562.01	0.08440479	0
80565.01	0.0839559	0
80568.01	0.08350851	0
80571.01	0.08306938	0
80574.01	0.08263416	0
80577.01	0.08220703	0
80580.01	0.08178726	0
80583.01	0.08137717	0
80586.01	0.08097736	0
80589.01	0.08057667	0
80592.01	0.08018958	0
80595.01	0.07980959	0
80598.01	0.07943891	0
80601.01	0.07906745	0
80604.01	0.07870718	0
80607.01	0.07834444	0
80610.01	0.07799547	0
80613.01	0.07765071	0
80616.01	0.07730803	0
80619.01	0.07697617	0
80622.01	0.07663898	0
80625.01	0.07630525	0
80628.01	0.07599432	0
80631.01	0.07567918	0
80634.01	0.07536138	0
80637.01	0.07503995	0
80640.01	0.07473351	0
80643.01	0.07443287	0
80646.01	0.07412674	0
80649.01	0.07383559	0
80652.01	0.07353769	0
80655.01	0.07325815	0
80658.01	0.07296668	0
80661.01	0.07268322	0
80664.01	0.07239816	0
80667.01	0.07212091	0
80670.01	0.07183991	0
80673.01	0.07155634	0
80676.01	0.071292	0
80679.01	0.07104395	0
80682.01	0.0707839	0
80685.01	0.07052858	0
80688.01	0.07027321	0
80691.01	0.07002705	0
80694.01	0.06977984	0
80697.01	0.06952902	0
80700.01	0.06928406	0
80703.01	0.06904984	0
80706.01	0.06881096	0
80709.01	0.06857745	0
80712.01	0.06834664	0
80715.01	0.06810144	0
80718.01	0.06786224	0
80721.01	0.06762542	0
80724.01	0.06739594	0
80727.01	0.06716947	0
80730.01	0.06695264	0
80733.01	0.06672235	0
80736.01	0.06649497	0
80739.01	0.06627619	0
80742.01	0.06605502	0
80745.01	0.06583782	0
80748.01	0.06562941	0
80751.01	0.0654183	0
80754.01	0.06521422	0
80757.01	0.06500896	0
80760.01	0.06481096	0
80763.01	0.06461179	0
80766.01	0.06441177	0
80769.01	0.06421451	0
80772.01	0.06401976	0
80775.01	0.06383086	0
80778.01	0.0636401	0
80781.01	0.06345829	0
80784.01	0.06327921	0
80787.01	0.06309299	0
80790.01	0.06291667	0
80793.01	0.06273131	0
80796.01	0.06254604	0
80799.01	0.06236966	0
80802.01	0.06218513	0
80805.01	0.06201453	0
80808.01	0.06183541	0
80811.01	0.06165545	0
80814.01	0.06147686	0
80817.01	0.06129995	0
80820.01	0.06112802	0
80823.01	0.06095776	0
80826.01	0.0607928	0
80829.01	0.06062191	0
80832.01	0.06045066	0
80835.01	0.06029122	0
80838.01	0.06013757	0
80841.01	0.05998324	0
80844.01	0.05982167	0
80847.01	0.0596677	0
80850.01	0.05951108	0
80853.01	0.0593611	0
80856.01	0.05920474	0
80859.01	0.05905056	0
80862.01	0.05891156	0
80865.01	0.05876638	0
80868.01	0.05863366	0
80871.01	0.05848481	0
80874.01	0.05833175	0
80877.01	0.05819662	0
80880.01	0.05805013	0
80883.01	0.05791264	0
80886.01	0.05777668	0
80889.01	0.0576363	0
80892.01	0.05748862	0
80895.01	0.05735419	0
80898.01	0.05721325	0
80901.01	0.05706878	0
80904.01	0.05693458	0
80907.01	0.05680037	0
80910.01	0.0566758	0
80913.01	0.05655817	0
80916.01	0.05643066	0
80919.01	0.05630262	0
80922.01	0.0561733	0
80925.01	0.05604157	0
80928.01	0.05591476	0
80931.01	0.0557786	0
80934.01	0.05565545	0
80937.01	0.0555117	0
80940.01	0.05538061	0
80943.01	0.05526706	0
80946.01	0.05512442	0
80949.01	0.05500013	0
80952.01	0.05488373	0
80955.01	0.05475622	0
80958.01	0.05462727	0
80961.01	0.05450099	0
80964.01	0.05437909	0
80967.01	0.05424996	0
80970.01	0.05412381	0
80973.01	0.05401483	0
80976.01	0.05390478	0
80979.01	0.05378145	0
80982.01	0.05368357	0
80985.01	0.05358396	0
80988.01	0.05347256	0
80991.01	0.05335837	0
80994.01	0.05323273	0
80997.01	0.0531321	0
81000.01	0.05302325	0
81003.01	0.05292133	0
81006.01	0.05282243	0
81009.01	0.05271227	0
81012.01	0.05260425	0
81015.01	0.05249693	0
81018.01	0.05239853	0
81021.01	0.05228235	0
81024.01	0.05216758	0
81027.01	0.05206084	0
81030.01	0.05195924	0
81033.01	0.05185739	0
81036.01	0.05175361	0
81039.01	0.05165752	0
81042.01	0.0515445	0
81045.01	0.05143779	0
81048.01	0.05134384	0
81051.01	0.05124895	0
81054.01	0.05114605	0
81057.01	0.05104369	0
81060.01	0.05093384	0
81063.01	0.05083837	0
81066.01	0.05074512	0
81069.01	0.05064645	0
81072.01	0.05055067	0
81075.01	0.05045418	0
81078.01	0.05037467	0
81081.01	0.05030199	0
81084.01	0.05021478	0
81087.01	0.05011906	0
81090.01	0.05001849	0
81093.01	0.04991777	0
81096.01	0.04981867	0
81099.01	0.04973456	0
81102.01	0.0496498	0
81105.01	0.04956092	0
81108.01	0.04948601	0
81111.01	0.04938942	0
81114.01	0.04930392	0
81117.01	0.04923204	0
81120.01	0.04915033	0
81123.01	0.04908001	0
81126.01	0.04898574	0
81129.01	0.0489143	0
81132.01	0.04882542	0
81135.01	0.04874997	0
81138.01	0.048675	0
81141.01	0.04860251	0
81144.01	0.04851256	0
81147.01	0.0484197	0
81150.01	0.04834662	0
81153.01	0.04827409	0
81156.01	0.04819532	0
81159.01	0.04812057	0
81162.01	0.04804845	0
81165.01	0.04798193	0
81168.01	0.04789601	0
81171.01	0.04783091	0
81174.01	0.04775284	0
81177.01	0.04767759	0
81180.01	0.04759278	0
81183.01	0.04751704	0
81186.01	0.04744903	0
81189.01	0.04738001	0
81192.01	0.04730037	0
81195.01	0.04721112	0
81198.01	0.04712229	0
81201.01	0.04703592	0
81204.01	0.04695394	0
81207.01	0.04688958	0
81210.01	0.04682712	0
81213.01	0.04674406	0
81216.01	0.04666996	0
81219.01	0.04660596	0
81222.01	0.04651906	0
81225.01	0.04647167	0
81228.01	0.04640229	0
81231.01	0.0463474	0
81234.01	0.04627743	0
81237.01	0.04619762	0
81240.01	0.04613221	0
81243.01	0.04605788	0
81246.01	0.04599923	0
81249.01	0.04593128	0
81252.01	0.04586532	0
81255.01	0.04580508	0
81258.01	0.04573243	0
81261.01	0.04567464	0
81264.01	0.04560971	0
81267.01	0.04554052	0
81270.01	0.04546675	0
81273.01	0.04539619	0
81276.01	0.04533175	0
81279.01	0.04527976	0
81282.01	0.04521974	0
81285.01	0.04514346	0
81288.01	0.045075	0
81291.01	0.04500088	0
81294.01	0.04494633	0
81297.01	0.04487553	0
81300.01	0.04480827	0
81303.01	0.04474265	0
81306.01	0.04467762	0
81309.01	0.04461135	0
81312.01	0.04454203	0
81315.01	0.04446952	0
81318.01	0.04440485	0
81321.01	0.04434444	0
81324.01	0.04428517	0
81327.01	0.04422455	0
81330.01	0.04416941	0
81333.01	0.04410758	0
81336.01	0.04404818	0
81339.01	0.0439861	0
81342.01	0.04392848	0
81345.01	0.04386026	0
81348.01	0.04380459	0
81351.01	0.04373433	0
81354.01	0.0436695	0
81357.01	0.04361088	0
81360.01	0.04354706	0
81363.01	0.04348519	0
81366.01	0.04341437	0
81369.01	0.0433537	0
81372.01	0.043293	0
81375.01	0.04323316	0
81378.01	0.04317184	0
81381.01	0.04311501	0
81384.01	0.04306796	0
81387.01	0.04301133	0
81390.01	0.04295492	0
81393.01	0.0429026	0
81396.01	0.04285314	0
81399.01	0.04279539	0
81402.01	0.04273764	0
81405.01	0.0426812	0
81408.01	0.0426194	0
81411.01	0.04257356	0
81414.01	0.04251032	0
81417.01	0.0424568	0
81420.01	0.04240551	0
81423.01	0.04235739	0
81426.01	0.04230851	0
81429.01	0.04225579	0
81432.01	0.04220297	0
81435.01	0.04215112	0
81438.01	0.04210441	0
81441.01	0.04205759	0
81444.01	0.04200834	0
81447.01	0.04195606	0
81450.01	0.04190645	0
81453.01	0.04185998	0
81456.01	0.0418056	0
81459.01	0.04174892	0
81462.01	0.04169249	0
81465.01	0.04164421	0
81468.01	0.04158681	0
81471.01	0.04154001	0
81474.01	0.0414838	0
81477.01	0.04143598	0
81480.01	0.04138964	0
81483.01	0.04134495	0
81486.01	0.0413117	0
81489.01	0.04126072	0
81492.01	0.04121296	0
81495.01	0.04117719	0
81498.01	0.04114138	0
81501.01	0.04109588	0
81504.01	0.04105683	0
81507.01	0.04101259	0
81510.01	0.04096903	0
81513.01	0.04092374	0
81516.01	0.04086742	0
81519.01	0.04081705	0
81522.01	0.04076884	0
81525.01	0.04071832	0
81528.01	0.04065879	0
81531.01	0.04061174	0
81534.01	0.04056775	0
81537.01	0.04051543	0
81540.01	0.04047342	0
81543.01	0.04043773	0
81546.01	0.04039834	0
81549.01	0.04035944	0
81552.01	0.04031769	0
81555.01	0.04027148	0
81558.01	0.04023532	0
81561.01	0.04019009	0
81564.01	0.04014873	0
81567.01	0.0401074	0
81570.01	0.04006394	0
81573.01	0.0400108	0
81576.01	0.03997041	0
81579.01	0.03993107	0
81582.01	0.03988354	0
81585.01	0.0398306	0
81588.01	0.03978748	0
81591.01	0.03973911	0
81594.01	0.03968451	0
81597.01	0.03962979	0
81600.01	0.03958022	0
81603.01	0.03954195	0
81606.01	0.03949235	0
81609.01	0.03944275	0
81612.01	0.03941261	0
81615.01	0.03936815	0
81618.01	0.03932273	0
81621.01	0.03927113	0
81624.01	0.0392233	0
81627.01	0.03917994	0
81630.01	0.03912826	0
81633.01	0.03907568	0
81636.01	0.03904415	0
81639.01	0.03901084	0
81642.01	0.03897336	0
81645.01	0.0389356	0
81648.01	0.03889542	0
81651.01	0.038859	0
81654.01	0.03882558	0
81657.01	0.03879204	0
81660.01	0.03876248	0
81663.01	0.03872407	0
81666.01	0.03869137	0
81669.01	0.03864485	0
81672.01	0.03861125	0
81675.01	0.03857493	0
81678.01	0.03854125	0
81681.01	0.03848702	0
81684.01	0.03844587	0
81687.01	0.03840542	0
81690.01	0.03836722	0
81693.01	0.03834137	0
81696.01	0.03831361	0
81699.01	0.03827406	0
81702.01	0.03823865	0
81705.01	0.038204	0
81708.01	0.03816352	0
81711.01	0.03811564	0
81714.01	0.03807454	0
81717.01	0.03803844	0
81720.01	0.03799824	0
81723.01	0.03796263	0
81726.01	0.0379133	0
81729.01	0.03788756	0
81732.01	0.03785159	0
81735.01	0.03780953	0
81738.01	0.0377754	0
81741.01	0.03774502	0
81744.01	0.0377075	0
81747.01	0.03766415	0
81750.01	0.03763036	0
81753.01	0.03759603	0
81756.01	0.0375578	0
81759.01	0.03751821	0
81762.01	0.03749153	0
81765.01	0.03745193	0
81768.01	0.03741293	0
81771.01	0.03737336	0
81774.01	0.0373368	0
81777.01	0.03730021	0
81780.01	0.03726367	0
81783.01	0.03722846	0
81786.01	0.03719336	0
81789.01	0.03715678	0
81792.01	0.03710644	0
81795.01	0.03705456	0
81798.01	0.03702032	0
81801.01	0.03698583	0
81804.01	0.03696086	0
81807.01	0.03692804	0
81810.01	0.03688767	0
81813.01	0.0368597	0
81816.01	0.03681952	0
81819.01	0.03678211	0
81822.01	0.03675159	0
81825.01	0.03671203	0
81828.01	0.03668321	0
81831.01	0.03664088	0
81834.01	0.03660636	0
81837.01	0.03657027	0
81840.01	0.03655316	0
81843.01	0.0365273	0
81846.01	0.03649501	0
81849.01	0.0364544	0
81852.01	0.03642286	0
81855.01	0.03638876	0
81858.01	0.03635302	0
81861.01	0.03631401	0
81864.01	0.03627748	0
81867.01	0.03624152	0
81870.01	0.03621005	0
81873.01	0.03618564	0
81876.01	0.03616349	0
81879.01	0.03614783	0
81882.01	0.0361232	0
81885.01	0.03609677	0
81888.01	0.03606497	0
81891.01	0.0360322	0
81894.01	0.03600531	0
81897.01	0.03597452	0
81900.01	0.03594479	0
81903.01	0.03591728	0
81906.01	0.03589459	0
81909.01	0.03586761	0
81912.01	0.03583235	0
81915.01	0.0357969	0
81918.01	0.03576426	0
81921.01	0.0357284	0
81924.01	0.03570703	0
81927.01	0.0356779	0
81930.01	0.03564426	0
81933.01	0.03562028	0
81936.01	0.03558952	0
81939.01	0.03556727	0
81942.01	0.035529	0
81945.01	0.03550426	0
81948.01	0.0354822	0
81951.01	0.03544827	0
81954.01	0.03541627	0
81957.01	0.03537809	0
81960.01	0.0353465	0
81963.01	0.03532542	0
81966.01	0.03529039	0
81969.01	0.03525683	0
81972.01	0.03522782	0
81975.01	0.0351995	0
81978.01	0.03516292	0
81981.01	0.03511958	0
81984.01	0.03508943	0
81987.01	0.03505687	0
81990.01	0.03501874	0
81993.01	0.03497447	0
81996.01	0.03495307	0
81999.01	0.03492397	0
82002.01	0.0348951	0
82005.01	0.03486768	0
82008.01	0.03484146	0
82011.01	0.03481636	0
82014.01	0.03478068	0
82017.01	0.03474853	0
82020.01	0.03472813	0
82023.01	0.03469626	0
82026.01	0.03466287	0
82029.01	0.03463662	0
82032.01	0.03461741	0
82035.01	0.03458535	0
82038.01	0.03454748	0
82041.01	0.03452086	0
82044.01	0.0345039	0
82047.01	0.03448692	0
82050.01	0.03446757	0
82053.01	0.03443944	0
82056.01	0.03440644	0
82059.01	0.03438076	0
82062.01	0.03436105	0
82065.01	0.03434613	0
82068.01	0.0343224	0
82071.01	0.03428404	0
82074.01	0.03426328	0
82077.01	0.0342418	0
82080.01	0.03422495	0
82083.01	0.03420264	0
82086.01	0.03417919	0
82089.01	0.0341427	0
82092.01	0.03410966	0
82095.01	0.03408951	0
82098.01	0.03406087	0
82101.01	0.03404235	0
82104.01	0.03401573	0
82107.01	0.0339888	0
82110.01	0.03395654	0
82113.01	0.03392447	0
82116.01	0.03390858	0
82119.01	0.03388202	0
82122.01	0.03385958	0
82125.01	0.0338266	0
82128.01	0.0338033	0
82131.01	0.03378971	0
82134.01	0.03376827	0
82137.01	0.03374581	0
82140.01	0.03371132	0
82143.01	0.03368126	0
82146.01	0.03364624	0
82149.01	0.03362664	0
82152.01	0.03360068	0
82155.01	0.03357239	0
82158.01	0.03355362	0
82161.01	0.03353012	0
82164.01	0.0334976	0
82167.01	0.03346625	0
82170.01	0.03342905	0
82173.01	0.03340999	0
82176.01	0.03339497	0
82179.01	0.03336899	0
82182.01	0.03334506	0
82185.01	0.03332207	0
82188.01	0.0333045	0
82191.01	0.03327232	0
82194.01	0.03325139	0
82197.01	0.03322073	0
82200.01	0.03317481	0
82203.01	0.03316749	0
82206.01	0.03315258	0
82209.01	0.03312291	0
82212.01	0.0331113	0
82215.01	0.03308877	0
82218.01	0.03306395	0
82221.01	0.03304881	0
82224.01	0.03303366	0
82227.01	0.03301836	0
82230.01	0.03299811	0
82233.01	0.03296834	0
82236.01	0.03294437	0
82239.01	0.03291653	0
82242.01	0.03289291	0
82245.01	0.03287134	0
82248.01	0.03286286	0
82251.01	0.03283695	0
82254.01	0.03280686	0
82257.01	0.03278499	0
82260.01	0.03276271	0
82263.01	0.03274438	0
82266.01	0.03271702	0
82269.01	0.03269928	0
82272.01	0.03267025	0
82275.01	0.03264291	0
82278.01	0.03261545	0
82281.01	0.03257721	0
82284.01	0.03254993	0
82287.01	0.03252247	0
82290.01	0.03249994	0
82293.01	0.0324885	0
82296.01	0.03247276	0
82299.01	0.03246528	0
82302.01	0.03244503	0
82305.01	0.03242519	0
82308.01	0.03239238	0
82311.01	0.03236765	0
82314.01	0.03233955	0
82317.01	0.03231503	0
82320.01	0.03228909	0
82323.01	0.03226652	0
82326.01	0.03224335	0
82329.01	0.03222201	0
82332.01	0.0321968	0
82335.01	0.03217736	0
82338.01	0.03215563	0
82341.01	0.03213671	0
82344.01	0.03211895	0
82347.01	0.03209862	0
82350.01	0.03207334	0
82353.01	0.03204835	0
82356.01	0.0320222	0
82359.01	0.03200014	0
82362.01	0.0319805	0
82365.01	0.03196282	0
82368.01	0.03194694	0
82371.01	0.03192845	0
82374.01	0.03190434	0
82377.01	0.0318814	0
82380.01	0.03186162	0
82383.01	0.03183482	0
82386.01	0.03180825	0
82389.01	0.03178911	0
82392.01	0.03177331	0
82395.01	0.03175201	0
82398.01	0.03172747	0
82401.01	0.03171147	0
82404.01	0.03169113	0
82407.01	0.031675	0
82410.01	0.03165866	0
82413.01	0.03164375	0
82416.01	0.03162851	0
82419.01	0.03160819	0
82422.01	0.03158537	0
82425.01	0.0315648	0
82428.01	0.03154523	0
82431.01	0.0315184	0
82434.01	0.03150143	0
82437.01	0.03148085	0
82440.01	0.03145931	0
82443.01	0.03143993	0
82446.01	0.03142179	0
82449.01	0.03140764	0
82452.01	0.03139317	0
82455.01	0.0313774	0
82458.01	0.03136128	0
82461.01	0.03134466	0
82464.01	0.03133424	0
82467.01	0.03131554	0
82470.01	0.03130833	0
82473.01	0.03128556	0
82476.01	0.03126535	0
82479.01	0.03124774	0
82482.01	0.03123298	0
82485.01	0.03121231	0
82488.01	0.03119705	0
82491.01	0.03118376	0
82494.01	0.03117372	0
82497.01	0.03115457	0
82500.01	0.03112947	0
82503.01	0.03111478	0
82506.01	0.03109929	0
82509.01	0.03107432	0
82512.01	0.03105195	0
82515.01	0.03103364	0
82518.01	0.03100692	0
82521.01	0.03098025	0
82524.01	0.03096119	0
82527.01	0.03093617	0
82530.01	0.03091357	0
82533.01	0.03089487	0
82536.01	0.03087177	0
82539.01	0.03085959	0
82542.01	0.03083339	0
82545.01	0.03081268	0
82548.01	0.03079313	0
82551.01	0.03077684	0
82554.01	0.03076407	0
82557.01	0.030747	0
82560.01	0.0307312	0
82563.01	0.03071332	0
82566.01	0.03069786	0
82569.01	0.0306727	0
82572.01	0.03064526	0
82575.01	0.03062465	0
82578.01	0.03060778	0
82581.01	0.03059026	0
82584.01	0.03057209	0
82587.01	0.030557	0
82590.01	0.03053603	0
82593.01	0.03051505	0
82596.01	0.0304988	0
82599.01	0.03047933	0
82602.01	0.03046667	0
82605.01	0.03045689	0
82608.01	0.03044585	0
82611.01	0.03044713	0
82614.01	0.03043548	0
82617.01	0.03041869	0
82620.01	0.03040969	0
82623.01	0.03038767	0
82626.01	0.0303608	0
82629.01	0.03034444	0
82632.01	0.03033028	0
82635.01	0.0303201	0
82638.01	0.03030414	0
82641.01	0.03028612	0
82644.01	0.03027453	0
82647.01	0.03026146	0
82650.01	0.03024148	0
82653.01	0.03022167	0
82656.01	0.03020019	0
82659.01	0.03017346	0
82662.01	0.03015116	0
82665.01	0.03012888	0
82668.01	0.03010282	0
82671.01	0.03009106	0
82674.01	0.03008092	0
82677.01	0.03007001	0
82680.01	0.03005524	0
82683.01	0.03004711	0
82686.01	0.030038	0
82689.01	0.03002412	0
82692.01	0.03000768	0
82695.01	0.02999691	0
82698.01	0.02998719	0
82701.01	0.02997006	0
82704.01	0.02996159	0
82707.01	0.02994733	0
82710.01	0.02992559	0
82713.01	0.0299123	0
82716.01	0.02990474	0
82719.01	0.02989362	0
82722.01	0.02985824	0
82725.01	0.02983039	0
82728.01	0.02980925	0
82731.01	0.02979698	0
82734.01	0.02977782	0
82737.01	0.02976383	0
82740.01	0.02974744	0
82743.01	0.02974122	0
82746.01	0.02974296	0
82749.01	0.02973837	0
82752.01	0.02971422	0
82755.01	0.02969522	0
82758.01	0.02968698	0
82761.01	0.02966965	0
82764.01	0.02964067	0
82767.01	0.02961613	0
82770.01	0.02960444	0
82773.01	0.02958093	0
82776.01	0.02957844	0
82779.01	0.02955737	0
82782.01	0.02954342	0
82785.01	0.02953574	0
82788.01	0.02951826	0
82791.01	0.02950181	0
82794.01	0.02948198	0
82797.01	0.02946972	0
82800.01	0.02945362	0
82803.01	0.02942923	0
82806.01	0.02939878	0
82809.01	0.02939966	0
82812.01	0.02938032	0
82815.01	0.02937444	0
82818.01	0.02935135	0
82821.01	0.02934038	0
82824.01	0.02932439	0
82827.01	0.02931575	0
82830.01	0.02929992	0
82833.01	0.02927738	0
82836.01	0.02926116	0
82839.01	0.02924632	0
82842.01	0.02922506	0
82845.01	0.02921093	0
82848.01	0.02919291	0
82851.01	0.02917015	0
82854.01	0.02915035	0
82857.01	0.02912931	0
82860.01	0.02911357	0
82863.01	0.02910054	0
82866.01	0.02908885	0
82869.01	0.02907493	0
82872.01	0.02905987	0
82875.01	0.02905032	0
82878.01	0.0290379	0
82881.01	0.0290206	0
82884.01	0.02902009	0
82887.01	0.02900196	0
82890.01	0.02899148	0
82893.01	0.02897832	0
82896.01	0.02896019	0
82899.01	0.02894579	0
82902.01	0.0289334	0
82905.01	0.02891822	0
82908.01	0.02890568	0
82911.01	0.02889289	0
82914.01	0.02888342	0
82917.01	0.02888781	0
82920.01	0.02886511	0
82923.01	0.02884715	0
82926.01	0.02882702	0
82929.01	0.02882227	0
82932.01	0.02881013	0
82935.01	0.02878618	0
82938.01	0.0287832	0
82941.01	0.02877187	0
82944.01	0.0287486	0
82947.01	0.02873519	0
82950.01	0.02871712	0
82953.01	0.02870227	0
82956.01	0.02868991	0
82959.01	0.02867364	0
82962.01	0.02865621	0
82965.01	0.0286426	0
82968.01	0.0286231	0
82971.01	0.02861436	0
82974.01	0.02860406	0
82977.01	0.02858754	0
82980.01	0.02856977	0
82983.01	0.02855288	0
82986.01	0.02853773	0
82989.01	0.02852351	0
82992.01	0.02851221	0
82995.01	0.02849002	0
82998.01	0.02846757	0
83001.01	0.02844954	0
83004.01	0.02842037	0
83007.01	0.02840254	0
83010.01	0.02839113	0
83013.01	0.02837464	0
83016.01	0.02837009	0
83019.01	0.02836503	0
83022.01	0.0283516	0
83025.01	0.0283272	0
83028.01	0.0283006	0
83031.01	0.02828646	0
83034.01	0.02827302	0
83037.01	0.02826543	0
83040.01	0.02825597	0
83043.01	0.02825115	0
83046.01	0.02823632	0
83049.01	0.02822163	0
83052.01	0.02821528	0
83055.01	0.02819176	0
83058.01	0.02817722	0
83061.01	0.02816932	0
83064.01	0.02815046	0
83067.01	0.02814294	0
83070.01	0.02812947	0
83073.01	0.02811438	0
83076.01	0.02809619	0
83079.01	0.02809716	0
83082.01	0.02808825	0
83085.01	0.02807234	0
83088.01	0.02805993	0
83091.01	0.02805985	0
83094.01	0.02804625	0
83097.01	0.02803798	0
83100.01	0.02802705	0
83103.01	0.02801894	0
83106.01	0.02800317	0
83109.01	0.02799287	0
83112.01	0.02797238	0
83115.01	0.02795841	0
83118.01	0.02794885	0
83121.01	0.02793345	0
83124.01	0.02792367	0
83127.01	0.02790857	0
83130.01	0.02789541	0
83133.01	0.02788196	0
83136.01	0.02787295	0
83139.01	0.02785761	0

83140.01	0.02785533	0
83142.01	0.02784568	0
83144.01	0.02783256	0
83146.01	0.02781779	0
83148.01	0.02780272	0
83150.01	0.02779647	0
83152.01	0.02779046	0
83154.01	0.02777575	0
83156.01	0.02776286	0
83158.01	0.02775425	0
83160.01	0.02774164	0
83162.01	0.02773245	0
83164.01	0.02772098	0
83166.01	0.02771347	0
83168.01	0.02770774	0
83170.01	0.02769543	0
83172.01	0.02768425	0
83174.01	0.02767626	0
83176.01	0.02766748	0
83178.01	0.0276622	0
83180.01	0.02765548	0
83182.01	0.02764158	0
83184.01	0.0276334	0
83186.01	0.02761847	0
83188.01	0.02761319	0
83190.01	0.02760322	0
83192.01	0.02759032	0
83194.01	0.02758291	0
83196.01	0.02757414	0
83198.01	0.02756741	0
83200.01	0.02755895	0
83202.01	0.02754865	0
83204.01	0.02753811	0
83206.01	0.02753201	0
83208.01	0.02752911	0
83210.01	0.0275308	0
83212.01	0.02752609	0
83214.01	0.02752606	0
83216.01	0.02752541	0
83218.01	0.0275166	0
83220.01	0.02750887	0
83222.01	0.02750243	0
83224.01	0.02749277	0
83226.01	0.0274862	0
83228.01	0.02747909	0
83230.01	0.02747265	0
83232.01	0.02746175	0
83234.01	0.02745606	0
83236.01	0.02744297	0
83238.01	0.02743294	0
83240.01	0.02742647	0
83242.01	0.02741996	0
83244.01	0.02741662	0
83246.01	0.02740712	0
83248.01	0.02739525	0
83250.01	0.0273754	0
83252.01	0.02736293	0
83254.01	0.02735289	0
83256.01	0.02734457	0
83258.01	0.02733594	0
83260.01	0.02732877	0
83262.01	0.02731935	0
83264.01	0.02731202	0
83266.01	0.0273015	0
83268.01	0.02729399	0
83270.01	0.02728319	0
83272.01	0.02728358	0
83274.01	0.02727759	0
83276.01	0.02726864	0
83278.01	0.02726424	0
83280.01	0.02725646	0
83282.01	0.02724705	0
83284.01	0.02723999	0
83286.01	0.0272336	0
83288.01	0.02722372	0
83290.01	0.02721533	0
83292.01	0.0272075	0
83294.01	0.02719975	0
83296.01	0.02718817	0
83298.01	0.02718211	0
83300.01	0.02717647	0
83302.01	0.02716865	0
83304.01	0.02716216	0
83306.01	0.0271578	0
83308.01	0.02715505	0
83310.01	0.0271503	0
83312.01	0.02714354	0
83314.01	0.02713485	0
83316.01	0.02712309	0
83318.01	0.02711667	0
83320.01	0.02710786	0
83322.01	0.02710004	0
83324.01	0.02709018	0
83326.01	0.02708249	0
83328.01	0.02707638	0
83330.01	0.02706603	0
83332.01	0.02705377	0
83334.01	0.02704106	0
83336.01	0.02703192	0
83338.01	0.02702524	0
83340.01	0.02701351	0
83342.01	0.02700783	0
83344.01	0.02699818	0
83346.01	0.02698986	0
83348.01	0.02698317	0
83350.01	0.02697389	0
83352.01	0.02697047	0
83354.01	0.02696785	0
83356.01	0.02696569	0
83358.01	0.02695101	0
83360.01	0.02693924	0
83362.01	0.02692994	0
83364.01	0.02692182	0
83366.01	0.02690767	0
83368.01	0.0269001	0
83370.01	0.02690261	0
83372.01	0.02689688	0
83374.01	0.02689611	0
83376.01	0.02688903	0
83378.01	0.02688165	0
83380.01	0.02687729	0
83382.01	0.02687632	0
83384.01	0.0268758	0
83386.01	0.02686922	0
83388.01	0.02686655	0
83390.01	0.02686335	0
83392.01	0.02685747	0
83394.01	0.02684801	0
83396.01	0.0268356	0
83398.01	0.02682574	0
83400.01	0.02681869	0
83402.01	0.02680948	0
83404.01	0.026801	0
83406.01	0.02678808	0
83408.01	0.02677639	0
83410.01	0.02676826	0
83412.01	0.02675847	0
83414.01	0.02675231	0
83416.01	0.02674186	0
83418.01	0.02673404	0
83420.01	0.02672882	0
83422.01	0.02672432	0
83424.01	0.02671543	0
83426.01	0.02670568	0
83428.01	0.02669908	0
83430.01	0.02668589	0
83432.01	0.0266792	0
83434.01	0.02666659	0
83436.01	0.02666026	0
83438.01	0.02664917	0
83440.01	0.02664025	0
83442.01	0.02663899	0
83444.01	0.02663697	0
83446.01	0.02662376	0
83448.01	0.02660169	0
83450.01	0.02658041	0
83452.01	0.02657292	0
83454.01	0.02655618	0
83456.01	0.0265465	0
83458.01	0.02653812	0
83460.01	0.02652261	0
83462.01	0.0265081	0
83464.01	0.02650387	0
83466.01	0.02649592	0
83468.01	0.02648063	0
83470.01	0.02647321	0
83472.01	0.026483	0
83474.01	0.0264865	0
83476.01	0.02649205	0
83478.01	0.02649376	0
83480.01	0.02649268	0
83482.01	0.02648997	0
83484.01	0.02648766	0
83486.01	0.02648379	0
83488.01	0.02648092	0
83490.01	0.02647298	0
83492.01	0.02646984	0
83494.01	0.02646689	0
83496.01	0.02646164	0
83498.01	0.02645359	0
83500.01	0.02644788	0
83502.01	0.02643919	0
83504.01	0.02643001	0
83506.01	0.02642343	0
83508.01	0.02641861	0
83510.01	0.02641176	0
83512.01	0.02640473	0
83514.01	0.02639645	0
83516.01	0.02638705	0
83518.01	0.02637857	0
83520.01	0.02636827	0
83522.01	0.02636356	0
83524.01	0.02635735	0
83526.01	0.02634793	0
83528.01	0.02634059	0
83530.01	0.02633577	0
83532.01	0.0263289	0
83534.01	0.02632638	0
83536.01	0.02631991	0
83538.01	0.02631215	0
83540.01	0.02630197	0
83542.01	0.02630177	0
83544.01	0.0263017	0
83546.01	0.02629717	0
83548.01	0.02628971	0
83550.01	0.02628576	0
83552.01	0.02628359	0
83554.01	0.02628222	0
83556.01	0.02627811	0
83558.01	0.02628325	0
83560.01	0.02627373	0
83562.01	0.02625834	0
83564.01	0.02625973	0
83566.01	0.02626396	0
83568.01	0.02625338	0
83570.01	0.02624487	0
83572.01	0.02622749	0
83574.01	0.02621855	0
83576.01	0.02620712	0
83578.01	0.02618921	0
83580.01	0.02617602	0
83582.01	0.02617629	0
83584.01	0.02618085	0
83586.01	0.02617703	0
83588.01	0.02616673	0
83590.01	0.02616246	0
83592.01	0.02615468	0
83594.01	0.02614714	0
83596.01	0.02614427	0
83598.01	0.02613431	0
83600.01	0.02612988	0
83602.01	0.02612204	0
83604.01	0.02611672	0
83606.01	0.02611096	0
83608.01	0.02610461	0
83610.01	0.02609611	0
83612.01	0.02608898	0
83614.01	0.02608475	0
83616.01	0.02608486	0
83618.01	0.02608516	0
83620.01	0.0260804	0
83622.01	0.02607589	0
83624.01	0.0260712	0
83626.01	0.02606533	0
83628.01	0.0260581	0
83630.01	0.02605311	0
83632.01	0.02605064	0
83634.01	0.02604274	0
83636.01	0.02602926	0
83638.01	0.02602001	0
83640.01	0.02600855	0
83642.01	0.025998	0
83644.01	0.02600179	0
83646.01	0.02599941	0
83648.01	0.02598996	0
83650.01	0.02597832	0
83652.01	0.02596762	0
83654.01	0.02596127	0
83656.01	0.02595486	0
83658.01	0.02594839	0
83660.01	0.02593874	0
83662.01	0.02592735	0
83664.01	0.02591318	0
83666.01	0.02590214	0
83668.01	0.02589706	0
83670.01	0.02589351	0
83672.01	0.02589602	0
83674.01	0.02590962	0
83676.01	0.02590293	0
83678.01	0.02589915	0
83680.01	0.02589244	0
83682.01	0.02589256	0
83684.01	0.02588955	0
83686.01	0.02588622	0
83688.01	0.02588369	0
83690.01	0.02587974	0
83692.01	0.02586794	0
83694.01	0.02585381	0
83696.01	0.02585864	0
83698.01	0.02584877	0
83700.01	0.02583995	0
83702.01	0.02584451	0
83704.01	0.02584605	0
83706.01	0.02583676	0
83708.01	0.02582541	0
83710.01	0.02582378	0
83712.01	0.0258194	0
83714.01	0.025817	0
83716.01	0.02581634	0
83718.01	0.025811	0
83720.01	0.02580329	0
83722.01	0.02579174	0
83724.01	0.02577909	0
83726.01	0.02576514	0
83728.01	0.02576229	0
83730.01	0.02575637	0
83732.01	0.02574421	0
83734.01	0.02573582	0
83736.01	0.02572608	0
83738.01	0.02571759	0
83740.01	0.02571037	0
83742.01	0.02570583	0
83744.01	0.02569701	0
83746.01	0.02570025	0
83748.01	0.02570062	0
83750.01	0.0256972	0
83752.01	0.02568737	0
83754.01	0.02568583	0
83756.01	0.02567675	0
83758.01	0.02567035	0
83760.01	0.02566568	0
83762.01	0.0256578	0
83764.01	0.02565377	0
83766.01	0.02565677	0
83768.01	0.02565189	0
83770.01	0.02564374	0
83772.01	0.02563107	0
83774.01	0.0256209	0
83776.01	0.02561047	0
83778.01	0.02560384	0
83780.01	0.0255977	0
83782.01	0.02558466	0
83784.01	0.02557571	0
83786.01	0.02556798	0
83788.01	0.02555823	0
83790.01	0.02555319	0
83792.01	0.02554798	0
83794.01	0.02554598	0
83796.01	0.02552932	0
83798.01	0.02551371	0
83800.01	0.02550798	0
83802.01	0.02549804	0
83804.01	0.02548736	0
83806.01	0.02547962	0
83808.01	0.02547123	0
83810.01	0.02546482	0
83812.01	0.02545681	0
83814.01	0.02544835	0
83816.01	0.02544063	0
83818.01	0.02544185	0
83820.01	0.02543609	0
83822.01	0.02543894	0
83824.01	0.02543963	0
83826.01	0.02543777	0
83828.01	0.02543446	0
83830.01	0.02543393	0
83832.01	0.0254257	0
83834.01	0.0254199	0
83836.01	0.02541345	0
83838.01	0.02540971	0
83840.01	0.02540117	0
83842.01	0.02540012	0
83844.01	0.02539176	0
83846.01	0.02537987	0
83848.01	0.0253825	0
83850.01	0.02538919	0
83852.01	0.02538483	0
83854.01	0.0253812	0
83856.01	0.02537259	0
83858.01	0.02536629	0
83860.01	0.02537005	0
83862.01	0.02536945	0
83864.01	0.02536645	0
83866.01	0.02535225	0
83868.01	0.02535743	0
83870.01	0.02535396	0
83872.01	0.02533506	0
83874.01	0.02532774	0
83876.01	0.02532369	0
83878.01	0.02531592	0
83880.01	0.02531123	0
83882.01	0.02530312	0
83884.01	0.02529879	0
83886.01	0.0252947	0
83888.01	0.02528816	0
83890.01	0.02528733	0
83892.01	0.02528264	0
83894.01	0.02527445	0
83896.01	0.02526839	0
83898.01	0.02526321	0
83900.01	0.02525481	0
83902.01	0.02524875	0
83904.01	0.02524728	0
83906.01	0.02524065	0
83908.01	0.02523538	0
83910.01	0.02522603	0
83912.01	0.02522134	0
83914.01	0.02521785	0
83916.01	0.02520778	0
83918.01	0.02520059	0
83920.01	0.02519591	0
83922.01	0.02519133	0
83924.01	0.02518322	0
83926.01	0.02517528	0
83928.01	0.02516989	0
83930.01	0.02517037	0
83932.01	0.02516555	0
83934.01	0.02515645	0
83936.01	0.02514976	0
83938.01	0.02514294	0
83940.01	0.02513807	0
83942.01	0.02513673	0
83944.01	0.02513054	0
83946.01	0.02512783	0
83948.01	0.02511864	0
83950.01	0.02510911	0
83952.01	0.02510455	0
83954.01	0.02510024	0
83956.01	0.02509019	0
83958.01	0.0250766	0
83960.01	0.02506498	0
83962.01	0.02505468	0
83964.01	0.02504562	0
83966.01	0.02503658	0
83968.01	0.02502655	0
83970.01	0.02501649	0
83972.01	0.02501587	0
83974.01	0.02501253	0
83976.01	0.02500509	0
83978.01	0.02500358	0
83980.01	0.02499794	0
83982.01	0.0249896	0
83984.01	0.02497942	0
83986.01	0.02497586	0
83988.01	0.02496879	0
83990.01	0.02495583	0
83992.01	0.02494624	0
83994.01	0.0249383	0
83996.01	0.0249398	0
83998.01	0.02494293	0
84000.01	0.02494286	0
84002.01	0.02493105	0
84004.01	0.02492436	0
84006.01	0.02492172	0
84008.01	0.02491137	0
84010.01	0.02490668	0
84012.01	0.02490266	0
84014.01	0.02489877	0
84016.01	0.02489416	0
84018.01	0.02488331	0
84020.01	0.02487652	0
84022.01	0.02486815	0
84024.01	0.02486564	0
84026.01	0.02486181	0
84028.01	0.02485808	0
84030.01	0.02485629	0
84032.01	0.02485516	0
84034.01	0.02485022	0
84036.01	0.02484838	0
84038.01	0.02484652	0
84040.01	0.02484495	0
84042.01	0.02484766	0
84044.01	0.02484684	0
84046.01	0.02485023	0
84048.01	0.0248507	0
84050.01	0.02485406	0
84052.01	0.02484279	0
84054.01	0.0248369	0
84056.01	0.02482944	0
84058.01	0.02481109	0
84060.01	0.02482126	0
84062.01	0.0248238	0
84064.01	0.02482406	0
84066.01	0.02481644	0
84068.01	0.02481306	0
84070.01	0.02481787	0
84072.01	0.02481741	0
84074.01	0.0248147	0
84076.01	0.02480438	0
84078.01	0.02479721	0
84080.01	0.02478295	0
84082.01	0.02477991	0
84084.01	0.0247704	0
84086.01	0.02475755	0
84088.01	0.02474608	0
84090.01	0.02473757	0
84092.01	0.02472781	0
84094.01	0.02472967	0
84096.01	0.02473267	0
84098.01	0.02472676	0
84100.01	0.02471395	0
84102.01	0.02472534	0
84104.01	0.02473178	0
84106.01	0.02472753	0
84108.01	0.02472465	0
84110.01	0.02471818	0
84112.01	0.02470283	0
84114.01	0.02469689	0
84116.01	0.0246862	0
84118.01	0.0246734	0
84120.01	0.02466277	0
84122.01	0.02465721	0
84124.01	0.02465702	0
84126.01	0.02464734	0
84128.01	0.02463585	0
84130.01	0.02463779	0
84132.01	0.02463814	0
84134.01	0.02463219	0
84136.01	0.0246212	0
84138.01	0.02461345	0
84140.01	0.02460908	0
84142.01	0.02459757	0
84144.01	0.02460027	0
84146.01	0.02459679	0
84148.01	0.02459615	0
84150.01	0.02459358	0
84152.01	0.02459423	0
84154.01	0.0245929	0
84156.01	0.02459593	0
84158.01	0.02458841	0
84160.01	0.02458429	0
84162.01	0.02458074	0
84164.01	0.02456721	0
84166.01	0.02456088	0
84168.01	0.02455887	0
84170.01	0.02455736	0
84172.01	0.0245489	0
84174.01	0.02453423	0
84176.01	0.02452236	0
84178.01	0.02451164	0
84180.01	0.02450073	0
84182.01	0.02448621	0
84184.01	0.02448372	0
84186.01	0.02447736	0
84188.01	0.02447191	0
84190.01	0.02446626	0
84192.01	0.02445596	0
84194.01	0.02444994	0
84196.01	0.02445273	0
84198.01	0.0244489	0
84200.01	0.02444428	0
84202.01	0.02443736	0
84204.01	0.02443147	0
84206.01	0.02442198	0
84208.01	0.02441278	0
84210.01	0.0244112	0
84212.01	0.02439934	0
84214.01	0.02439361	0
84216.01	0.02439212	0
84218.01	0.02438025	0
84220.01	0.02437627	0
84222.01	0.02437031	0
84224.01	0.02436653	0
84226.01	0.02435751	0
84228.01	0.02435872	0
84230.01	0.02435741	0
84232.01	0.02435103	0
84234.01	0.02434477	0
84236.01	0.02433283	0
84238.01	0.02432671	0
84240.01	0.02432148	0
84242.01	0.02431449	0
84244.01	0.02430905	0
84246.01	0.0242963	0
84248.01	0.02428918	0
84250.01	0.02428796	0
84252.01	0.02428489	0
84254.01	0.02428733	0
84256.01	0.02428229	0
84258.01	0.02427681	0
84260.01	0.02427338	0
84262.01	0.02427384	0
84264.01	0.02427449	0
84266.01	0.0242743	0
84268.01	0.02426943	0
84270.01	0.02426582	0
84272.01	0.02426043	0
84274.01	0.0242594	0
84276.01	0.02425786	0
84278.01	0.02425346	0
84280.01	0.02425344	0
84282.01	0.02424963	0
84284.01	0.0242387	0
84286.01	0.02422418	0
84288.01	0.02421397	0
84290.01	0.02420149	0
84292.01	0.02419471	0
84294.01	0.02418737	0
84296.01	0.02418363	0
84298.01	0.02418272	0
84300.01	0.02418751	0
84302.01	0.02418683	0
84304.01	0.02418321	0
84306.01	0.02417851	0
84308.01	0.02417511	0
84310.01	0.02416812	0
84312.01	0.02416387	0
84314.01	0.0241582	0
84316.01	0.02415176	0
84318.01	0.02414123	0
84320.01	0.02413647	0
84322.01	0.0241276	0
84324.01	0.02412153	0
84326.01	0.02412169	0
84328.01	0.02411833	0
84330.01	0.02411857	0
84332.01	0.02411938	0
84334.01	0.02411898	0
84336.01	0.02411202	0
84338.01	0.02410606	0
84340.01	0.0241028	0
84342.01	0.02410508	0
84344.01	0.02410441	0
84346.01	0.02410342	0
84348.01	0.02410324	0
84350.01	0.02409744	0
84352.01	0.02409173	0
84354.01	0.0240938	0
84356.01	0.02408684	0
84358.01	0.02408357	0
84360.01	0.02407604	0
84362.01	0.0240691	0
84364.01	0.0240633	0
84366.01	0.02405615	0
84368.01	0.02404855	0
84370.01	0.02404606	0
84372.01	0.02403865	0
84374.01	0.0240387	0
84376.01	0.02403786	0
84378.01	0.02403764	0
84380.01	0.0240378	0
84382.01	0.02403014	0
84384.01	0.02402191	0
84386.01	0.02401558	0
84388.01	0.02400942	0
84390.01	0.02399878	0
84392.01	0.02398647	0
84394.01	0.02397888	0
84396.01	0.02396741	0
84398.01	0.02395976	0
84400.01	0.02395126	0
84402.01	0.02394848	0
84404.01	0.0239472	0
84406.01	0.02394152	0
84408.01	0.02394619	0
84410.01	0.02393897	0
84412.01	0.02393459	0
84414.01	0.023928	0
84416.01	0.02391781	0
84418.01	0.02391553	0
84420.01	0.02390739	0
84422.01	0.02390268	0
84424.01	0.02390432	0
84426.01	0.02389778	0
84428.01	0.02389506	0
84430.01	0.02388702	0
84432.01	0.02387474	0
84434.01	0.02386997	0
84436.01	0.02385974	0
84438.01	0.02385987	0
84440.01	0.02386024	0
84442.01	0.02385423	0
84444.01	0.02384996	0
84446.01	0.02385097	0
84448.01	0.02384951	0
84450.01	0.0238418	0
84452.01	0.02384494	0
84454.01	0.02384238	0
84456.01	0.0238355	0
84458.01	0.02383419	0
84460.01	0.02383369	0
84462.01	0.02383383	0
84464.01	0.02383208	0
84466.01	0.02383556	0
84468.01	0.0238297	0
84470.01	0.02382755	0
84472.01	0.02382499	0
84474.01	0.02381564	0
84476.01	0.02381126	0
84478.01	0.02380563	0
84480.01	0.02381057	0
84482.01	0.02380493	0
84484.01	0.02379535	0
84486.01	0.02379799	0
84488.01	0.02380765	0
84490.01	0.02380371	0
84492.01	0.0238017	0
84494.01	0.02379694	0
84496.01	0.02379436	0
84498.01	0.02379104	0
84500.01	0.02378024	0
84502.01	0.02377401	0
84504.01	0.02376941	0
84506.01	0.02376434	0
84508.01	0.02375611	0
84510.01	0.02375622	0
84512.01	0.02374588	0
84514.01	0.02373775	0
84516.01	0.02373568	0
84518.01	0.02372348	0
84520.01	0.02371593	0
84522.01	0.02370499	0
84524.01	0.02368411	0
84526.01	0.02366782	0
84528.01	0.02368208	0
84530.01	0.02368686	0
84532.01	0.02368939	0
84534.01	0.02368613	0
84536.01	0.02368466	0
84538.01	0.02369389	0
84540.01	0.02368741	0
84542.01	0.02368248	0
84544.01	0.02368508	0
84546.01	0.02368687	0
84548.01	0.02368173	0
84550.01	0.0236824	0
84552.01	0.02367899	0
84554.01	0.02367755	0
84556.01	0.02367205	0
84558.01	0.02366755	0
84560.01	0.02367154	0
84562.01	0.02366686	0
84564.01	0.0236678	0
84566.01	0.02366249	0
84568.01	0.02366045	0
84570.01	0.02365508	0
84572.01	0.02364886	0
84574.01	0.02364115	0
84576.01	0.02363038	0
84578.01	0.0236214	0
84580.01	0.02361899	0
84582.01	0.0236224	0
84584.01	0.02361191	0
84586.01	0.02360926	0
84588.01	0.0236069	0
84590.01	0.02360596	0
84592.01	0.02360664	0
84594.01	0.02359364	0
84596.01	0.0235873	0
84598.01	0.02357188	0
84600.01	0.0235748	0
84602.01	0.02357678	0
84604.01	0.02357243	0
84606.01	0.02356727	0
84608.01	0.02356103	0
84610.01	0.02355918	0
84612.01	0.02355658	0
84614.01	0.02354741	0
84616.01	0.02354393	0
84618.01	0.02354634	0
84620.01	0.02354308	0
84622.01	0.02352433	0
84624.01	0.02350375	0
84626.01	0.02350988	0
84628.01	0.02351023	0
84630.01	0.02351492	0
84632.01	0.02351511	0
84634.01	0.02349964	0
84636.01	0.0234998	0
84638.01	0.02350114	0
84640.01	0.02349999	0
84642.01	0.02349898	0
84644.01	0.02350264	0
84646.01	0.02349215	0
84648.01	0.02349084	0
84650.01	0.02348963	0
84652.01	0.02348216	0
84654.01	0.0234793	0
84656.01	0.02347195	0
84658.01	0.02347509	0
84660.01	0.02347293	0
84662.01	0.02347198	0
84664.01	0.02347387	0
84666.01	0.02347138	0
84668.01	0.02347096	0
84670.01	0.02346785	0
84672.01	0.02345876	0
84674.01	0.02345743	0
84676.01	0.02345588	0
84678.01	0.02344522	0
84680.01	0.02343193	0
84682.01	0.02342183	0
84684.01	0.0234199	0
84686.01	0.02341771	0
84688.01	0.02341527	0
84690.01	0.02342573	0
84692.01	0.02342116	0
84694.01	0.02341623	0
84696.01	0.02340283	0
84698.01	0.02339542	0
84700.01	0.02339543	0
84702.01	0.02339515	0
84704.01	0.02339682	0
84706.01	0.02338441	0
84708.01	0.02338226	0
84710.01	0.02337137	0
84712.01	0.02335568	0
84714.01	0.02334748	0
84716.01	0.02335493	0
84718.01	0.02335153	0
84720.01	0.02333534	0
84722.01	0.02332238	0
84724.01	0.02330885	0
84726.01	0.02330123	0
84728.01	0.02329689	0
84730.01	0.02329051	0
84732.01	0.02328542	0
84734.01	0.02328617	0
84736.01	0.02327931	0
84738.01	0.02327654	0
84740.01	0.02327703	0
84742.01	0.02327541	0
84744.01	0.02327027	0
84746.01	0.02326376	0
84748.01	0.02327182	0
84750.01	0.02327363	0
84752.01	0.02327036	0
84754.01	0.02327106	0
84756.01	0.02327063	0
84758.01	0.02326494	0
84760.01	0.02326077	0
84762.01	0.023261	0
84764.01	0.02326414	0
84766.01	0.02325633	0
84768.01	0.02324813	0
84770.01	0.02324276	0
84772.01	0.02323602	0
84774.01	0.02322708	0
84776.01	0.02323125	0
84778.01	0.0232198	0
84780.01	0.02320711	0
84782.01	0.02320173	0
84784.01	0.02320593	0
84786.01	0.02319903	0
84788.01	0.02320997	0
84790.01	0.02321355	0
84792.01	0.02320932	0
84794.01	0.02320521	0
84796.01	0.02319801	0
84798.01	0.02318979	0
84800.01	0.02319487	0
84802.01	0.02318662	0
84804.01	0.02317278	0
84806.01	0.02316779	0
84808.01	0.02317757	0
84810.01	0.02317141	0
84812.01	0.02316952	0
84814.01	0.02315727	0
84816.01	0.0231454	0
84818.01	0.02313874	0
84820.01	0.02314126	0
84822.01	0.02313895	0
84824.01	0.02313173	0
84826.01	0.0231236	0
84828.01	0.02311888	0
84830.01	0.02311325	0
84832.01	0.02311212	0
84834.01	0.0231112	0
84836.01	0.0231125	0
84838.01	0.02311642	0
84840.01	0.02311214	0
84842.01	0.02312228	0
84844.01	0.02312231	0
84846.01	0.02310379	0
84848.01	0.02310719	0
84850.01	0.02310169	0
84852.01	0.02308869	0
84854.01	0.02309459	0
84856.01	0.02308581	0
84858.01	0.02308742	0
84860.01	0.02308332	0
84862.01	0.02307015	0
84864.01	0.02306676	0
84866.01	0.0230742	0
84868.01	0.02307802	0
84870.01	0.02307551	0
84872.01	0.02306844	0
84874.01	0.02305809	0
84876.01	0.02304889	0
84878.01	0.02304088	0
84880.01	0.02302859	0
84882.01	0.02302061	0
84884.01	0.0230016	0
84886.01	0.02299451	0
84888.01	0.02299736	0
84890.01	0.02299821	0
84892.01	0.0229991	0
84894.01	0.02300261	0
84896.01	0.0230017	0
84898.01	0.02299913	0
84900.01	0.02299362	0
84902.01	0.02299002	0
84904.01	0.02298675	0
84906.01	0.02298052	0
84908.01	0.02296881	0
84910.01	0.02296118	0
84912.01	0.02295686	0
84914.01	0.02294969	0
84916.01	0.02293722	0
84918.01	0.02293076	0
84920.01	0.02293181	0
84922.01	0.02292412	0
84924.01	0.0229186	0
84926.01	0.0229155	0
84928.01	0.02290614	0
84930.01	0.02290633	0
84932.01	0.02290831	0
84934.01	0.02291137	0
84936.01	0.02290457	0
84938.01	0.02290079	0
84940.01	0.02290413	0
84942.01	0.02289771	0
84944.01	0.02289955	0
84946.01	0.02290955	0
84948.01	0.02291277	0
84950.01	0.02291181	0
84952.01	0.02291181	0
84954.01	0.02290477	0
84956.01	0.022897	0
84958.01	0.02289161	0
84960.01	0.02288911	0
84962.01	0.02288624	0
84964.01	0.02287756	0
84966.01	0.02287189	0
84968.01	0.0228657	0
84970.01	0.02286895	0
84972.01	0.02287998	0
84974.01	0.02287966	0
84976.01	0.02287705	0
84978.01	0.02286584	0
84980.01	0.02286703	0
84982.01	0.02286457	0
84984.01	0.02285825	0
84986.01	0.02285759	0
84988.01	0.02285766	0
84990.01	0.02284722	0
84992.01	0.02284208	0
84994.01	0.02284615	0
84996.01	0.02283777	0
84998.01	0.02283791	0
85000.01	0.02283886	0
85002.01	0.02284299	0
85004.01	0.02283707	0
85006.01	0.0228361	0
85008.01	0.02284065	0
85010.01	0.0228382	0
85012.01	0.02283498	0
85014.01	0.02283528	0
85016.01	0.02282953	0
85018.01	0.02282909	0
85020.01	0.0228277	0
85022.01	0.02282449	0
85024.01	0.0228131	0
85026.01	0.02281321	0
85028.01	0.0228075	0
85030.01	0.02280499	0
85032.01	0.02279827	0
85034.01	0.02279427	0
85036.01	0.0228002	0
85038.01	0.02279743	0
85040.01	0.02279213	0
85042.01	0.02278163	0
85044.01	0.02278123	0
85046.01	0.02278287	0
85048.01	0.02278143	0
85050.01	0.02277633	0
85052.01	0.02277212	0
85054.01	0.02275647	0
85056.01	0.02275263	0
85058.01	0.02275528	0
85060.01	0.02275752	0
85062.01	0.02275329	0
85064.01	0.02274835	0
85066.01	0.02274409	0
85068.01	0.02273796	0
85070.01	0.02272663	0
85072.01	0.02271472	0
85074.01	0.0227089	0
85076.01	0.02271251	0
85078.01	0.02271429	0
85080.01	0.02271062	0
85082.01	0.02271042	0
85084.01	0.02270418	0
85086.01	0.02270522	0
85088.01	0.02270244	0
85090.01	0.02269599	0
85092.01	0.02269179	0
85094.01	0.02268391	0
85096.01	0.0226782	0
85098.01	0.02267189	0
85100.01	0.02267659	0
85102.01	0.0226707	0
85104.01	0.02265948	0
85106.01	0.02264994	0
85108.01	0.02264199	0
85110.01	0.02263067	0
85112.01	0.02262184	0
85114.01	0.02263166	0
85116.01	0.02262531	0
85118.01	0.02260814	0
85120.01	0.02260624	0
85122.01	0.02258342	0
85124.01	0.02259228	0
85126.01	0.0226017	0
85128.01	0.02259843	0
85130.01	0.02259314	0
85132.01	0.02258581	0
85134.01	0.02257384	0
85136.01	0.0225658	0
85138.01	0.02255819	0
85140.01	0.02255322	0
85142.01	0.02254308	0
85144.01	0.02253408	0
85146.01	0.02252878	0
85148.01	0.02252545	0
85150.01	0.02252642	0
85152.01	0.02252329	0
85154.01	0.02251883	0
85156.01	0.02251463	0
85158.01	0.02250907	0
85160.01	0.02250212	0
85162.01	0.02249904	0
85164.01	0.02249791	0
85166.01	0.02249467	0
85168.01	0.02249078	0
85170.01	0.02248935	0
85172.01	0.0224824	0
85174.01	0.02248378	0
85176.01	0.02248772	0
85178.01	0.02248032	0
85180.01	0.02247425	0
85182.01	0.02247475	0
85184.01	0.02246858	0
85186.01	0.0224667	0
85188.01	0.02246514	0
85190.01	0.02245892	0
85192.01	0.02245982	0
85194.01	0.02245636	0
85196.01	0.02245009	0
85198.01	0.02244319	0
85200.01	0.02243909	0
85202.01	0.02243794	0
85204.01	0.02243009	0
85206.01	0.02242646	0
85208.01	0.02242172	0
85210.01	0.02241575	0
85212.01	0.02241389	0
85214.01	0.02240494	0
85216.01	0.02239947	0
85218.01	0.02239703	0
85220.01	0.02239672	0
85222.01	0.02238576	0
85224.01	0.02238205	0
85226.01	0.02237973	0
85228.01	0.02237603	0
85230.01	0.02237522	0
85232.01	0.02237682	0
85234.01	0.02237841	0
85236.01	0.02237546	0
85238.01	0.02237653	0
85240.01	0.02237297	0
85242.01	0.02236944	0
85244.01	0.0223696	0
85246.01	0.02237077	0
85248.01	0.02236931	0
85250.01	0.02237229	0
85252.01	0.02237095	0
85254.01	0.0223683	0
85256.01	0.02235626	0
85258.01	0.02235429	0
85260.01	0.02234679	0
85262.01	0.02234207	0
85264.01	0.02233594	0
85266.01	0.02232935	0
85268.01	0.022325	0
85270.01	0.02232399	0
85272.01	0.02233001	0
85274.01	0.02232897	0
85276.01	0.02232878	0
85278.01	0.0223299	0
85280.01	0.02233119	0
85282.01	0.02233084	0
85284.01	0.02233161	0
85286.01	0.02233325	0
85288.01	0.02232839	0
85290.01	0.02233191	0
85292.01	0.02232934	0
85294.01	0.02232456	0
85296.01	0.02231959	0
85298.01	0.02231873	0
85300.01	0.02231232	0
85302.01	0.02230402	0
85304.01	0.0222956	0
85306.01	0.02229059	0
85308.01	0.02228485	0
85310.01	0.02227253	0
85312.01	0.02226666	0
85314.01	0.02226315	0
85316.01	0.02225955	0
85318.01	0.02225333	0
85320.01	0.02224951	0
85322.01	0.02224428	0
85324.01	0.02224279	0
85326.01	0.02224537	0
85328.01	0.02225123	0
85330.01	0.02225354	0
85332.01	0.02224993	0
85334.01	0.02224835	0
85336.01	0.02224624	0
85338.01	0.02224118	0
85340.01	0.02223188	0
85342.01	0.02222624	0
85344.01	0.02222592	0
85346.01	0.02222031	0
85348.01	0.02220847	0
85350.01	0.02220377	0
85352.01	0.02219996	0
85354.01	0.02219933	0
85356.01	0.02219974	0
85358.01	0.02219355	0
85360.01	0.02218733	0
85362.01	0.02218815	0
85364.01	0.02218302	0
85366.01	0.02217899	0
85368.01	0.02217541	0
85370.01	0.02216814	0
85372.01	0.02215933	0
85374.01	0.02214992	0
85376.01	0.02213669	0
85378.01	0.02212828	0
85380.01	0.02213222	0
85382.01	0.02212895	0
85384.01	0.02213083	0
85386.01	0.02212204	0
85388.01	0.02211961	0
85390.01	0.02211284	0
85392.01	0.02210457	0
85394.01	0.02210048	0
85396.01	0.02209683	0
85398.01	0.02208659	0
85400.01	0.02207898	0
85402.01	0.02207921	0
85404.01	0.02208032	0
85406.01	0.02207501	0
85408.01	0.02206427	0
85410.01	0.02205844	0
85412.01	0.02205354	0
85414.01	0.02205627	0
85416.01	0.02204994	0
85418.01	0.02204405	0
85420.01	0.02204529	0
85422.01	0.02203961	0
85424.01	0.02203392	0
85426.01	0.02203163	0
85428.01	0.02202669	0
85430.01	0.02202282	0
85432.01	0.02202176	0
85434.01	0.02202205	0
85436.01	0.02202174	0
85438.01	0.0220171	0
85440.01	0.02201554	0
85442.01	0.02200906	0
85444.01	0.02200426	0
85446.01	0.02200497	0
85448.01	0.02201285	0
85450.01	0.022015	0
85452.01	0.02201763	0
85454.01	0.02201663	0
85456.01	0.02201406	0
85458.01	0.02201667	0
85460.01	0.02201619	0
85462.01	0.02200915	0
85464.01	0.02200196	0
85466.01	0.02199804	0
85468.01	0.02199361	0
85470.01	0.02198624	0
85472.01	0.0219826	0
85474.01	0.02198344	0
85476.01	0.02198393	0
85478.01	0.02197933	0
85480.01	0.02198162	0
85482.01	0.02198448	0
85484.01	0.02197271	0
85486.01	0.02196667	0
85488.01	0.02195936	0
85489.01	0.02195782	0